[2025-05-19T08:34:32.832+0000] {taskinstance.py:1087} INFO - Dependencies all met for <TaskInstance: math_crawler_pipeline.extract_problem_and_solution manual__2025-05-19T08:34:27.706257+00:00 [queued]>
[2025-05-19T08:34:32.849+0000] {taskinstance.py:1087} INFO - Dependencies all met for <TaskInstance: math_crawler_pipeline.extract_problem_and_solution manual__2025-05-19T08:34:27.706257+00:00 [queued]>
[2025-05-19T08:34:32.850+0000] {taskinstance.py:1283} INFO - 
--------------------------------------------------------------------------------
[2025-05-19T08:34:32.850+0000] {taskinstance.py:1284} INFO - Starting attempt 1 of 3
[2025-05-19T08:34:32.850+0000] {taskinstance.py:1285} INFO - 
--------------------------------------------------------------------------------
[2025-05-19T08:34:32.866+0000] {taskinstance.py:1304} INFO - Executing <Task(PythonOperator): extract_problem_and_solution> on 2025-05-19 08:34:27.706257+00:00
[2025-05-19T08:34:32.876+0000] {standard_task_runner.py:55} INFO - Started process 1928 to run task
[2025-05-19T08:34:32.881+0000] {standard_task_runner.py:82} INFO - Running: ['***', 'tasks', 'run', 'math_crawler_pipeline', 'extract_problem_and_solution', 'manual__2025-05-19T08:34:27.706257+00:00', '--job-id', '32', '--raw', '--subdir', 'DAGS_FOLDER/MathDag.py', '--cfg-path', '/tmp/tmpsp5w0j6x']
[2025-05-19T08:34:32.883+0000] {standard_task_runner.py:83} INFO - Job 32: Subtask extract_problem_and_solution
[2025-05-19T08:34:32.950+0000] {task_command.py:389} INFO - Running <TaskInstance: math_crawler_pipeline.extract_problem_and_solution manual__2025-05-19T08:34:27.706257+00:00 [running]> on host 23e48ed0cd15
[2025-05-19T08:34:33.016+0000] {taskinstance.py:1511} INFO - Exporting the following env vars:
AIRFLOW_CTX_DAG_OWNER=***
AIRFLOW_CTX_DAG_ID=math_crawler_pipeline
AIRFLOW_CTX_TASK_ID=extract_problem_and_solution
AIRFLOW_CTX_EXECUTION_DATE=2025-05-19T08:34:27.706257+00:00
AIRFLOW_CTX_TRY_NUMBER=1
AIRFLOW_CTX_DAG_RUN_ID=manual__2025-05-19T08:34:27.706257+00:00
[2025-05-19T08:34:33.029+0000] {MathDag.py:45} INFO - Đang crawl link 1/64: https://loigiaihay.com/de-tham-khao-thi-vao-10-toan-ha-noi-nam-2025-co-dap-an-va-loi-giai-chi-tiet-a179519.html
[2025-05-19T08:34:33.035+0000] {connectionpool.py:812} WARNING - Retrying (Retry(total=2, connect=None, read=None, redirect=None, status=None)) after connection broken by 'NewConnectionError('<urllib3.connection.HTTPConnection object at 0x7f0b1412c130>: Failed to establish a new connection: [Errno 111] Connection refused')': /wd/hub/session
[2025-05-19T08:34:33.037+0000] {connectionpool.py:812} WARNING - Retrying (Retry(total=1, connect=None, read=None, redirect=None, status=None)) after connection broken by 'NewConnectionError('<urllib3.connection.HTTPConnection object at 0x7f0b1412c700>: Failed to establish a new connection: [Errno 111] Connection refused')': /wd/hub/session
[2025-05-19T08:34:33.039+0000] {connectionpool.py:812} WARNING - Retrying (Retry(total=0, connect=None, read=None, redirect=None, status=None)) after connection broken by 'NewConnectionError('<urllib3.connection.HTTPConnection object at 0x7f0b1412c8b0>: Failed to establish a new connection: [Errno 111] Connection refused')': /wd/hub/session
[2025-05-19T08:34:33.041+0000] {MathDag.py:50} ERROR - Lỗi crawl link https://loigiaihay.com/de-tham-khao-thi-vao-10-toan-ha-noi-nam-2025-co-dap-an-va-loi-giai-chi-tiet-a179519.html: HTTPConnectionPool(host='localhost', port=4444): Max retries exceeded with url: /wd/hub/session (Caused by NewConnectionError('<urllib3.connection.HTTPConnection object at 0x7f0b1412c9d0>: Failed to establish a new connection: [Errno 111] Connection refused'))
[2025-05-19T08:34:33.041+0000] {MathDag.py:45} INFO - Đang crawl link 2/64: https://loigiaihay.com/de-tham-khao-thi-vao-10-toan-ha-noi-nam-2025-co-dap-an-va-loi-giai-chi-tiet-de-2-a179539.html
[2025-05-19T08:34:33.043+0000] {connectionpool.py:812} WARNING - Retrying (Retry(total=2, connect=None, read=None, redirect=None, status=None)) after connection broken by 'NewConnectionError('<urllib3.connection.HTTPConnection object at 0x7f0b1412cf70>: Failed to establish a new connection: [Errno 111] Connection refused')': /wd/hub/session
[2025-05-19T08:34:33.044+0000] {connectionpool.py:812} WARNING - Retrying (Retry(total=1, connect=None, read=None, redirect=None, status=None)) after connection broken by 'NewConnectionError('<urllib3.connection.HTTPConnection object at 0x7f0b140d40d0>: Failed to establish a new connection: [Errno 111] Connection refused')': /wd/hub/session
[2025-05-19T08:34:33.045+0000] {connectionpool.py:812} WARNING - Retrying (Retry(total=0, connect=None, read=None, redirect=None, status=None)) after connection broken by 'NewConnectionError('<urllib3.connection.HTTPConnection object at 0x7f0b140d4280>: Failed to establish a new connection: [Errno 111] Connection refused')': /wd/hub/session
[2025-05-19T08:34:33.046+0000] {MathDag.py:50} ERROR - Lỗi crawl link https://loigiaihay.com/de-tham-khao-thi-vao-10-toan-ha-noi-nam-2025-co-dap-an-va-loi-giai-chi-tiet-de-2-a179539.html: HTTPConnectionPool(host='localhost', port=4444): Max retries exceeded with url: /wd/hub/session (Caused by NewConnectionError('<urllib3.connection.HTTPConnection object at 0x7f0b1412c6d0>: Failed to establish a new connection: [Errno 111] Connection refused'))
[2025-05-19T08:34:33.046+0000] {MathDag.py:45} INFO - Đang crawl link 3/64: https://loigiaihay.com/de-tham-khao-thi-vao-10-toan-ha-noi-nam-2025-co-dap-an-va-loi-giai-chi-tiet-de-3-a181097.html
[2025-05-19T08:34:33.047+0000] {connectionpool.py:812} WARNING - Retrying (Retry(total=2, connect=None, read=None, redirect=None, status=None)) after connection broken by 'NewConnectionError('<urllib3.connection.HTTPConnection object at 0x7f0b14106ac0>: Failed to establish a new connection: [Errno 111] Connection refused')': /wd/hub/session
[2025-05-19T08:34:33.047+0000] {connectionpool.py:812} WARNING - Retrying (Retry(total=1, connect=None, read=None, redirect=None, status=None)) after connection broken by 'NewConnectionError('<urllib3.connection.HTTPConnection object at 0x7f0b1417bfa0>: Failed to establish a new connection: [Errno 111] Connection refused')': /wd/hub/session
[2025-05-19T08:34:33.048+0000] {connectionpool.py:812} WARNING - Retrying (Retry(total=0, connect=None, read=None, redirect=None, status=None)) after connection broken by 'NewConnectionError('<urllib3.connection.HTTPConnection object at 0x7f0b14168970>: Failed to establish a new connection: [Errno 111] Connection refused')': /wd/hub/session
[2025-05-19T08:34:33.048+0000] {MathDag.py:50} ERROR - Lỗi crawl link https://loigiaihay.com/de-tham-khao-thi-vao-10-toan-ha-noi-nam-2025-co-dap-an-va-loi-giai-chi-tiet-de-3-a181097.html: HTTPConnectionPool(host='localhost', port=4444): Max retries exceeded with url: /wd/hub/session (Caused by NewConnectionError('<urllib3.connection.HTTPConnection object at 0x7f0b140d43d0>: Failed to establish a new connection: [Errno 111] Connection refused'))
[2025-05-19T08:34:33.049+0000] {MathDag.py:45} INFO - Đang crawl link 4/64: https://loigiaihay.com/de-tham-khao-thi-vao-10-mon-toan-ha-noi-nam-2025-de-so-4-a181870.html
[2025-05-19T08:34:33.049+0000] {connectionpool.py:812} WARNING - Retrying (Retry(total=2, connect=None, read=None, redirect=None, status=None)) after connection broken by 'NewConnectionError('<urllib3.connection.HTTPConnection object at 0x7f0b140d4970>: Failed to establish a new connection: [Errno 111] Connection refused')': /wd/hub/session
[2025-05-19T08:34:33.050+0000] {connectionpool.py:812} WARNING - Retrying (Retry(total=1, connect=None, read=None, redirect=None, status=None)) after connection broken by 'NewConnectionError('<urllib3.connection.HTTPConnection object at 0x7f0b140d4a90>: Failed to establish a new connection: [Errno 111] Connection refused')': /wd/hub/session
[2025-05-19T08:34:33.051+0000] {connectionpool.py:812} WARNING - Retrying (Retry(total=0, connect=None, read=None, redirect=None, status=None)) after connection broken by 'NewConnectionError('<urllib3.connection.HTTPConnection object at 0x7f0b140d4c40>: Failed to establish a new connection: [Errno 111] Connection refused')': /wd/hub/session
[2025-05-19T08:34:33.051+0000] {MathDag.py:50} ERROR - Lỗi crawl link https://loigiaihay.com/de-tham-khao-thi-vao-10-mon-toan-ha-noi-nam-2025-de-so-4-a181870.html: HTTPConnectionPool(host='localhost', port=4444): Max retries exceeded with url: /wd/hub/session (Caused by NewConnectionError('<urllib3.connection.HTTPConnection object at 0x7f0b140d4d90>: Failed to establish a new connection: [Errno 111] Connection refused'))
[2025-05-19T08:34:33.051+0000] {MathDag.py:45} INFO - Đang crawl link 5/64: https://loigiaihay.com/de-tham-khao-thi-vao-10-mon-toan-ha-noi-nam-2025-de-so-5-a182059.html
[2025-05-19T08:34:33.053+0000] {connectionpool.py:812} WARNING - Retrying (Retry(total=2, connect=None, read=None, redirect=None, status=None)) after connection broken by 'NewConnectionError('<urllib3.connection.HTTPConnection object at 0x7f0b140e7370>: Failed to establish a new connection: [Errno 111] Connection refused')': /wd/hub/session
[2025-05-19T08:34:33.054+0000] {connectionpool.py:812} WARNING - Retrying (Retry(total=1, connect=None, read=None, redirect=None, status=None)) after connection broken by 'NewConnectionError('<urllib3.connection.HTTPConnection object at 0x7f0b140e7490>: Failed to establish a new connection: [Errno 111] Connection refused')': /wd/hub/session
[2025-05-19T08:34:33.055+0000] {connectionpool.py:812} WARNING - Retrying (Retry(total=0, connect=None, read=None, redirect=None, status=None)) after connection broken by 'NewConnectionError('<urllib3.connection.HTTPConnection object at 0x7f0b1417bfd0>: Failed to establish a new connection: [Errno 111] Connection refused')': /wd/hub/session
[2025-05-19T08:34:33.056+0000] {MathDag.py:50} ERROR - Lỗi crawl link https://loigiaihay.com/de-tham-khao-thi-vao-10-mon-toan-ha-noi-nam-2025-de-so-5-a182059.html: HTTPConnectionPool(host='localhost', port=4444): Max retries exceeded with url: /wd/hub/session (Caused by NewConnectionError('<urllib3.connection.HTTPConnection object at 0x7f0b1417be80>: Failed to establish a new connection: [Errno 111] Connection refused'))
[2025-05-19T08:34:33.056+0000] {MathDag.py:45} INFO - Đang crawl link 6/64: https://loigiaihay.com/de-tham-khao-thi-vao-10-mon-toan-ha-noi-nam-2025-de-so-6-a182290.html
[2025-05-19T08:34:33.058+0000] {connectionpool.py:812} WARNING - Retrying (Retry(total=2, connect=None, read=None, redirect=None, status=None)) after connection broken by 'NewConnectionError('<urllib3.connection.HTTPConnection object at 0x7f0b1412c8b0>: Failed to establish a new connection: [Errno 111] Connection refused')': /wd/hub/session
[2025-05-19T08:34:33.059+0000] {connectionpool.py:812} WARNING - Retrying (Retry(total=1, connect=None, read=None, redirect=None, status=None)) after connection broken by 'NewConnectionError('<urllib3.connection.HTTPConnection object at 0x7f0b140d4700>: Failed to establish a new connection: [Errno 111] Connection refused')': /wd/hub/session
[2025-05-19T08:34:33.060+0000] {connectionpool.py:812} WARNING - Retrying (Retry(total=0, connect=None, read=None, redirect=None, status=None)) after connection broken by 'NewConnectionError('<urllib3.connection.HTTPConnection object at 0x7f0b140d4af0>: Failed to establish a new connection: [Errno 111] Connection refused')': /wd/hub/session
[2025-05-19T08:34:33.060+0000] {MathDag.py:50} ERROR - Lỗi crawl link https://loigiaihay.com/de-tham-khao-thi-vao-10-mon-toan-ha-noi-nam-2025-de-so-6-a182290.html: HTTPConnectionPool(host='localhost', port=4444): Max retries exceeded with url: /wd/hub/session (Caused by NewConnectionError('<urllib3.connection.HTTPConnection object at 0x7f0b140d4df0>: Failed to establish a new connection: [Errno 111] Connection refused'))
[2025-05-19T08:34:33.061+0000] {MathDag.py:45} INFO - Đang crawl link 7/64: https://loigiaihay.com/de-tham-khao-thi-vao-10-mon-toan-ha-noi-nam-2025-de-so-7-a182562.html
[2025-05-19T08:34:33.062+0000] {connectionpool.py:812} WARNING - Retrying (Retry(total=2, connect=None, read=None, redirect=None, status=None)) after connection broken by 'NewConnectionError('<urllib3.connection.HTTPConnection object at 0x7f0b140d4610>: Failed to establish a new connection: [Errno 111] Connection refused')': /wd/hub/session
[2025-05-19T08:34:33.063+0000] {connectionpool.py:812} WARNING - Retrying (Retry(total=1, connect=None, read=None, redirect=None, status=None)) after connection broken by 'NewConnectionError('<urllib3.connection.HTTPConnection object at 0x7f0b140d4490>: Failed to establish a new connection: [Errno 111] Connection refused')': /wd/hub/session
[2025-05-19T08:34:33.063+0000] {connectionpool.py:812} WARNING - Retrying (Retry(total=0, connect=None, read=None, redirect=None, status=None)) after connection broken by 'NewConnectionError('<urllib3.connection.HTTPConnection object at 0x7f0b140d4310>: Failed to establish a new connection: [Errno 111] Connection refused')': /wd/hub/session
[2025-05-19T08:34:33.064+0000] {MathDag.py:50} ERROR - Lỗi crawl link https://loigiaihay.com/de-tham-khao-thi-vao-10-mon-toan-ha-noi-nam-2025-de-so-7-a182562.html: HTTPConnectionPool(host='localhost', port=4444): Max retries exceeded with url: /wd/hub/session (Caused by NewConnectionError('<urllib3.connection.HTTPConnection object at 0x7f0b140e75b0>: Failed to establish a new connection: [Errno 111] Connection refused'))
[2025-05-19T08:34:33.064+0000] {MathDag.py:45} INFO - Đang crawl link 8/64: https://loigiaihay.com/de-tham-khao-thi-vao-10-mon-toan-ha-noi-nam-2025-de-so-8-a183073.html
[2025-05-19T08:34:33.065+0000] {connectionpool.py:812} WARNING - Retrying (Retry(total=2, connect=None, read=None, redirect=None, status=None)) after connection broken by 'NewConnectionError('<urllib3.connection.HTTPConnection object at 0x7f0b140e7b50>: Failed to establish a new connection: [Errno 111] Connection refused')': /wd/hub/session
[2025-05-19T08:34:33.067+0000] {connectionpool.py:812} WARNING - Retrying (Retry(total=1, connect=None, read=None, redirect=None, status=None)) after connection broken by 'NewConnectionError('<urllib3.connection.HTTPConnection object at 0x7f0b140e7c70>: Failed to establish a new connection: [Errno 111] Connection refused')': /wd/hub/session
[2025-05-19T08:34:33.070+0000] {connectionpool.py:812} WARNING - Retrying (Retry(total=0, connect=None, read=None, redirect=None, status=None)) after connection broken by 'NewConnectionError('<urllib3.connection.HTTPConnection object at 0x7f0b140e7e20>: Failed to establish a new connection: [Errno 111] Connection refused')': /wd/hub/session
[2025-05-19T08:34:33.071+0000] {MathDag.py:50} ERROR - Lỗi crawl link https://loigiaihay.com/de-tham-khao-thi-vao-10-mon-toan-ha-noi-nam-2025-de-so-8-a183073.html: HTTPConnectionPool(host='localhost', port=4444): Max retries exceeded with url: /wd/hub/session (Caused by NewConnectionError('<urllib3.connection.HTTPConnection object at 0x7f0b141061f0>: Failed to establish a new connection: [Errno 111] Connection refused'))
[2025-05-19T08:34:33.071+0000] {MathDag.py:45} INFO - Đang crawl link 9/64: https://loigiaihay.com/de-tham-khao-thi-vao-10-mon-toan-ha-noi-nam-2025-de-so-9-a183564.html
[2025-05-19T08:34:33.073+0000] {connectionpool.py:812} WARNING - Retrying (Retry(total=2, connect=None, read=None, redirect=None, status=None)) after connection broken by 'NewConnectionError('<urllib3.connection.HTTPConnection object at 0x7f0b140d4280>: Failed to establish a new connection: [Errno 111] Connection refused')': /wd/hub/session
[2025-05-19T08:34:33.074+0000] {connectionpool.py:812} WARNING - Retrying (Retry(total=1, connect=None, read=None, redirect=None, status=None)) after connection broken by 'NewConnectionError('<urllib3.connection.HTTPConnection object at 0x7f0b140d4550>: Failed to establish a new connection: [Errno 111] Connection refused')': /wd/hub/session
[2025-05-19T08:34:33.075+0000] {connectionpool.py:812} WARNING - Retrying (Retry(total=0, connect=None, read=None, redirect=None, status=None)) after connection broken by 'NewConnectionError('<urllib3.connection.HTTPConnection object at 0x7f0b140d47c0>: Failed to establish a new connection: [Errno 111] Connection refused')': /wd/hub/session
[2025-05-19T08:34:33.075+0000] {MathDag.py:50} ERROR - Lỗi crawl link https://loigiaihay.com/de-tham-khao-thi-vao-10-mon-toan-ha-noi-nam-2025-de-so-9-a183564.html: HTTPConnectionPool(host='localhost', port=4444): Max retries exceeded with url: /wd/hub/session (Caused by NewConnectionError('<urllib3.connection.HTTPConnection object at 0x7f0b140d4a00>: Failed to establish a new connection: [Errno 111] Connection refused'))
[2025-05-19T08:34:33.076+0000] {MathDag.py:45} INFO - Đang crawl link 10/64: https://loigiaihay.com/de-tham-khao-thi-vao-10-mon-toan-ha-noi-nam-2025-de-so-10-a183809.html
[2025-05-19T08:34:33.077+0000] {connectionpool.py:812} WARNING - Retrying (Retry(total=2, connect=None, read=None, redirect=None, status=None)) after connection broken by 'NewConnectionError('<urllib3.connection.HTTPConnection object at 0x7f0b140d4f40>: Failed to establish a new connection: [Errno 111] Connection refused')': /wd/hub/session
[2025-05-19T08:34:33.078+0000] {connectionpool.py:812} WARNING - Retrying (Retry(total=1, connect=None, read=None, redirect=None, status=None)) after connection broken by 'NewConnectionError('<urllib3.connection.HTTPConnection object at 0x7f0b140d40a0>: Failed to establish a new connection: [Errno 111] Connection refused')': /wd/hub/session
[2025-05-19T08:34:33.079+0000] {connectionpool.py:812} WARNING - Retrying (Retry(total=0, connect=None, read=None, redirect=None, status=None)) after connection broken by 'NewConnectionError('<urllib3.connection.HTTPConnection object at 0x7f0b140d41c0>: Failed to establish a new connection: [Errno 111] Connection refused')': /wd/hub/session
[2025-05-19T08:34:33.080+0000] {MathDag.py:50} ERROR - Lỗi crawl link https://loigiaihay.com/de-tham-khao-thi-vao-10-mon-toan-ha-noi-nam-2025-de-so-10-a183809.html: HTTPConnectionPool(host='localhost', port=4444): Max retries exceeded with url: /wd/hub/session (Caused by NewConnectionError('<urllib3.connection.HTTPConnection object at 0x7f0b1412c760>: Failed to establish a new connection: [Errno 111] Connection refused'))
[2025-05-19T08:34:33.080+0000] {MathDag.py:45} INFO - Đang crawl link 11/64: https://loigiaihay.com/de-tham-khao-thi-vao-10-mon-toan-ha-noi-nam-2025-de-so-11-a184285.html
[2025-05-19T08:34:33.082+0000] {connectionpool.py:812} WARNING - Retrying (Retry(total=2, connect=None, read=None, redirect=None, status=None)) after connection broken by 'NewConnectionError('<urllib3.connection.HTTPConnection object at 0x7f0b1412cf70>: Failed to establish a new connection: [Errno 111] Connection refused')': /wd/hub/session
[2025-05-19T08:34:33.083+0000] {connectionpool.py:812} WARNING - Retrying (Retry(total=1, connect=None, read=None, redirect=None, status=None)) after connection broken by 'NewConnectionError('<urllib3.connection.HTTPConnection object at 0x7f0b1412cee0>: Failed to establish a new connection: [Errno 111] Connection refused')': /wd/hub/session
[2025-05-19T08:34:33.083+0000] {connectionpool.py:812} WARNING - Retrying (Retry(total=0, connect=None, read=None, redirect=None, status=None)) after connection broken by 'NewConnectionError('<urllib3.connection.HTTPConnection object at 0x7f0b1412cc10>: Failed to establish a new connection: [Errno 111] Connection refused')': /wd/hub/session
[2025-05-19T08:34:33.084+0000] {MathDag.py:50} ERROR - Lỗi crawl link https://loigiaihay.com/de-tham-khao-thi-vao-10-mon-toan-ha-noi-nam-2025-de-so-11-a184285.html: HTTPConnectionPool(host='localhost', port=4444): Max retries exceeded with url: /wd/hub/session (Caused by NewConnectionError('<urllib3.connection.HTTPConnection object at 0x7f0b141afca0>: Failed to establish a new connection: [Errno 111] Connection refused'))
[2025-05-19T08:34:33.084+0000] {MathDag.py:45} INFO - Đang crawl link 12/64: https://loigiaihay.com/de-tham-khao-thi-vao-10-toan-tp-ho-chi-minh-nam-2025-co-dap-an-va-loi-giai-chi-tiet-de-1-a179544.html
[2025-05-19T08:34:33.085+0000] {connectionpool.py:812} WARNING - Retrying (Retry(total=2, connect=None, read=None, redirect=None, status=None)) after connection broken by 'NewConnectionError('<urllib3.connection.HTTPConnection object at 0x7f0b1412cfd0>: Failed to establish a new connection: [Errno 111] Connection refused')': /wd/hub/session
[2025-05-19T08:34:33.086+0000] {connectionpool.py:812} WARNING - Retrying (Retry(total=1, connect=None, read=None, redirect=None, status=None)) after connection broken by 'NewConnectionError('<urllib3.connection.HTTPConnection object at 0x7f0b1412ca90>: Failed to establish a new connection: [Errno 111] Connection refused')': /wd/hub/session
[2025-05-19T08:34:33.087+0000] {connectionpool.py:812} WARNING - Retrying (Retry(total=0, connect=None, read=None, redirect=None, status=None)) after connection broken by 'NewConnectionError('<urllib3.connection.HTTPConnection object at 0x7f0b1412cd60>: Failed to establish a new connection: [Errno 111] Connection refused')': /wd/hub/session
[2025-05-19T08:34:33.088+0000] {MathDag.py:50} ERROR - Lỗi crawl link https://loigiaihay.com/de-tham-khao-thi-vao-10-toan-tp-ho-chi-minh-nam-2025-co-dap-an-va-loi-giai-chi-tiet-de-1-a179544.html: HTTPConnectionPool(host='localhost', port=4444): Max retries exceeded with url: /wd/hub/session (Caused by NewConnectionError('<urllib3.connection.HTTPConnection object at 0x7f0b1412c8e0>: Failed to establish a new connection: [Errno 111] Connection refused'))
[2025-05-19T08:34:33.088+0000] {MathDag.py:45} INFO - Đang crawl link 13/64: https://loigiaihay.com/de-tham-khao-thi-vao-10-mon-toan-tp-ho-chi-minh-nam-2025-de-so-2-a181829.html
[2025-05-19T08:34:33.089+0000] {connectionpool.py:812} WARNING - Retrying (Retry(total=2, connect=None, read=None, redirect=None, status=None)) after connection broken by 'NewConnectionError('<urllib3.connection.HTTPConnection object at 0x7f0b140d4a60>: Failed to establish a new connection: [Errno 111] Connection refused')': /wd/hub/session
[2025-05-19T08:34:33.090+0000] {connectionpool.py:812} WARNING - Retrying (Retry(total=1, connect=None, read=None, redirect=None, status=None)) after connection broken by 'NewConnectionError('<urllib3.connection.HTTPConnection object at 0x7f0b140d41f0>: Failed to establish a new connection: [Errno 111] Connection refused')': /wd/hub/session
[2025-05-19T08:34:33.090+0000] {connectionpool.py:812} WARNING - Retrying (Retry(total=0, connect=None, read=None, redirect=None, status=None)) after connection broken by 'NewConnectionError('<urllib3.connection.HTTPConnection object at 0x7f0b140d40d0>: Failed to establish a new connection: [Errno 111] Connection refused')': /wd/hub/session
[2025-05-19T08:34:33.091+0000] {MathDag.py:50} ERROR - Lỗi crawl link https://loigiaihay.com/de-tham-khao-thi-vao-10-mon-toan-tp-ho-chi-minh-nam-2025-de-so-2-a181829.html: HTTPConnectionPool(host='localhost', port=4444): Max retries exceeded with url: /wd/hub/session (Caused by NewConnectionError('<urllib3.connection.HTTPConnection object at 0x7f0b140d4fd0>: Failed to establish a new connection: [Errno 111] Connection refused'))
[2025-05-19T08:34:33.091+0000] {MathDag.py:45} INFO - Đang crawl link 14/64: https://loigiaihay.com/de-tham-khao-thi-vao-10-mon-toan-tp-ho-chi-minh-nam-2025-de-so-3-a181884.html
[2025-05-19T08:34:33.092+0000] {connectionpool.py:812} WARNING - Retrying (Retry(total=2, connect=None, read=None, redirect=None, status=None)) after connection broken by 'NewConnectionError('<urllib3.connection.HTTPConnection object at 0x7f0b140d4760>: Failed to establish a new connection: [Errno 111] Connection refused')': /wd/hub/session
[2025-05-19T08:34:33.092+0000] {connectionpool.py:812} WARNING - Retrying (Retry(total=1, connect=None, read=None, redirect=None, status=None)) after connection broken by 'NewConnectionError('<urllib3.connection.HTTPConnection object at 0x7f0b140d4550>: Failed to establish a new connection: [Errno 111] Connection refused')': /wd/hub/session
[2025-05-19T08:34:33.093+0000] {connectionpool.py:812} WARNING - Retrying (Retry(total=0, connect=None, read=None, redirect=None, status=None)) after connection broken by 'NewConnectionError('<urllib3.connection.HTTPConnection object at 0x7f0b140d4370>: Failed to establish a new connection: [Errno 111] Connection refused')': /wd/hub/session
[2025-05-19T08:34:33.094+0000] {MathDag.py:50} ERROR - Lỗi crawl link https://loigiaihay.com/de-tham-khao-thi-vao-10-mon-toan-tp-ho-chi-minh-nam-2025-de-so-3-a181884.html: HTTPConnectionPool(host='localhost', port=4444): Max retries exceeded with url: /wd/hub/session (Caused by NewConnectionError('<urllib3.connection.HTTPConnection object at 0x7f0b140d4b50>: Failed to establish a new connection: [Errno 111] Connection refused'))
[2025-05-19T08:34:33.095+0000] {MathDag.py:45} INFO - Đang crawl link 15/64: https://loigiaihay.com/de-tham-khao-thi-vao-10-mon-toan-tp-ho-chi-minh-nam-2025-de-so-4-a181981.html
[2025-05-19T08:34:33.097+0000] {connectionpool.py:812} WARNING - Retrying (Retry(total=2, connect=None, read=None, redirect=None, status=None)) after connection broken by 'NewConnectionError('<urllib3.connection.HTTPConnection object at 0x7f0b140e7e20>: Failed to establish a new connection: [Errno 111] Connection refused')': /wd/hub/session
[2025-05-19T08:34:33.097+0000] {connectionpool.py:812} WARNING - Retrying (Retry(total=1, connect=None, read=None, redirect=None, status=None)) after connection broken by 'NewConnectionError('<urllib3.connection.HTTPConnection object at 0x7f0b140e7340>: Failed to establish a new connection: [Errno 111] Connection refused')': /wd/hub/session
[2025-05-19T08:34:33.098+0000] {connectionpool.py:812} WARNING - Retrying (Retry(total=0, connect=None, read=None, redirect=None, status=None)) after connection broken by 'NewConnectionError('<urllib3.connection.HTTPConnection object at 0x7f0b140d4b20>: Failed to establish a new connection: [Errno 111] Connection refused')': /wd/hub/session
[2025-05-19T08:34:33.099+0000] {MathDag.py:50} ERROR - Lỗi crawl link https://loigiaihay.com/de-tham-khao-thi-vao-10-mon-toan-tp-ho-chi-minh-nam-2025-de-so-4-a181981.html: HTTPConnectionPool(host='localhost', port=4444): Max retries exceeded with url: /wd/hub/session (Caused by NewConnectionError('<urllib3.connection.HTTPConnection object at 0x7f0b140d43a0>: Failed to establish a new connection: [Errno 111] Connection refused'))
[2025-05-19T08:34:33.099+0000] {MathDag.py:45} INFO - Đang crawl link 16/64: https://loigiaihay.com/de-tham-khao-thi-vao-10-mon-toan-tp-ho-chi-minh-nam-2025-de-so-5-a182269.html
[2025-05-19T08:34:33.101+0000] {connectionpool.py:812} WARNING - Retrying (Retry(total=2, connect=None, read=None, redirect=None, status=None)) after connection broken by 'NewConnectionError('<urllib3.connection.HTTPConnection object at 0x7f0b140d4400>: Failed to establish a new connection: [Errno 111] Connection refused')': /wd/hub/session
[2025-05-19T08:34:33.101+0000] {connectionpool.py:812} WARNING - Retrying (Retry(total=1, connect=None, read=None, redirect=None, status=None)) after connection broken by 'NewConnectionError('<urllib3.connection.HTTPConnection object at 0x7f0b140d4d00>: Failed to establish a new connection: [Errno 111] Connection refused')': /wd/hub/session
[2025-05-19T08:34:33.102+0000] {connectionpool.py:812} WARNING - Retrying (Retry(total=0, connect=None, read=None, redirect=None, status=None)) after connection broken by 'NewConnectionError('<urllib3.connection.HTTPConnection object at 0x7f0b140d40a0>: Failed to establish a new connection: [Errno 111] Connection refused')': /wd/hub/session
[2025-05-19T08:34:33.103+0000] {MathDag.py:50} ERROR - Lỗi crawl link https://loigiaihay.com/de-tham-khao-thi-vao-10-mon-toan-tp-ho-chi-minh-nam-2025-de-so-5-a182269.html: HTTPConnectionPool(host='localhost', port=4444): Max retries exceeded with url: /wd/hub/session (Caused by NewConnectionError('<urllib3.connection.HTTPConnection object at 0x7f0b140d4f70>: Failed to establish a new connection: [Errno 111] Connection refused'))
[2025-05-19T08:34:33.103+0000] {MathDag.py:45} INFO - Đang crawl link 17/64: https://loigiaihay.com/de-tham-khao-thi-vao-10-mon-toan-tp-ho-chi-minh-nam-2025-de-so-6-a182568.html
[2025-05-19T08:34:33.104+0000] {connectionpool.py:812} WARNING - Retrying (Retry(total=2, connect=None, read=None, redirect=None, status=None)) after connection broken by 'NewConnectionError('<urllib3.connection.HTTPConnection object at 0x7f0b1412c5e0>: Failed to establish a new connection: [Errno 111] Connection refused')': /wd/hub/session
[2025-05-19T08:34:33.104+0000] {connectionpool.py:812} WARNING - Retrying (Retry(total=1, connect=None, read=None, redirect=None, status=None)) after connection broken by 'NewConnectionError('<urllib3.connection.HTTPConnection object at 0x7f0b1412ca00>: Failed to establish a new connection: [Errno 111] Connection refused')': /wd/hub/session
[2025-05-19T08:34:33.105+0000] {connectionpool.py:812} WARNING - Retrying (Retry(total=0, connect=None, read=None, redirect=None, status=None)) after connection broken by 'NewConnectionError('<urllib3.connection.HTTPConnection object at 0x7f0b1412c910>: Failed to establish a new connection: [Errno 111] Connection refused')': /wd/hub/session
[2025-05-19T08:34:33.105+0000] {MathDag.py:50} ERROR - Lỗi crawl link https://loigiaihay.com/de-tham-khao-thi-vao-10-mon-toan-tp-ho-chi-minh-nam-2025-de-so-6-a182568.html: HTTPConnectionPool(host='localhost', port=4444): Max retries exceeded with url: /wd/hub/session (Caused by NewConnectionError('<urllib3.connection.HTTPConnection object at 0x7f0b1412cf10>: Failed to establish a new connection: [Errno 111] Connection refused'))
[2025-05-19T08:34:33.105+0000] {MathDag.py:45} INFO - Đang crawl link 18/64: https://loigiaihay.com/de-tham-khao-thi-vao-10-mon-toan-tp-ho-chi-minh-nam-2025-de-so-7-a182986.html
[2025-05-19T08:34:33.106+0000] {connectionpool.py:812} WARNING - Retrying (Retry(total=2, connect=None, read=None, redirect=None, status=None)) after connection broken by 'NewConnectionError('<urllib3.connection.HTTPConnection object at 0x7f0b140e7ee0>: Failed to establish a new connection: [Errno 111] Connection refused')': /wd/hub/session
[2025-05-19T08:34:33.107+0000] {connectionpool.py:812} WARNING - Retrying (Retry(total=1, connect=None, read=None, redirect=None, status=None)) after connection broken by 'NewConnectionError('<urllib3.connection.HTTPConnection object at 0x7f0b140e7070>: Failed to establish a new connection: [Errno 111] Connection refused')': /wd/hub/session
[2025-05-19T08:34:33.108+0000] {connectionpool.py:812} WARNING - Retrying (Retry(total=0, connect=None, read=None, redirect=None, status=None)) after connection broken by 'NewConnectionError('<urllib3.connection.HTTPConnection object at 0x7f0b140e7430>: Failed to establish a new connection: [Errno 111] Connection refused')': /wd/hub/session
[2025-05-19T08:34:33.109+0000] {MathDag.py:50} ERROR - Lỗi crawl link https://loigiaihay.com/de-tham-khao-thi-vao-10-mon-toan-tp-ho-chi-minh-nam-2025-de-so-7-a182986.html: HTTPConnectionPool(host='localhost', port=4444): Max retries exceeded with url: /wd/hub/session (Caused by NewConnectionError('<urllib3.connection.HTTPConnection object at 0x7f0b140f80a0>: Failed to establish a new connection: [Errno 111] Connection refused'))
[2025-05-19T08:34:33.109+0000] {MathDag.py:45} INFO - Đang crawl link 19/64: https://loigiaihay.com/de-tham-khao-thi-vao-10-mon-toan-tp-ho-chi-minh-nam-2025-de-so-8-a183544.html
[2025-05-19T08:34:33.110+0000] {connectionpool.py:812} WARNING - Retrying (Retry(total=2, connect=None, read=None, redirect=None, status=None)) after connection broken by 'NewConnectionError('<urllib3.connection.HTTPConnection object at 0x7f0b140d4220>: Failed to establish a new connection: [Errno 111] Connection refused')': /wd/hub/session
[2025-05-19T08:34:33.111+0000] {connectionpool.py:812} WARNING - Retrying (Retry(total=1, connect=None, read=None, redirect=None, status=None)) after connection broken by 'NewConnectionError('<urllib3.connection.HTTPConnection object at 0x7f0b140d4eb0>: Failed to establish a new connection: [Errno 111] Connection refused')': /wd/hub/session
[2025-05-19T08:34:33.112+0000] {connectionpool.py:812} WARNING - Retrying (Retry(total=0, connect=None, read=None, redirect=None, status=None)) after connection broken by 'NewConnectionError('<urllib3.connection.HTTPConnection object at 0x7f0b140d4dc0>: Failed to establish a new connection: [Errno 111] Connection refused')': /wd/hub/session
[2025-05-19T08:34:33.113+0000] {MathDag.py:50} ERROR - Lỗi crawl link https://loigiaihay.com/de-tham-khao-thi-vao-10-mon-toan-tp-ho-chi-minh-nam-2025-de-so-8-a183544.html: HTTPConnectionPool(host='localhost', port=4444): Max retries exceeded with url: /wd/hub/session (Caused by NewConnectionError('<urllib3.connection.HTTPConnection object at 0x7f0b140d4ca0>: Failed to establish a new connection: [Errno 111] Connection refused'))
[2025-05-19T08:34:33.113+0000] {MathDag.py:45} INFO - Đang crawl link 20/64: https://loigiaihay.com/de-tham-khao-thi-vao-10-mon-toan-tp-ho-chi-minh-nam-2025-de-so-9-a184122.html
[2025-05-19T08:34:33.115+0000] {connectionpool.py:812} WARNING - Retrying (Retry(total=2, connect=None, read=None, redirect=None, status=None)) after connection broken by 'NewConnectionError('<urllib3.connection.HTTPConnection object at 0x7f0b1412c2b0>: Failed to establish a new connection: [Errno 111] Connection refused')': /wd/hub/session
[2025-05-19T08:34:33.116+0000] {connectionpool.py:812} WARNING - Retrying (Retry(total=1, connect=None, read=None, redirect=None, status=None)) after connection broken by 'NewConnectionError('<urllib3.connection.HTTPConnection object at 0x7f0b1412c310>: Failed to establish a new connection: [Errno 111] Connection refused')': /wd/hub/session
[2025-05-19T08:34:33.117+0000] {connectionpool.py:812} WARNING - Retrying (Retry(total=0, connect=None, read=None, redirect=None, status=None)) after connection broken by 'NewConnectionError('<urllib3.connection.HTTPConnection object at 0x7f0b1412c6a0>: Failed to establish a new connection: [Errno 111] Connection refused')': /wd/hub/session
[2025-05-19T08:34:33.117+0000] {MathDag.py:50} ERROR - Lỗi crawl link https://loigiaihay.com/de-tham-khao-thi-vao-10-mon-toan-tp-ho-chi-minh-nam-2025-de-so-9-a184122.html: HTTPConnectionPool(host='localhost', port=4444): Max retries exceeded with url: /wd/hub/session (Caused by NewConnectionError('<urllib3.connection.HTTPConnection object at 0x7f0b1412c940>: Failed to establish a new connection: [Errno 111] Connection refused'))
[2025-05-19T08:34:33.118+0000] {MathDag.py:45} INFO - Đang crawl link 21/64: https://loigiaihay.com/de-tham-khao-thi-vao-10-mon-toan-tp-ho-chi-minh-nam-2025-de-so-10-a184527.html
[2025-05-19T08:34:33.119+0000] {connectionpool.py:812} WARNING - Retrying (Retry(total=2, connect=None, read=None, redirect=None, status=None)) after connection broken by 'NewConnectionError('<urllib3.connection.HTTPConnection object at 0x7f0b140f8460>: Failed to establish a new connection: [Errno 111] Connection refused')': /wd/hub/session
[2025-05-19T08:34:33.119+0000] {connectionpool.py:812} WARNING - Retrying (Retry(total=1, connect=None, read=None, redirect=None, status=None)) after connection broken by 'NewConnectionError('<urllib3.connection.HTTPConnection object at 0x7f0b140f8580>: Failed to establish a new connection: [Errno 111] Connection refused')': /wd/hub/session
[2025-05-19T08:34:33.120+0000] {connectionpool.py:812} WARNING - Retrying (Retry(total=0, connect=None, read=None, redirect=None, status=None)) after connection broken by 'NewConnectionError('<urllib3.connection.HTTPConnection object at 0x7f0b140f8730>: Failed to establish a new connection: [Errno 111] Connection refused')': /wd/hub/session
[2025-05-19T08:34:33.120+0000] {MathDag.py:50} ERROR - Lỗi crawl link https://loigiaihay.com/de-tham-khao-thi-vao-10-mon-toan-tp-ho-chi-minh-nam-2025-de-so-10-a184527.html: HTTPConnectionPool(host='localhost', port=4444): Max retries exceeded with url: /wd/hub/session (Caused by NewConnectionError('<urllib3.connection.HTTPConnection object at 0x7f0b140f8880>: Failed to establish a new connection: [Errno 111] Connection refused'))
[2025-05-19T08:34:33.121+0000] {MathDag.py:45} INFO - Đang crawl link 22/64: https://loigiaihay.com/de-so-1-de-thi-vao-lop-10-mon-toan-c44a49454.html
[2025-05-19T08:34:33.123+0000] {connectionpool.py:812} WARNING - Retrying (Retry(total=2, connect=None, read=None, redirect=None, status=None)) after connection broken by 'NewConnectionError('<urllib3.connection.HTTPConnection object at 0x7f0b1412c850>: Failed to establish a new connection: [Errno 111] Connection refused')': /wd/hub/session
[2025-05-19T08:34:33.124+0000] {connectionpool.py:812} WARNING - Retrying (Retry(total=1, connect=None, read=None, redirect=None, status=None)) after connection broken by 'NewConnectionError('<urllib3.connection.HTTPConnection object at 0x7f0b1412c670>: Failed to establish a new connection: [Errno 111] Connection refused')': /wd/hub/session
[2025-05-19T08:34:33.124+0000] {connectionpool.py:812} WARNING - Retrying (Retry(total=0, connect=None, read=None, redirect=None, status=None)) after connection broken by 'NewConnectionError('<urllib3.connection.HTTPConnection object at 0x7f0b1412caf0>: Failed to establish a new connection: [Errno 111] Connection refused')': /wd/hub/session
[2025-05-19T08:34:33.125+0000] {MathDag.py:50} ERROR - Lỗi crawl link https://loigiaihay.com/de-so-1-de-thi-vao-lop-10-mon-toan-c44a49454.html: HTTPConnectionPool(host='localhost', port=4444): Max retries exceeded with url: /wd/hub/session (Caused by NewConnectionError('<urllib3.connection.HTTPConnection object at 0x7f0b1412c2b0>: Failed to establish a new connection: [Errno 111] Connection refused'))
[2025-05-19T08:34:33.125+0000] {MathDag.py:45} INFO - Đang crawl link 23/64: https://loigiaihay.com/de-so-2-de-thi-vao-lop-10-mon-toan-c44a49464.html
[2025-05-19T08:34:33.126+0000] {connectionpool.py:812} WARNING - Retrying (Retry(total=2, connect=None, read=None, redirect=None, status=None)) after connection broken by 'NewConnectionError('<urllib3.connection.HTTPConnection object at 0x7f0b140d4be0>: Failed to establish a new connection: [Errno 111] Connection refused')': /wd/hub/session
[2025-05-19T08:34:33.127+0000] {connectionpool.py:812} WARNING - Retrying (Retry(total=1, connect=None, read=None, redirect=None, status=None)) after connection broken by 'NewConnectionError('<urllib3.connection.HTTPConnection object at 0x7f0b140d4e50>: Failed to establish a new connection: [Errno 111] Connection refused')': /wd/hub/session
[2025-05-19T08:34:33.128+0000] {connectionpool.py:812} WARNING - Retrying (Retry(total=0, connect=None, read=None, redirect=None, status=None)) after connection broken by 'NewConnectionError('<urllib3.connection.HTTPConnection object at 0x7f0b140d4a00>: Failed to establish a new connection: [Errno 111] Connection refused')': /wd/hub/session
[2025-05-19T08:34:33.128+0000] {MathDag.py:50} ERROR - Lỗi crawl link https://loigiaihay.com/de-so-2-de-thi-vao-lop-10-mon-toan-c44a49464.html: HTTPConnectionPool(host='localhost', port=4444): Max retries exceeded with url: /wd/hub/session (Caused by NewConnectionError('<urllib3.connection.HTTPConnection object at 0x7f0b140d4fd0>: Failed to establish a new connection: [Errno 111] Connection refused'))
[2025-05-19T08:34:33.128+0000] {MathDag.py:45} INFO - Đang crawl link 24/64: https://loigiaihay.com/de-so-3-de-thi-vao-lop-10-mon-toan-c44a49465.html
[2025-05-19T08:34:33.130+0000] {connectionpool.py:812} WARNING - Retrying (Retry(total=2, connect=None, read=None, redirect=None, status=None)) after connection broken by 'NewConnectionError('<urllib3.connection.HTTPConnection object at 0x7f0b140f8af0>: Failed to establish a new connection: [Errno 111] Connection refused')': /wd/hub/session
[2025-05-19T08:34:33.130+0000] {connectionpool.py:812} WARNING - Retrying (Retry(total=1, connect=None, read=None, redirect=None, status=None)) after connection broken by 'NewConnectionError('<urllib3.connection.HTTPConnection object at 0x7f0b140f8190>: Failed to establish a new connection: [Errno 111] Connection refused')': /wd/hub/session
[2025-05-19T08:34:33.131+0000] {connectionpool.py:812} WARNING - Retrying (Retry(total=0, connect=None, read=None, redirect=None, status=None)) after connection broken by 'NewConnectionError('<urllib3.connection.HTTPConnection object at 0x7f0b140f8880>: Failed to establish a new connection: [Errno 111] Connection refused')': /wd/hub/session
[2025-05-19T08:34:33.131+0000] {MathDag.py:50} ERROR - Lỗi crawl link https://loigiaihay.com/de-so-3-de-thi-vao-lop-10-mon-toan-c44a49465.html: HTTPConnectionPool(host='localhost', port=4444): Max retries exceeded with url: /wd/hub/session (Caused by NewConnectionError('<urllib3.connection.HTTPConnection object at 0x7f0b140f87c0>: Failed to establish a new connection: [Errno 111] Connection refused'))
[2025-05-19T08:34:33.132+0000] {MathDag.py:45} INFO - Đang crawl link 25/64: https://loigiaihay.com/de-so-4-de-thi-vao-lop-10-mon-toan-c44a49466.html
[2025-05-19T08:34:33.133+0000] {connectionpool.py:812} WARNING - Retrying (Retry(total=2, connect=None, read=None, redirect=None, status=None)) after connection broken by 'NewConnectionError('<urllib3.connection.HTTPConnection object at 0x7f0b140f8eb0>: Failed to establish a new connection: [Errno 111] Connection refused')': /wd/hub/session
[2025-05-19T08:34:33.134+0000] {connectionpool.py:812} WARNING - Retrying (Retry(total=1, connect=None, read=None, redirect=None, status=None)) after connection broken by 'NewConnectionError('<urllib3.connection.HTTPConnection object at 0x7f0b141848e0>: Failed to establish a new connection: [Errno 111] Connection refused')': /wd/hub/session
[2025-05-19T08:34:33.135+0000] {connectionpool.py:812} WARNING - Retrying (Retry(total=0, connect=None, read=None, redirect=None, status=None)) after connection broken by 'NewConnectionError('<urllib3.connection.HTTPConnection object at 0x7f0b140d4b80>: Failed to establish a new connection: [Errno 111] Connection refused')': /wd/hub/session
[2025-05-19T08:34:33.136+0000] {MathDag.py:50} ERROR - Lỗi crawl link https://loigiaihay.com/de-so-4-de-thi-vao-lop-10-mon-toan-c44a49466.html: HTTPConnectionPool(host='localhost', port=4444): Max retries exceeded with url: /wd/hub/session (Caused by NewConnectionError('<urllib3.connection.HTTPConnection object at 0x7f0b140d4100>: Failed to establish a new connection: [Errno 111] Connection refused'))
[2025-05-19T08:34:33.137+0000] {MathDag.py:45} INFO - Đang crawl link 26/64: https://loigiaihay.com/de-so-5-de-thi-vao-lop-10-mon-toan-c44a49467.html
[2025-05-19T08:34:33.138+0000] {connectionpool.py:812} WARNING - Retrying (Retry(total=2, connect=None, read=None, redirect=None, status=None)) after connection broken by 'NewConnectionError('<urllib3.connection.HTTPConnection object at 0x7f0b140d4a90>: Failed to establish a new connection: [Errno 111] Connection refused')': /wd/hub/session
[2025-05-19T08:34:33.138+0000] {connectionpool.py:812} WARNING - Retrying (Retry(total=1, connect=None, read=None, redirect=None, status=None)) after connection broken by 'NewConnectionError('<urllib3.connection.HTTPConnection object at 0x7f0b140d4070>: Failed to establish a new connection: [Errno 111] Connection refused')': /wd/hub/session
[2025-05-19T08:34:33.140+0000] {connectionpool.py:812} WARNING - Retrying (Retry(total=0, connect=None, read=None, redirect=None, status=None)) after connection broken by 'NewConnectionError('<urllib3.connection.HTTPConnection object at 0x7f0b140d4520>: Failed to establish a new connection: [Errno 111] Connection refused')': /wd/hub/session
[2025-05-19T08:34:33.141+0000] {MathDag.py:50} ERROR - Lỗi crawl link https://loigiaihay.com/de-so-5-de-thi-vao-lop-10-mon-toan-c44a49467.html: HTTPConnectionPool(host='localhost', port=4444): Max retries exceeded with url: /wd/hub/session (Caused by NewConnectionError('<urllib3.connection.HTTPConnection object at 0x7f0b140d4970>: Failed to establish a new connection: [Errno 111] Connection refused'))
[2025-05-19T08:34:33.141+0000] {MathDag.py:45} INFO - Đang crawl link 27/64: https://loigiaihay.com/de-so-6-de-thi-vao-lop-10-mon-toan-c44a49468.html
[2025-05-19T08:34:33.144+0000] {connectionpool.py:812} WARNING - Retrying (Retry(total=2, connect=None, read=None, redirect=None, status=None)) after connection broken by 'NewConnectionError('<urllib3.connection.HTTPConnection object at 0x7f0b140f8490>: Failed to establish a new connection: [Errno 111] Connection refused')': /wd/hub/session
[2025-05-19T08:34:33.145+0000] {connectionpool.py:812} WARNING - Retrying (Retry(total=1, connect=None, read=None, redirect=None, status=None)) after connection broken by 'NewConnectionError('<urllib3.connection.HTTPConnection object at 0x7f0b140f8a30>: Failed to establish a new connection: [Errno 111] Connection refused')': /wd/hub/session
[2025-05-19T08:34:33.146+0000] {connectionpool.py:812} WARNING - Retrying (Retry(total=0, connect=None, read=None, redirect=None, status=None)) after connection broken by 'NewConnectionError('<urllib3.connection.HTTPConnection object at 0x7f0b140f8be0>: Failed to establish a new connection: [Errno 111] Connection refused')': /wd/hub/session
[2025-05-19T08:34:33.146+0000] {MathDag.py:50} ERROR - Lỗi crawl link https://loigiaihay.com/de-so-6-de-thi-vao-lop-10-mon-toan-c44a49468.html: HTTPConnectionPool(host='localhost', port=4444): Max retries exceeded with url: /wd/hub/session (Caused by NewConnectionError('<urllib3.connection.HTTPConnection object at 0x7f0b1412c9a0>: Failed to establish a new connection: [Errno 111] Connection refused'))
[2025-05-19T08:34:33.147+0000] {MathDag.py:45} INFO - Đang crawl link 28/64: https://loigiaihay.com/de-so-7-de-thi-vao-lop-10-mon-toan-c44a49469.html
[2025-05-19T08:34:33.150+0000] {connectionpool.py:812} WARNING - Retrying (Retry(total=2, connect=None, read=None, redirect=None, status=None)) after connection broken by 'NewConnectionError('<urllib3.connection.HTTPConnection object at 0x7f0b1412c850>: Failed to establish a new connection: [Errno 111] Connection refused')': /wd/hub/session
[2025-05-19T08:34:33.153+0000] {connectionpool.py:812} WARNING - Retrying (Retry(total=1, connect=None, read=None, redirect=None, status=None)) after connection broken by 'NewConnectionError('<urllib3.connection.HTTPConnection object at 0x7f0b140e90a0>: Failed to establish a new connection: [Errno 111] Connection refused')': /wd/hub/session
[2025-05-19T08:34:33.154+0000] {connectionpool.py:812} WARNING - Retrying (Retry(total=0, connect=None, read=None, redirect=None, status=None)) after connection broken by 'NewConnectionError('<urllib3.connection.HTTPConnection object at 0x7f0b140e9250>: Failed to establish a new connection: [Errno 111] Connection refused')': /wd/hub/session
[2025-05-19T08:34:33.155+0000] {MathDag.py:50} ERROR - Lỗi crawl link https://loigiaihay.com/de-so-7-de-thi-vao-lop-10-mon-toan-c44a49469.html: HTTPConnectionPool(host='localhost', port=4444): Max retries exceeded with url: /wd/hub/session (Caused by NewConnectionError('<urllib3.connection.HTTPConnection object at 0x7f0b1412cf70>: Failed to establish a new connection: [Errno 111] Connection refused'))
[2025-05-19T08:34:33.155+0000] {MathDag.py:45} INFO - Đang crawl link 29/64: https://loigiaihay.com/de-so-8-de-thi-vao-lop-10-mon-toan-c44a49470.html
[2025-05-19T08:34:33.157+0000] {connectionpool.py:812} WARNING - Retrying (Retry(total=2, connect=None, read=None, redirect=None, status=None)) after connection broken by 'NewConnectionError('<urllib3.connection.HTTPConnection object at 0x7f0b140f86a0>: Failed to establish a new connection: [Errno 111] Connection refused')': /wd/hub/session
[2025-05-19T08:34:33.158+0000] {connectionpool.py:812} WARNING - Retrying (Retry(total=1, connect=None, read=None, redirect=None, status=None)) after connection broken by 'NewConnectionError('<urllib3.connection.HTTPConnection object at 0x7f0b140f8880>: Failed to establish a new connection: [Errno 111] Connection refused')': /wd/hub/session
[2025-05-19T08:34:33.158+0000] {connectionpool.py:812} WARNING - Retrying (Retry(total=0, connect=None, read=None, redirect=None, status=None)) after connection broken by 'NewConnectionError('<urllib3.connection.HTTPConnection object at 0x7f0b140f88b0>: Failed to establish a new connection: [Errno 111] Connection refused')': /wd/hub/session
[2025-05-19T08:34:33.159+0000] {MathDag.py:50} ERROR - Lỗi crawl link https://loigiaihay.com/de-so-8-de-thi-vao-lop-10-mon-toan-c44a49470.html: HTTPConnectionPool(host='localhost', port=4444): Max retries exceeded with url: /wd/hub/session (Caused by NewConnectionError('<urllib3.connection.HTTPConnection object at 0x7f0b140d4cd0>: Failed to establish a new connection: [Errno 111] Connection refused'))
[2025-05-19T08:34:33.159+0000] {MathDag.py:45} INFO - Đang crawl link 30/64: https://loigiaihay.com/de-so-9-de-thi-vao-lop-10-mon-toan-c44a49471.html
[2025-05-19T08:34:33.160+0000] {connectionpool.py:812} WARNING - Retrying (Retry(total=2, connect=None, read=None, redirect=None, status=None)) after connection broken by 'NewConnectionError('<urllib3.connection.HTTPConnection object at 0x7f0b140d4be0>: Failed to establish a new connection: [Errno 111] Connection refused')': /wd/hub/session
[2025-05-19T08:34:33.161+0000] {connectionpool.py:812} WARNING - Retrying (Retry(total=1, connect=None, read=None, redirect=None, status=None)) after connection broken by 'NewConnectionError('<urllib3.connection.HTTPConnection object at 0x7f0b140d4dc0>: Failed to establish a new connection: [Errno 111] Connection refused')': /wd/hub/session
[2025-05-19T08:34:33.161+0000] {connectionpool.py:812} WARNING - Retrying (Retry(total=0, connect=None, read=None, redirect=None, status=None)) after connection broken by 'NewConnectionError('<urllib3.connection.HTTPConnection object at 0x7f0b140d4a60>: Failed to establish a new connection: [Errno 111] Connection refused')': /wd/hub/session
[2025-05-19T08:34:33.162+0000] {MathDag.py:50} ERROR - Lỗi crawl link https://loigiaihay.com/de-so-9-de-thi-vao-lop-10-mon-toan-c44a49471.html: HTTPConnectionPool(host='localhost', port=4444): Max retries exceeded with url: /wd/hub/session (Caused by NewConnectionError('<urllib3.connection.HTTPConnection object at 0x7f0b140d4910>: Failed to establish a new connection: [Errno 111] Connection refused'))
[2025-05-19T08:34:33.163+0000] {MathDag.py:45} INFO - Đang crawl link 31/64: https://loigiaihay.com/de-so-10-de-thi-vao-lop-10-mon-toan-c44a49472.html
[2025-05-19T08:34:33.164+0000] {connectionpool.py:812} WARNING - Retrying (Retry(total=2, connect=None, read=None, redirect=None, status=None)) after connection broken by 'NewConnectionError('<urllib3.connection.HTTPConnection object at 0x7f0b140e9610>: Failed to establish a new connection: [Errno 111] Connection refused')': /wd/hub/session
[2025-05-19T08:34:33.165+0000] {connectionpool.py:812} WARNING - Retrying (Retry(total=1, connect=None, read=None, redirect=None, status=None)) after connection broken by 'NewConnectionError('<urllib3.connection.HTTPConnection object at 0x7f0b140e9730>: Failed to establish a new connection: [Errno 111] Connection refused')': /wd/hub/session
[2025-05-19T08:34:33.166+0000] {connectionpool.py:812} WARNING - Retrying (Retry(total=0, connect=None, read=None, redirect=None, status=None)) after connection broken by 'NewConnectionError('<urllib3.connection.HTTPConnection object at 0x7f0b140e98e0>: Failed to establish a new connection: [Errno 111] Connection refused')': /wd/hub/session
[2025-05-19T08:34:33.167+0000] {MathDag.py:50} ERROR - Lỗi crawl link https://loigiaihay.com/de-so-10-de-thi-vao-lop-10-mon-toan-c44a49472.html: HTTPConnectionPool(host='localhost', port=4444): Max retries exceeded with url: /wd/hub/session (Caused by NewConnectionError('<urllib3.connection.HTTPConnection object at 0x7f0b140e9a30>: Failed to establish a new connection: [Errno 111] Connection refused'))
[2025-05-19T08:34:33.167+0000] {MathDag.py:45} INFO - Đang crawl link 32/64: https://loigiaihay.com/de-so-11-de-thi-vao-lop-10-mon-toan-c44a49473.html
[2025-05-19T08:34:33.170+0000] {connectionpool.py:812} WARNING - Retrying (Retry(total=2, connect=None, read=None, redirect=None, status=None)) after connection broken by 'NewConnectionError('<urllib3.connection.HTTPConnection object at 0x7f0b140d4fd0>: Failed to establish a new connection: [Errno 111] Connection refused')': /wd/hub/session
[2025-05-19T08:34:33.172+0000] {connectionpool.py:812} WARNING - Retrying (Retry(total=1, connect=None, read=None, redirect=None, status=None)) after connection broken by 'NewConnectionError('<urllib3.connection.HTTPConnection object at 0x7f0b140d4760>: Failed to establish a new connection: [Errno 111] Connection refused')': /wd/hub/session
[2025-05-19T08:34:33.176+0000] {connectionpool.py:812} WARNING - Retrying (Retry(total=0, connect=None, read=None, redirect=None, status=None)) after connection broken by 'NewConnectionError('<urllib3.connection.HTTPConnection object at 0x7f0b140d42e0>: Failed to establish a new connection: [Errno 111] Connection refused')': /wd/hub/session
[2025-05-19T08:34:33.180+0000] {MathDag.py:50} ERROR - Lỗi crawl link https://loigiaihay.com/de-so-11-de-thi-vao-lop-10-mon-toan-c44a49473.html: HTTPConnectionPool(host='localhost', port=4444): Max retries exceeded with url: /wd/hub/session (Caused by NewConnectionError('<urllib3.connection.HTTPConnection object at 0x7f0b140d4b20>: Failed to establish a new connection: [Errno 111] Connection refused'))
[2025-05-19T08:34:33.180+0000] {MathDag.py:45} INFO - Đang crawl link 33/64: https://loigiaihay.com/de-so-12-de-thi-vao-lop-10-mon-toan-c44a49474.html
[2025-05-19T08:34:33.183+0000] {connectionpool.py:812} WARNING - Retrying (Retry(total=2, connect=None, read=None, redirect=None, status=None)) after connection broken by 'NewConnectionError('<urllib3.connection.HTTPConnection object at 0x7f0b140f8820>: Failed to establish a new connection: [Errno 111] Connection refused')': /wd/hub/session
[2025-05-19T08:34:33.185+0000] {connectionpool.py:812} WARNING - Retrying (Retry(total=1, connect=None, read=None, redirect=None, status=None)) after connection broken by 'NewConnectionError('<urllib3.connection.HTTPConnection object at 0x7f0b140f8190>: Failed to establish a new connection: [Errno 111] Connection refused')': /wd/hub/session
[2025-05-19T08:34:33.186+0000] {connectionpool.py:812} WARNING - Retrying (Retry(total=0, connect=None, read=None, redirect=None, status=None)) after connection broken by 'NewConnectionError('<urllib3.connection.HTTPConnection object at 0x7f0b140f86d0>: Failed to establish a new connection: [Errno 111] Connection refused')': /wd/hub/session
[2025-05-19T08:34:33.188+0000] {MathDag.py:50} ERROR - Lỗi crawl link https://loigiaihay.com/de-so-12-de-thi-vao-lop-10-mon-toan-c44a49474.html: HTTPConnectionPool(host='localhost', port=4444): Max retries exceeded with url: /wd/hub/session (Caused by NewConnectionError('<urllib3.connection.HTTPConnection object at 0x7f0b140f8a90>: Failed to establish a new connection: [Errno 111] Connection refused'))
[2025-05-19T08:34:33.188+0000] {MathDag.py:45} INFO - Đang crawl link 34/64: https://loigiaihay.com/de-so-13-de-thi-vao-lop-10-mon-toan-c44a49515.html
[2025-05-19T08:34:33.190+0000] {connectionpool.py:812} WARNING - Retrying (Retry(total=2, connect=None, read=None, redirect=None, status=None)) after connection broken by 'NewConnectionError('<urllib3.connection.HTTPConnection object at 0x7f0b140e9f40>: Failed to establish a new connection: [Errno 111] Connection refused')': /wd/hub/session
[2025-05-19T08:34:33.190+0000] {connectionpool.py:812} WARNING - Retrying (Retry(total=1, connect=None, read=None, redirect=None, status=None)) after connection broken by 'NewConnectionError('<urllib3.connection.HTTPConnection object at 0x7f0b140900a0>: Failed to establish a new connection: [Errno 111] Connection refused')': /wd/hub/session
[2025-05-19T08:34:33.192+0000] {connectionpool.py:812} WARNING - Retrying (Retry(total=0, connect=None, read=None, redirect=None, status=None)) after connection broken by 'NewConnectionError('<urllib3.connection.HTTPConnection object at 0x7f0b14090250>: Failed to establish a new connection: [Errno 111] Connection refused')': /wd/hub/session
[2025-05-19T08:34:33.193+0000] {MathDag.py:50} ERROR - Lỗi crawl link https://loigiaihay.com/de-so-13-de-thi-vao-lop-10-mon-toan-c44a49515.html: HTTPConnectionPool(host='localhost', port=4444): Max retries exceeded with url: /wd/hub/session (Caused by NewConnectionError('<urllib3.connection.HTTPConnection object at 0x7f0b140903a0>: Failed to establish a new connection: [Errno 111] Connection refused'))
[2025-05-19T08:34:33.193+0000] {MathDag.py:45} INFO - Đang crawl link 35/64: https://loigiaihay.com/de-so-14-de-thi-vao-lop-10-mon-toan-c44a49529.html
[2025-05-19T08:34:33.194+0000] {connectionpool.py:812} WARNING - Retrying (Retry(total=2, connect=None, read=None, redirect=None, status=None)) after connection broken by 'NewConnectionError('<urllib3.connection.HTTPConnection object at 0x7f0b140f8850>: Failed to establish a new connection: [Errno 111] Connection refused')': /wd/hub/session
[2025-05-19T08:34:33.195+0000] {connectionpool.py:812} WARNING - Retrying (Retry(total=1, connect=None, read=None, redirect=None, status=None)) after connection broken by 'NewConnectionError('<urllib3.connection.HTTPConnection object at 0x7f0b140f86a0>: Failed to establish a new connection: [Errno 111] Connection refused')': /wd/hub/session
[2025-05-19T08:34:33.196+0000] {connectionpool.py:812} WARNING - Retrying (Retry(total=0, connect=None, read=None, redirect=None, status=None)) after connection broken by 'NewConnectionError('<urllib3.connection.HTTPConnection object at 0x7f0b140f8cd0>: Failed to establish a new connection: [Errno 111] Connection refused')': /wd/hub/session
[2025-05-19T08:34:33.196+0000] {MathDag.py:50} ERROR - Lỗi crawl link https://loigiaihay.com/de-so-14-de-thi-vao-lop-10-mon-toan-c44a49529.html: HTTPConnectionPool(host='localhost', port=4444): Max retries exceeded with url: /wd/hub/session (Caused by NewConnectionError('<urllib3.connection.HTTPConnection object at 0x7f0b140d4fa0>: Failed to establish a new connection: [Errno 111] Connection refused'))
[2025-05-19T08:34:33.197+0000] {MathDag.py:45} INFO - Đang crawl link 36/64: https://loigiaihay.com/de-so-15-de-thi-vao-lop-10-mon-toan-c44a49531.html
[2025-05-19T08:34:33.198+0000] {connectionpool.py:812} WARNING - Retrying (Retry(total=2, connect=None, read=None, redirect=None, status=None)) after connection broken by 'NewConnectionError('<urllib3.connection.HTTPConnection object at 0x7f0b140d4fd0>: Failed to establish a new connection: [Errno 111] Connection refused')': /wd/hub/session
[2025-05-19T08:34:33.199+0000] {connectionpool.py:812} WARNING - Retrying (Retry(total=1, connect=None, read=None, redirect=None, status=None)) after connection broken by 'NewConnectionError('<urllib3.connection.HTTPConnection object at 0x7f0b140d4400>: Failed to establish a new connection: [Errno 111] Connection refused')': /wd/hub/session
[2025-05-19T08:34:33.200+0000] {connectionpool.py:812} WARNING - Retrying (Retry(total=0, connect=None, read=None, redirect=None, status=None)) after connection broken by 'NewConnectionError('<urllib3.connection.HTTPConnection object at 0x7f0b140d4f70>: Failed to establish a new connection: [Errno 111] Connection refused')': /wd/hub/session
[2025-05-19T08:34:33.201+0000] {MathDag.py:50} ERROR - Lỗi crawl link https://loigiaihay.com/de-so-15-de-thi-vao-lop-10-mon-toan-c44a49531.html: HTTPConnectionPool(host='localhost', port=4444): Max retries exceeded with url: /wd/hub/session (Caused by NewConnectionError('<urllib3.connection.HTTPConnection object at 0x7f0b140d44f0>: Failed to establish a new connection: [Errno 111] Connection refused'))
[2025-05-19T08:34:33.201+0000] {MathDag.py:45} INFO - Đang crawl link 37/64: https://loigiaihay.com/de-so-16-de-thi-vao-lop-10-mon-toan-c44a49533.html
[2025-05-19T08:34:33.202+0000] {connectionpool.py:812} WARNING - Retrying (Retry(total=2, connect=None, read=None, redirect=None, status=None)) after connection broken by 'NewConnectionError('<urllib3.connection.HTTPConnection object at 0x7f0b140909a0>: Failed to establish a new connection: [Errno 111] Connection refused')': /wd/hub/session
[2025-05-19T08:34:33.203+0000] {connectionpool.py:812} WARNING - Retrying (Retry(total=1, connect=None, read=None, redirect=None, status=None)) after connection broken by 'NewConnectionError('<urllib3.connection.HTTPConnection object at 0x7f0b14090ac0>: Failed to establish a new connection: [Errno 111] Connection refused')': /wd/hub/session
[2025-05-19T08:34:33.203+0000] {connectionpool.py:812} WARNING - Retrying (Retry(total=0, connect=None, read=None, redirect=None, status=None)) after connection broken by 'NewConnectionError('<urllib3.connection.HTTPConnection object at 0x7f0b14090c70>: Failed to establish a new connection: [Errno 111] Connection refused')': /wd/hub/session
[2025-05-19T08:34:33.205+0000] {MathDag.py:50} ERROR - Lỗi crawl link https://loigiaihay.com/de-so-16-de-thi-vao-lop-10-mon-toan-c44a49533.html: HTTPConnectionPool(host='localhost', port=4444): Max retries exceeded with url: /wd/hub/session (Caused by NewConnectionError('<urllib3.connection.HTTPConnection object at 0x7f0b14090df0>: Failed to establish a new connection: [Errno 111] Connection refused'))
[2025-05-19T08:34:33.205+0000] {MathDag.py:45} INFO - Đang crawl link 38/64: https://loigiaihay.com/de-so-17-de-thi-vao-lop-10-mon-toan-c44a49536.html
[2025-05-19T08:34:33.207+0000] {connectionpool.py:812} WARNING - Retrying (Retry(total=2, connect=None, read=None, redirect=None, status=None)) after connection broken by 'NewConnectionError('<urllib3.connection.HTTPConnection object at 0x7f0b140d4ca0>: Failed to establish a new connection: [Errno 111] Connection refused')': /wd/hub/session
[2025-05-19T08:34:33.208+0000] {connectionpool.py:812} WARNING - Retrying (Retry(total=1, connect=None, read=None, redirect=None, status=None)) after connection broken by 'NewConnectionError('<urllib3.connection.HTTPConnection object at 0x7f0b140d4850>: Failed to establish a new connection: [Errno 111] Connection refused')': /wd/hub/session
[2025-05-19T08:34:33.208+0000] {connectionpool.py:812} WARNING - Retrying (Retry(total=0, connect=None, read=None, redirect=None, status=None)) after connection broken by 'NewConnectionError('<urllib3.connection.HTTPConnection object at 0x7f0b140d4220>: Failed to establish a new connection: [Errno 111] Connection refused')': /wd/hub/session
[2025-05-19T08:34:33.209+0000] {MathDag.py:50} ERROR - Lỗi crawl link https://loigiaihay.com/de-so-17-de-thi-vao-lop-10-mon-toan-c44a49536.html: HTTPConnectionPool(host='localhost', port=4444): Max retries exceeded with url: /wd/hub/session (Caused by NewConnectionError('<urllib3.connection.HTTPConnection object at 0x7f0b140d4cd0>: Failed to establish a new connection: [Errno 111] Connection refused'))
[2025-05-19T08:34:33.209+0000] {MathDag.py:45} INFO - Đang crawl link 39/64: https://loigiaihay.com/de-so-18-de-thi-vao-lop-10-mon-toan-c44a49538.html
[2025-05-19T08:34:33.210+0000] {connectionpool.py:812} WARNING - Retrying (Retry(total=2, connect=None, read=None, redirect=None, status=None)) after connection broken by 'NewConnectionError('<urllib3.connection.HTTPConnection object at 0x7f0b140f8160>: Failed to establish a new connection: [Errno 111] Connection refused')': /wd/hub/session
[2025-05-19T08:34:33.211+0000] {connectionpool.py:812} WARNING - Retrying (Retry(total=1, connect=None, read=None, redirect=None, status=None)) after connection broken by 'NewConnectionError('<urllib3.connection.HTTPConnection object at 0x7f0b140f8ac0>: Failed to establish a new connection: [Errno 111] Connection refused')': /wd/hub/session
[2025-05-19T08:34:33.213+0000] {connectionpool.py:812} WARNING - Retrying (Retry(total=0, connect=None, read=None, redirect=None, status=None)) after connection broken by 'NewConnectionError('<urllib3.connection.HTTPConnection object at 0x7f0b140f88e0>: Failed to establish a new connection: [Errno 111] Connection refused')': /wd/hub/session
[2025-05-19T08:34:33.214+0000] {MathDag.py:50} ERROR - Lỗi crawl link https://loigiaihay.com/de-so-18-de-thi-vao-lop-10-mon-toan-c44a49538.html: HTTPConnectionPool(host='localhost', port=4444): Max retries exceeded with url: /wd/hub/session (Caused by NewConnectionError('<urllib3.connection.HTTPConnection object at 0x7f0b14090ee0>: Failed to establish a new connection: [Errno 111] Connection refused'))
[2025-05-19T08:34:33.214+0000] {MathDag.py:45} INFO - Đang crawl link 40/64: https://loigiaihay.com/de-so-19-de-thi-vao-lop-10-mon-toan-c44a49540.html
[2025-05-19T08:34:33.215+0000] {connectionpool.py:812} WARNING - Retrying (Retry(total=2, connect=None, read=None, redirect=None, status=None)) after connection broken by 'NewConnectionError('<urllib3.connection.HTTPConnection object at 0x7f0b140a6430>: Failed to establish a new connection: [Errno 111] Connection refused')': /wd/hub/session
[2025-05-19T08:34:33.216+0000] {connectionpool.py:812} WARNING - Retrying (Retry(total=1, connect=None, read=None, redirect=None, status=None)) after connection broken by 'NewConnectionError('<urllib3.connection.HTTPConnection object at 0x7f0b140a6550>: Failed to establish a new connection: [Errno 111] Connection refused')': /wd/hub/session
[2025-05-19T08:34:33.217+0000] {connectionpool.py:812} WARNING - Retrying (Retry(total=0, connect=None, read=None, redirect=None, status=None)) after connection broken by 'NewConnectionError('<urllib3.connection.HTTPConnection object at 0x7f0b140a6700>: Failed to establish a new connection: [Errno 111] Connection refused')': /wd/hub/session
[2025-05-19T08:34:33.218+0000] {MathDag.py:50} ERROR - Lỗi crawl link https://loigiaihay.com/de-so-19-de-thi-vao-lop-10-mon-toan-c44a49540.html: HTTPConnectionPool(host='localhost', port=4444): Max retries exceeded with url: /wd/hub/session (Caused by NewConnectionError('<urllib3.connection.HTTPConnection object at 0x7f0b140a6850>: Failed to establish a new connection: [Errno 111] Connection refused'))
[2025-05-19T08:34:33.219+0000] {MathDag.py:45} INFO - Đang crawl link 41/64: https://loigiaihay.com/de-so-20-de-thi-vao-lop-10-mon-toan-c44a49541.html
[2025-05-19T08:34:33.220+0000] {connectionpool.py:812} WARNING - Retrying (Retry(total=2, connect=None, read=None, redirect=None, status=None)) after connection broken by 'NewConnectionError('<urllib3.connection.HTTPConnection object at 0x7f0b140f8a90>: Failed to establish a new connection: [Errno 111] Connection refused')': /wd/hub/session
[2025-05-19T08:34:33.221+0000] {connectionpool.py:812} WARNING - Retrying (Retry(total=1, connect=None, read=None, redirect=None, status=None)) after connection broken by 'NewConnectionError('<urllib3.connection.HTTPConnection object at 0x7f0b140f8490>: Failed to establish a new connection: [Errno 111] Connection refused')': /wd/hub/session
[2025-05-19T08:34:33.222+0000] {connectionpool.py:812} WARNING - Retrying (Retry(total=0, connect=None, read=None, redirect=None, status=None)) after connection broken by 'NewConnectionError('<urllib3.connection.HTTPConnection object at 0x7f0b140f8820>: Failed to establish a new connection: [Errno 111] Connection refused')': /wd/hub/session
[2025-05-19T08:34:33.222+0000] {MathDag.py:50} ERROR - Lỗi crawl link https://loigiaihay.com/de-so-20-de-thi-vao-lop-10-mon-toan-c44a49541.html: HTTPConnectionPool(host='localhost', port=4444): Max retries exceeded with url: /wd/hub/session (Caused by NewConnectionError('<urllib3.connection.HTTPConnection object at 0x7f0b140d4730>: Failed to establish a new connection: [Errno 111] Connection refused'))
[2025-05-19T08:34:33.222+0000] {MathDag.py:45} INFO - Đang crawl link 42/64: https://loigiaihay.com/de-so-21-de-thi-vao-lop-10-mon-toan-c44a49573.html
[2025-05-19T08:34:33.224+0000] {connectionpool.py:812} WARNING - Retrying (Retry(total=2, connect=None, read=None, redirect=None, status=None)) after connection broken by 'NewConnectionError('<urllib3.connection.HTTPConnection object at 0x7f0b140d4c10>: Failed to establish a new connection: [Errno 111] Connection refused')': /wd/hub/session
[2025-05-19T08:34:33.224+0000] {connectionpool.py:812} WARNING - Retrying (Retry(total=1, connect=None, read=None, redirect=None, status=None)) after connection broken by 'NewConnectionError('<urllib3.connection.HTTPConnection object at 0x7f0b140d4670>: Failed to establish a new connection: [Errno 111] Connection refused')': /wd/hub/session
[2025-05-19T08:34:33.225+0000] {connectionpool.py:812} WARNING - Retrying (Retry(total=0, connect=None, read=None, redirect=None, status=None)) after connection broken by 'NewConnectionError('<urllib3.connection.HTTPConnection object at 0x7f0b140d40d0>: Failed to establish a new connection: [Errno 111] Connection refused')': /wd/hub/session
[2025-05-19T08:34:33.226+0000] {MathDag.py:50} ERROR - Lỗi crawl link https://loigiaihay.com/de-so-21-de-thi-vao-lop-10-mon-toan-c44a49573.html: HTTPConnectionPool(host='localhost', port=4444): Max retries exceeded with url: /wd/hub/session (Caused by NewConnectionError('<urllib3.connection.HTTPConnection object at 0x7f0b140a69a0>: Failed to establish a new connection: [Errno 111] Connection refused'))
[2025-05-19T08:34:33.226+0000] {MathDag.py:45} INFO - Đang crawl link 43/64: https://loigiaihay.com/de-so-22-de-thi-vao-lop-10-mon-toan-c44a49582.html
[2025-05-19T08:34:33.228+0000] {connectionpool.py:812} WARNING - Retrying (Retry(total=2, connect=None, read=None, redirect=None, status=None)) after connection broken by 'NewConnectionError('<urllib3.connection.HTTPConnection object at 0x7f0b140a6e50>: Failed to establish a new connection: [Errno 111] Connection refused')': /wd/hub/session
[2025-05-19T08:34:33.228+0000] {connectionpool.py:812} WARNING - Retrying (Retry(total=1, connect=None, read=None, redirect=None, status=None)) after connection broken by 'NewConnectionError('<urllib3.connection.HTTPConnection object at 0x7f0b140ba070>: Failed to establish a new connection: [Errno 111] Connection refused')': /wd/hub/session
[2025-05-19T08:34:33.229+0000] {connectionpool.py:812} WARNING - Retrying (Retry(total=0, connect=None, read=None, redirect=None, status=None)) after connection broken by 'NewConnectionError('<urllib3.connection.HTTPConnection object at 0x7f0b140ba160>: Failed to establish a new connection: [Errno 111] Connection refused')': /wd/hub/session
[2025-05-19T08:34:33.230+0000] {MathDag.py:50} ERROR - Lỗi crawl link https://loigiaihay.com/de-so-22-de-thi-vao-lop-10-mon-toan-c44a49582.html: HTTPConnectionPool(host='localhost', port=4444): Max retries exceeded with url: /wd/hub/session (Caused by NewConnectionError('<urllib3.connection.HTTPConnection object at 0x7f0b140ba2b0>: Failed to establish a new connection: [Errno 111] Connection refused'))
[2025-05-19T08:34:33.230+0000] {MathDag.py:45} INFO - Đang crawl link 44/64: https://loigiaihay.com/de-so-23-de-thi-vao-lop-10-mon-toan-c44a49583.html
[2025-05-19T08:34:33.231+0000] {connectionpool.py:812} WARNING - Retrying (Retry(total=2, connect=None, read=None, redirect=None, status=None)) after connection broken by 'NewConnectionError('<urllib3.connection.HTTPConnection object at 0x7f0b140d4910>: Failed to establish a new connection: [Errno 111] Connection refused')': /wd/hub/session
[2025-05-19T08:34:33.231+0000] {connectionpool.py:812} WARNING - Retrying (Retry(total=1, connect=None, read=None, redirect=None, status=None)) after connection broken by 'NewConnectionError('<urllib3.connection.HTTPConnection object at 0x7f0b140d4340>: Failed to establish a new connection: [Errno 111] Connection refused')': /wd/hub/session
[2025-05-19T08:34:33.232+0000] {connectionpool.py:812} WARNING - Retrying (Retry(total=0, connect=None, read=None, redirect=None, status=None)) after connection broken by 'NewConnectionError('<urllib3.connection.HTTPConnection object at 0x7f0b140d4970>: Failed to establish a new connection: [Errno 111] Connection refused')': /wd/hub/session
[2025-05-19T08:34:33.233+0000] {MathDag.py:50} ERROR - Lỗi crawl link https://loigiaihay.com/de-so-23-de-thi-vao-lop-10-mon-toan-c44a49583.html: HTTPConnectionPool(host='localhost', port=4444): Max retries exceeded with url: /wd/hub/session (Caused by NewConnectionError('<urllib3.connection.HTTPConnection object at 0x7f0b140d4610>: Failed to establish a new connection: [Errno 111] Connection refused'))
[2025-05-19T08:34:33.233+0000] {MathDag.py:45} INFO - Đang crawl link 45/64: https://loigiaihay.com/de-so-24-de-thi-vao-lop-10-mon-toan-c44a49585.html
[2025-05-19T08:34:33.235+0000] {connectionpool.py:812} WARNING - Retrying (Retry(total=2, connect=None, read=None, redirect=None, status=None)) after connection broken by 'NewConnectionError('<urllib3.connection.HTTPConnection object at 0x7f0b140f8160>: Failed to establish a new connection: [Errno 111] Connection refused')': /wd/hub/session
[2025-05-19T08:34:33.235+0000] {connectionpool.py:812} WARNING - Retrying (Retry(total=1, connect=None, read=None, redirect=None, status=None)) after connection broken by 'NewConnectionError('<urllib3.connection.HTTPConnection object at 0x7f0b140f8d30>: Failed to establish a new connection: [Errno 111] Connection refused')': /wd/hub/session
[2025-05-19T08:34:33.236+0000] {connectionpool.py:812} WARNING - Retrying (Retry(total=0, connect=None, read=None, redirect=None, status=None)) after connection broken by 'NewConnectionError('<urllib3.connection.HTTPConnection object at 0x7f0b14090ee0>: Failed to establish a new connection: [Errno 111] Connection refused')': /wd/hub/session
[2025-05-19T08:34:33.236+0000] {MathDag.py:50} ERROR - Lỗi crawl link https://loigiaihay.com/de-so-24-de-thi-vao-lop-10-mon-toan-c44a49585.html: HTTPConnectionPool(host='localhost', port=4444): Max retries exceeded with url: /wd/hub/session (Caused by NewConnectionError('<urllib3.connection.HTTPConnection object at 0x7f0b140a6940>: Failed to establish a new connection: [Errno 111] Connection refused'))
[2025-05-19T08:34:33.237+0000] {MathDag.py:45} INFO - Đang crawl link 46/64: https://loigiaihay.com/de-so-25-de-thi-vao-lop-10-mon-toan-c44a49613.html
[2025-05-19T08:34:33.238+0000] {connectionpool.py:812} WARNING - Retrying (Retry(total=2, connect=None, read=None, redirect=None, status=None)) after connection broken by 'NewConnectionError('<urllib3.connection.HTTPConnection object at 0x7f0b140ba8b0>: Failed to establish a new connection: [Errno 111] Connection refused')': /wd/hub/session
[2025-05-19T08:34:33.239+0000] {connectionpool.py:812} WARNING - Retrying (Retry(total=1, connect=None, read=None, redirect=None, status=None)) after connection broken by 'NewConnectionError('<urllib3.connection.HTTPConnection object at 0x7f0b140ba9d0>: Failed to establish a new connection: [Errno 111] Connection refused')': /wd/hub/session
[2025-05-19T08:34:33.241+0000] {connectionpool.py:812} WARNING - Retrying (Retry(total=0, connect=None, read=None, redirect=None, status=None)) after connection broken by 'NewConnectionError('<urllib3.connection.HTTPConnection object at 0x7f0b140bab80>: Failed to establish a new connection: [Errno 111] Connection refused')': /wd/hub/session
[2025-05-19T08:34:33.243+0000] {MathDag.py:50} ERROR - Lỗi crawl link https://loigiaihay.com/de-so-25-de-thi-vao-lop-10-mon-toan-c44a49613.html: HTTPConnectionPool(host='localhost', port=4444): Max retries exceeded with url: /wd/hub/session (Caused by NewConnectionError('<urllib3.connection.HTTPConnection object at 0x7f0b140bacd0>: Failed to establish a new connection: [Errno 111] Connection refused'))
[2025-05-19T08:34:33.243+0000] {MathDag.py:45} INFO - Đang crawl link 47/64: https://loigiaihay.com/de-so-26-de-thi-vao-lop-10-mon-toan-c44a49614.html
[2025-05-19T08:34:33.244+0000] {connectionpool.py:812} WARNING - Retrying (Retry(total=2, connect=None, read=None, redirect=None, status=None)) after connection broken by 'NewConnectionError('<urllib3.connection.HTTPConnection object at 0x7f0b140a6d60>: Failed to establish a new connection: [Errno 111] Connection refused')': /wd/hub/session
[2025-05-19T08:34:33.244+0000] {connectionpool.py:812} WARNING - Retrying (Retry(total=1, connect=None, read=None, redirect=None, status=None)) after connection broken by 'NewConnectionError('<urllib3.connection.HTTPConnection object at 0x7f0b140a6bb0>: Failed to establish a new connection: [Errno 111] Connection refused')': /wd/hub/session
[2025-05-19T08:34:33.245+0000] {connectionpool.py:812} WARNING - Retrying (Retry(total=0, connect=None, read=None, redirect=None, status=None)) after connection broken by 'NewConnectionError('<urllib3.connection.HTTPConnection object at 0x7f0b140a6130>: Failed to establish a new connection: [Errno 111] Connection refused')': /wd/hub/session
[2025-05-19T08:34:33.246+0000] {MathDag.py:50} ERROR - Lỗi crawl link https://loigiaihay.com/de-so-26-de-thi-vao-lop-10-mon-toan-c44a49614.html: HTTPConnectionPool(host='localhost', port=4444): Max retries exceeded with url: /wd/hub/session (Caused by NewConnectionError('<urllib3.connection.HTTPConnection object at 0x7f0b140a65e0>: Failed to establish a new connection: [Errno 111] Connection refused'))
[2025-05-19T08:34:33.246+0000] {MathDag.py:45} INFO - Đang crawl link 48/64: https://loigiaihay.com/de-so-27-de-thi-vao-lop-10-mon-toan-c44a49615.html
[2025-05-19T08:34:33.247+0000] {connectionpool.py:812} WARNING - Retrying (Retry(total=2, connect=None, read=None, redirect=None, status=None)) after connection broken by 'NewConnectionError('<urllib3.connection.HTTPConnection object at 0x7f0b140a6220>: Failed to establish a new connection: [Errno 111] Connection refused')': /wd/hub/session
[2025-05-19T08:34:33.248+0000] {connectionpool.py:812} WARNING - Retrying (Retry(total=1, connect=None, read=None, redirect=None, status=None)) after connection broken by 'NewConnectionError('<urllib3.connection.HTTPConnection object at 0x7f0b14090460>: Failed to establish a new connection: [Errno 111] Connection refused')': /wd/hub/session
[2025-05-19T08:34:33.249+0000] {connectionpool.py:812} WARNING - Retrying (Retry(total=0, connect=None, read=None, redirect=None, status=None)) after connection broken by 'NewConnectionError('<urllib3.connection.HTTPConnection object at 0x7f0b14090fd0>: Failed to establish a new connection: [Errno 111] Connection refused')': /wd/hub/session
[2025-05-19T08:34:33.249+0000] {MathDag.py:50} ERROR - Lỗi crawl link https://loigiaihay.com/de-so-27-de-thi-vao-lop-10-mon-toan-c44a49615.html: HTTPConnectionPool(host='localhost', port=4444): Max retries exceeded with url: /wd/hub/session (Caused by NewConnectionError('<urllib3.connection.HTTPConnection object at 0x7f0b14090a60>: Failed to establish a new connection: [Errno 111] Connection refused'))
[2025-05-19T08:34:33.249+0000] {MathDag.py:45} INFO - Đang crawl link 49/64: https://loigiaihay.com/de-so-28-de-thi-vao-lop-10-mon-toan-c44a49616.html
[2025-05-19T08:34:33.250+0000] {connectionpool.py:812} WARNING - Retrying (Retry(total=2, connect=None, read=None, redirect=None, status=None)) after connection broken by 'NewConnectionError('<urllib3.connection.HTTPConnection object at 0x7f0b14090910>: Failed to establish a new connection: [Errno 111] Connection refused')': /wd/hub/session
[2025-05-19T08:34:33.251+0000] {connectionpool.py:812} WARNING - Retrying (Retry(total=1, connect=None, read=None, redirect=None, status=None)) after connection broken by 'NewConnectionError('<urllib3.connection.HTTPConnection object at 0x7f0b140907f0>: Failed to establish a new connection: [Errno 111] Connection refused')': /wd/hub/session
[2025-05-19T08:34:33.251+0000] {connectionpool.py:812} WARNING - Retrying (Retry(total=0, connect=None, read=None, redirect=None, status=None)) after connection broken by 'NewConnectionError('<urllib3.connection.HTTPConnection object at 0x7f0b140904f0>: Failed to establish a new connection: [Errno 111] Connection refused')': /wd/hub/session
[2025-05-19T08:34:33.252+0000] {MathDag.py:50} ERROR - Lỗi crawl link https://loigiaihay.com/de-so-28-de-thi-vao-lop-10-mon-toan-c44a49616.html: HTTPConnectionPool(host='localhost', port=4444): Max retries exceeded with url: /wd/hub/session (Caused by NewConnectionError('<urllib3.connection.HTTPConnection object at 0x7f0b140902b0>: Failed to establish a new connection: [Errno 111] Connection refused'))
[2025-05-19T08:34:33.252+0000] {MathDag.py:45} INFO - Đang crawl link 50/64: https://loigiaihay.com/de-so-29-de-thi-vao-lop-10-mon-toan-c44a49621.html
[2025-05-19T08:34:33.253+0000] {connectionpool.py:812} WARNING - Retrying (Retry(total=2, connect=None, read=None, redirect=None, status=None)) after connection broken by 'NewConnectionError('<urllib3.connection.HTTPConnection object at 0x7f0b140e9b80>: Failed to establish a new connection: [Errno 111] Connection refused')': /wd/hub/session
[2025-05-19T08:34:33.254+0000] {connectionpool.py:812} WARNING - Retrying (Retry(total=1, connect=None, read=None, redirect=None, status=None)) after connection broken by 'NewConnectionError('<urllib3.connection.HTTPConnection object at 0x7f0b14090bb0>: Failed to establish a new connection: [Errno 111] Connection refused')': /wd/hub/session
[2025-05-19T08:34:33.255+0000] {connectionpool.py:812} WARNING - Retrying (Retry(total=0, connect=None, read=None, redirect=None, status=None)) after connection broken by 'NewConnectionError('<urllib3.connection.HTTPConnection object at 0x7f0b14090280>: Failed to establish a new connection: [Errno 111] Connection refused')': /wd/hub/session
[2025-05-19T08:34:33.255+0000] {MathDag.py:50} ERROR - Lỗi crawl link https://loigiaihay.com/de-so-29-de-thi-vao-lop-10-mon-toan-c44a49621.html: HTTPConnectionPool(host='localhost', port=4444): Max retries exceeded with url: /wd/hub/session (Caused by NewConnectionError('<urllib3.connection.HTTPConnection object at 0x7f0b140900a0>: Failed to establish a new connection: [Errno 111] Connection refused'))
[2025-05-19T08:34:33.255+0000] {MathDag.py:45} INFO - Đang crawl link 51/64: https://loigiaihay.com/de-so-30-de-thi-vao-lop-10-mon-toan-c44a49629.html
[2025-05-19T08:34:33.256+0000] {connectionpool.py:812} WARNING - Retrying (Retry(total=2, connect=None, read=None, redirect=None, status=None)) after connection broken by 'NewConnectionError('<urllib3.connection.HTTPConnection object at 0x7f0b14090b20>: Failed to establish a new connection: [Errno 111] Connection refused')': /wd/hub/session
[2025-05-19T08:34:33.257+0000] {connectionpool.py:812} WARNING - Retrying (Retry(total=1, connect=None, read=None, redirect=None, status=None)) after connection broken by 'NewConnectionError('<urllib3.connection.HTTPConnection object at 0x7f0b14090a00>: Failed to establish a new connection: [Errno 111] Connection refused')': /wd/hub/session
[2025-05-19T08:34:33.257+0000] {connectionpool.py:812} WARNING - Retrying (Retry(total=0, connect=None, read=None, redirect=None, status=None)) after connection broken by 'NewConnectionError('<urllib3.connection.HTTPConnection object at 0x7f0b140906d0>: Failed to establish a new connection: [Errno 111] Connection refused')': /wd/hub/session
[2025-05-19T08:34:33.257+0000] {MathDag.py:50} ERROR - Lỗi crawl link https://loigiaihay.com/de-so-30-de-thi-vao-lop-10-mon-toan-c44a49629.html: HTTPConnectionPool(host='localhost', port=4444): Max retries exceeded with url: /wd/hub/session (Caused by NewConnectionError('<urllib3.connection.HTTPConnection object at 0x7f0b141848e0>: Failed to establish a new connection: [Errno 111] Connection refused'))
[2025-05-19T08:34:33.258+0000] {MathDag.py:45} INFO - Đang crawl link 52/64: https://loigiaihay.com/de-so-31-de-thi-vao-lop-10-mon-toan-c44a49640.html
[2025-05-19T08:34:33.259+0000] {connectionpool.py:812} WARNING - Retrying (Retry(total=2, connect=None, read=None, redirect=None, status=None)) after connection broken by 'NewConnectionError('<urllib3.connection.HTTPConnection object at 0x7f0b140a64c0>: Failed to establish a new connection: [Errno 111] Connection refused')': /wd/hub/session
[2025-05-19T08:34:33.259+0000] {connectionpool.py:812} WARNING - Retrying (Retry(total=1, connect=None, read=None, redirect=None, status=None)) after connection broken by 'NewConnectionError('<urllib3.connection.HTTPConnection object at 0x7f0b140a6760>: Failed to establish a new connection: [Errno 111] Connection refused')': /wd/hub/session
[2025-05-19T08:34:33.260+0000] {connectionpool.py:812} WARNING - Retrying (Retry(total=0, connect=None, read=None, redirect=None, status=None)) after connection broken by 'NewConnectionError('<urllib3.connection.HTTPConnection object at 0x7f0b140a6460>: Failed to establish a new connection: [Errno 111] Connection refused')': /wd/hub/session
[2025-05-19T08:34:33.261+0000] {MathDag.py:50} ERROR - Lỗi crawl link https://loigiaihay.com/de-so-31-de-thi-vao-lop-10-mon-toan-c44a49640.html: HTTPConnectionPool(host='localhost', port=4444): Max retries exceeded with url: /wd/hub/session (Caused by NewConnectionError('<urllib3.connection.HTTPConnection object at 0x7f0b140a6130>: Failed to establish a new connection: [Errno 111] Connection refused'))
[2025-05-19T08:34:33.261+0000] {MathDag.py:45} INFO - Đang crawl link 53/64: https://loigiaihay.com/de-so-32-de-thi-vao-lop-10-mon-toan-c44a49639.html
[2025-05-19T08:34:33.262+0000] {connectionpool.py:812} WARNING - Retrying (Retry(total=2, connect=None, read=None, redirect=None, status=None)) after connection broken by 'NewConnectionError('<urllib3.connection.HTTPConnection object at 0x7f0b140e9e20>: Failed to establish a new connection: [Errno 111] Connection refused')': /wd/hub/session
[2025-05-19T08:34:33.263+0000] {connectionpool.py:812} WARNING - Retrying (Retry(total=1, connect=None, read=None, redirect=None, status=None)) after connection broken by 'NewConnectionError('<urllib3.connection.HTTPConnection object at 0x7f0b140e9eb0>: Failed to establish a new connection: [Errno 111] Connection refused')': /wd/hub/session
[2025-05-19T08:34:33.263+0000] {connectionpool.py:812} WARNING - Retrying (Retry(total=0, connect=None, read=None, redirect=None, status=None)) after connection broken by 'NewConnectionError('<urllib3.connection.HTTPConnection object at 0x7f0b140e9400>: Failed to establish a new connection: [Errno 111] Connection refused')': /wd/hub/session
[2025-05-19T08:34:33.264+0000] {MathDag.py:50} ERROR - Lỗi crawl link https://loigiaihay.com/de-so-32-de-thi-vao-lop-10-mon-toan-c44a49639.html: HTTPConnectionPool(host='localhost', port=4444): Max retries exceeded with url: /wd/hub/session (Caused by NewConnectionError('<urllib3.connection.HTTPConnection object at 0x7f0b141848e0>: Failed to establish a new connection: [Errno 111] Connection refused'))
[2025-05-19T08:34:33.264+0000] {MathDag.py:45} INFO - Đang crawl link 54/64: https://loigiaihay.com/de-so-33-de-thi-vao-lop-10-mon-toan-c44a49641.html
[2025-05-19T08:34:33.265+0000] {connectionpool.py:812} WARNING - Retrying (Retry(total=2, connect=None, read=None, redirect=None, status=None)) after connection broken by 'NewConnectionError('<urllib3.connection.HTTPConnection object at 0x7f0b140a66d0>: Failed to establish a new connection: [Errno 111] Connection refused')': /wd/hub/session
[2025-05-19T08:34:33.265+0000] {connectionpool.py:812} WARNING - Retrying (Retry(total=1, connect=None, read=None, redirect=None, status=None)) after connection broken by 'NewConnectionError('<urllib3.connection.HTTPConnection object at 0x7f0b140a67c0>: Failed to establish a new connection: [Errno 111] Connection refused')': /wd/hub/session
[2025-05-19T08:34:33.266+0000] {connectionpool.py:812} WARNING - Retrying (Retry(total=0, connect=None, read=None, redirect=None, status=None)) after connection broken by 'NewConnectionError('<urllib3.connection.HTTPConnection object at 0x7f0b140a6280>: Failed to establish a new connection: [Errno 111] Connection refused')': /wd/hub/session
[2025-05-19T08:34:33.266+0000] {MathDag.py:50} ERROR - Lỗi crawl link https://loigiaihay.com/de-so-33-de-thi-vao-lop-10-mon-toan-c44a49641.html: HTTPConnectionPool(host='localhost', port=4444): Max retries exceeded with url: /wd/hub/session (Caused by NewConnectionError('<urllib3.connection.HTTPConnection object at 0x7f0b140a68e0>: Failed to establish a new connection: [Errno 111] Connection refused'))
[2025-05-19T08:34:33.266+0000] {MathDag.py:45} INFO - Đang crawl link 55/64: https://loigiaihay.com/de-so-34-de-thi-vao-lop-10-mon-toan-c44a49643.html
[2025-05-19T08:34:33.268+0000] {connectionpool.py:812} WARNING - Retrying (Retry(total=2, connect=None, read=None, redirect=None, status=None)) after connection broken by 'NewConnectionError('<urllib3.connection.HTTPConnection object at 0x7f0b14090c70>: Failed to establish a new connection: [Errno 111] Connection refused')': /wd/hub/session
[2025-05-19T08:34:33.269+0000] {connectionpool.py:812} WARNING - Retrying (Retry(total=1, connect=None, read=None, redirect=None, status=None)) after connection broken by 'NewConnectionError('<urllib3.connection.HTTPConnection object at 0x7f0b14090d90>: Failed to establish a new connection: [Errno 111] Connection refused')': /wd/hub/session
[2025-05-19T08:34:33.269+0000] {connectionpool.py:812} WARNING - Retrying (Retry(total=0, connect=None, read=None, redirect=None, status=None)) after connection broken by 'NewConnectionError('<urllib3.connection.HTTPConnection object at 0x7f0b14090790>: Failed to establish a new connection: [Errno 111] Connection refused')': /wd/hub/session
[2025-05-19T08:34:33.270+0000] {MathDag.py:50} ERROR - Lỗi crawl link https://loigiaihay.com/de-so-34-de-thi-vao-lop-10-mon-toan-c44a49643.html: HTTPConnectionPool(host='localhost', port=4444): Max retries exceeded with url: /wd/hub/session (Caused by NewConnectionError('<urllib3.connection.HTTPConnection object at 0x7f0b14090190>: Failed to establish a new connection: [Errno 111] Connection refused'))
[2025-05-19T08:34:33.270+0000] {MathDag.py:45} INFO - Đang crawl link 56/64: https://loigiaihay.com/de-so-35-de-thi-vao-lop-10-mon-toan-c44a49644.html
[2025-05-19T08:34:33.271+0000] {connectionpool.py:812} WARNING - Retrying (Retry(total=2, connect=None, read=None, redirect=None, status=None)) after connection broken by 'NewConnectionError('<urllib3.connection.HTTPConnection object at 0x7f0b140e99a0>: Failed to establish a new connection: [Errno 111] Connection refused')': /wd/hub/session
[2025-05-19T08:34:33.271+0000] {connectionpool.py:812} WARNING - Retrying (Retry(total=1, connect=None, read=None, redirect=None, status=None)) after connection broken by 'NewConnectionError('<urllib3.connection.HTTPConnection object at 0x7f0b140e94f0>: Failed to establish a new connection: [Errno 111] Connection refused')': /wd/hub/session
[2025-05-19T08:34:33.272+0000] {connectionpool.py:812} WARNING - Retrying (Retry(total=0, connect=None, read=None, redirect=None, status=None)) after connection broken by 'NewConnectionError('<urllib3.connection.HTTPConnection object at 0x7f0b140e91c0>: Failed to establish a new connection: [Errno 111] Connection refused')': /wd/hub/session
[2025-05-19T08:34:33.272+0000] {MathDag.py:50} ERROR - Lỗi crawl link https://loigiaihay.com/de-so-35-de-thi-vao-lop-10-mon-toan-c44a49644.html: HTTPConnectionPool(host='localhost', port=4444): Max retries exceeded with url: /wd/hub/session (Caused by NewConnectionError('<urllib3.connection.HTTPConnection object at 0x7f0b140e9160>: Failed to establish a new connection: [Errno 111] Connection refused'))
[2025-05-19T08:34:33.272+0000] {MathDag.py:45} INFO - Đang crawl link 57/64: https://loigiaihay.com/de-so-36-de-thi-vao-lop-10-mon-toan-c44a49645.html
[2025-05-19T08:34:33.274+0000] {connectionpool.py:812} WARNING - Retrying (Retry(total=2, connect=None, read=None, redirect=None, status=None)) after connection broken by 'NewConnectionError('<urllib3.connection.HTTPConnection object at 0x7f0b140e90a0>: Failed to establish a new connection: [Errno 111] Connection refused')': /wd/hub/session
[2025-05-19T08:34:33.274+0000] {connectionpool.py:812} WARNING - Retrying (Retry(total=1, connect=None, read=None, redirect=None, status=None)) after connection broken by 'NewConnectionError('<urllib3.connection.HTTPConnection object at 0x7f0b140e9250>: Failed to establish a new connection: [Errno 111] Connection refused')': /wd/hub/session
[2025-05-19T08:34:33.275+0000] {connectionpool.py:812} WARNING - Retrying (Retry(total=0, connect=None, read=None, redirect=None, status=None)) after connection broken by 'NewConnectionError('<urllib3.connection.HTTPConnection object at 0x7f0b140e99a0>: Failed to establish a new connection: [Errno 111] Connection refused')': /wd/hub/session
[2025-05-19T08:34:33.275+0000] {MathDag.py:50} ERROR - Lỗi crawl link https://loigiaihay.com/de-so-36-de-thi-vao-lop-10-mon-toan-c44a49645.html: HTTPConnectionPool(host='localhost', port=4444): Max retries exceeded with url: /wd/hub/session (Caused by NewConnectionError('<urllib3.connection.HTTPConnection object at 0x7f0b140e9850>: Failed to establish a new connection: [Errno 111] Connection refused'))
[2025-05-19T08:34:33.276+0000] {MathDag.py:45} INFO - Đang crawl link 58/64: https://loigiaihay.com/de-so-37-de-thi-vao-lop-10-mon-toan-c44a49646.html
[2025-05-19T08:34:33.276+0000] {connectionpool.py:812} WARNING - Retrying (Retry(total=2, connect=None, read=None, redirect=None, status=None)) after connection broken by 'NewConnectionError('<urllib3.connection.HTTPConnection object at 0x7f0b14090e50>: Failed to establish a new connection: [Errno 111] Connection refused')': /wd/hub/session
[2025-05-19T08:34:33.277+0000] {connectionpool.py:812} WARNING - Retrying (Retry(total=1, connect=None, read=None, redirect=None, status=None)) after connection broken by 'NewConnectionError('<urllib3.connection.HTTPConnection object at 0x7f0b140905b0>: Failed to establish a new connection: [Errno 111] Connection refused')': /wd/hub/session
[2025-05-19T08:34:33.278+0000] {connectionpool.py:812} WARNING - Retrying (Retry(total=0, connect=None, read=None, redirect=None, status=None)) after connection broken by 'NewConnectionError('<urllib3.connection.HTTPConnection object at 0x7f0b14090580>: Failed to establish a new connection: [Errno 111] Connection refused')': /wd/hub/session
[2025-05-19T08:34:33.278+0000] {MathDag.py:50} ERROR - Lỗi crawl link https://loigiaihay.com/de-so-37-de-thi-vao-lop-10-mon-toan-c44a49646.html: HTTPConnectionPool(host='localhost', port=4444): Max retries exceeded with url: /wd/hub/session (Caused by NewConnectionError('<urllib3.connection.HTTPConnection object at 0x7f0b14090a30>: Failed to establish a new connection: [Errno 111] Connection refused'))
[2025-05-19T08:34:33.278+0000] {MathDag.py:45} INFO - Đang crawl link 59/64: https://loigiaihay.com/de-so-38-de-thi-vao-lop-10-mon-toan-c44a49647.html
[2025-05-19T08:34:33.279+0000] {connectionpool.py:812} WARNING - Retrying (Retry(total=2, connect=None, read=None, redirect=None, status=None)) after connection broken by 'NewConnectionError('<urllib3.connection.HTTPConnection object at 0x7f0b140a6400>: Failed to establish a new connection: [Errno 111] Connection refused')': /wd/hub/session
[2025-05-19T08:34:33.280+0000] {connectionpool.py:812} WARNING - Retrying (Retry(total=1, connect=None, read=None, redirect=None, status=None)) after connection broken by 'NewConnectionError('<urllib3.connection.HTTPConnection object at 0x7f0b140a6250>: Failed to establish a new connection: [Errno 111] Connection refused')': /wd/hub/session
[2025-05-19T08:34:33.280+0000] {connectionpool.py:812} WARNING - Retrying (Retry(total=0, connect=None, read=None, redirect=None, status=None)) after connection broken by 'NewConnectionError('<urllib3.connection.HTTPConnection object at 0x7f0b140a62e0>: Failed to establish a new connection: [Errno 111] Connection refused')': /wd/hub/session
[2025-05-19T08:34:33.281+0000] {MathDag.py:50} ERROR - Lỗi crawl link https://loigiaihay.com/de-so-38-de-thi-vao-lop-10-mon-toan-c44a49647.html: HTTPConnectionPool(host='localhost', port=4444): Max retries exceeded with url: /wd/hub/session (Caused by NewConnectionError('<urllib3.connection.HTTPConnection object at 0x7f0b140a6be0>: Failed to establish a new connection: [Errno 111] Connection refused'))
[2025-05-19T08:34:33.281+0000] {MathDag.py:45} INFO - Đang crawl link 60/64: https://loigiaihay.com/de-so-39-de-thi-vao-lop-10-mon-toan-c44a49648.html
[2025-05-19T08:34:33.282+0000] {connectionpool.py:812} WARNING - Retrying (Retry(total=2, connect=None, read=None, redirect=None, status=None)) after connection broken by 'NewConnectionError('<urllib3.connection.HTTPConnection object at 0x7f0b140f8d00>: Failed to establish a new connection: [Errno 111] Connection refused')': /wd/hub/session
[2025-05-19T08:34:33.283+0000] {connectionpool.py:812} WARNING - Retrying (Retry(total=1, connect=None, read=None, redirect=None, status=None)) after connection broken by 'NewConnectionError('<urllib3.connection.HTTPConnection object at 0x7f0b140f8850>: Failed to establish a new connection: [Errno 111] Connection refused')': /wd/hub/session
[2025-05-19T08:34:33.284+0000] {connectionpool.py:812} WARNING - Retrying (Retry(total=0, connect=None, read=None, redirect=None, status=None)) after connection broken by 'NewConnectionError('<urllib3.connection.HTTPConnection object at 0x7f0b140a6730>: Failed to establish a new connection: [Errno 111] Connection refused')': /wd/hub/session
[2025-05-19T08:34:33.284+0000] {MathDag.py:50} ERROR - Lỗi crawl link https://loigiaihay.com/de-so-39-de-thi-vao-lop-10-mon-toan-c44a49648.html: HTTPConnectionPool(host='localhost', port=4444): Max retries exceeded with url: /wd/hub/session (Caused by NewConnectionError('<urllib3.connection.HTTPConnection object at 0x7f0b140a6be0>: Failed to establish a new connection: [Errno 111] Connection refused'))
[2025-05-19T08:34:33.285+0000] {MathDag.py:45} INFO - Đang crawl link 61/64: https://loigiaihay.com/de-so-40-de-thi-vao-lop-10-mon-toan-c44a49649.html
[2025-05-19T08:34:33.286+0000] {connectionpool.py:812} WARNING - Retrying (Retry(total=2, connect=None, read=None, redirect=None, status=None)) after connection broken by 'NewConnectionError('<urllib3.connection.HTTPConnection object at 0x7f0b14090d30>: Failed to establish a new connection: [Errno 111] Connection refused')': /wd/hub/session
[2025-05-19T08:34:33.286+0000] {connectionpool.py:812} WARNING - Retrying (Retry(total=1, connect=None, read=None, redirect=None, status=None)) after connection broken by 'NewConnectionError('<urllib3.connection.HTTPConnection object at 0x7f0b140909a0>: Failed to establish a new connection: [Errno 111] Connection refused')': /wd/hub/session
[2025-05-19T08:34:33.287+0000] {connectionpool.py:812} WARNING - Retrying (Retry(total=0, connect=None, read=None, redirect=None, status=None)) after connection broken by 'NewConnectionError('<urllib3.connection.HTTPConnection object at 0x7f0b140908b0>: Failed to establish a new connection: [Errno 111] Connection refused')': /wd/hub/session
[2025-05-19T08:34:33.287+0000] {MathDag.py:50} ERROR - Lỗi crawl link https://loigiaihay.com/de-so-40-de-thi-vao-lop-10-mon-toan-c44a49649.html: HTTPConnectionPool(host='localhost', port=4444): Max retries exceeded with url: /wd/hub/session (Caused by NewConnectionError('<urllib3.connection.HTTPConnection object at 0x7f0b14090b80>: Failed to establish a new connection: [Errno 111] Connection refused'))
[2025-05-19T08:34:33.287+0000] {MathDag.py:45} INFO - Đang crawl link 62/64: https://loigiaihay.com/de-so-41-de-thi-vao-lop-10-mon-toan-c44a49650.html
[2025-05-19T08:34:33.289+0000] {connectionpool.py:812} WARNING - Retrying (Retry(total=2, connect=None, read=None, redirect=None, status=None)) after connection broken by 'NewConnectionError('<urllib3.connection.HTTPConnection object at 0x7f0b14090640>: Failed to establish a new connection: [Errno 111] Connection refused')': /wd/hub/session
[2025-05-19T08:34:33.290+0000] {connectionpool.py:812} WARNING - Retrying (Retry(total=1, connect=None, read=None, redirect=None, status=None)) after connection broken by 'NewConnectionError('<urllib3.connection.HTTPConnection object at 0x7f0b140e96a0>: Failed to establish a new connection: [Errno 111] Connection refused')': /wd/hub/session
[2025-05-19T08:34:33.290+0000] {connectionpool.py:812} WARNING - Retrying (Retry(total=0, connect=None, read=None, redirect=None, status=None)) after connection broken by 'NewConnectionError('<urllib3.connection.HTTPConnection object at 0x7f0b140e92e0>: Failed to establish a new connection: [Errno 111] Connection refused')': /wd/hub/session
[2025-05-19T08:34:33.291+0000] {MathDag.py:50} ERROR - Lỗi crawl link https://loigiaihay.com/de-so-41-de-thi-vao-lop-10-mon-toan-c44a49650.html: HTTPConnectionPool(host='localhost', port=4444): Max retries exceeded with url: /wd/hub/session (Caused by NewConnectionError('<urllib3.connection.HTTPConnection object at 0x7f0b140e9a30>: Failed to establish a new connection: [Errno 111] Connection refused'))
[2025-05-19T08:34:33.291+0000] {MathDag.py:45} INFO - Đang crawl link 63/64: https://loigiaihay.com/de-so-42-de-thi-vao-lop-10-mon-toan-c44a49651.html
[2025-05-19T08:34:33.292+0000] {connectionpool.py:812} WARNING - Retrying (Retry(total=2, connect=None, read=None, redirect=None, status=None)) after connection broken by 'NewConnectionError('<urllib3.connection.HTTPConnection object at 0x7f0b140f8b80>: Failed to establish a new connection: [Errno 111] Connection refused')': /wd/hub/session
[2025-05-19T08:34:33.292+0000] {connectionpool.py:812} WARNING - Retrying (Retry(total=1, connect=None, read=None, redirect=None, status=None)) after connection broken by 'NewConnectionError('<urllib3.connection.HTTPConnection object at 0x7f0b140f8190>: Failed to establish a new connection: [Errno 111] Connection refused')': /wd/hub/session
[2025-05-19T08:34:33.293+0000] {connectionpool.py:812} WARNING - Retrying (Retry(total=0, connect=None, read=None, redirect=None, status=None)) after connection broken by 'NewConnectionError('<urllib3.connection.HTTPConnection object at 0x7f0b140f8310>: Failed to establish a new connection: [Errno 111] Connection refused')': /wd/hub/session
[2025-05-19T08:34:33.294+0000] {MathDag.py:50} ERROR - Lỗi crawl link https://loigiaihay.com/de-so-42-de-thi-vao-lop-10-mon-toan-c44a49651.html: HTTPConnectionPool(host='localhost', port=4444): Max retries exceeded with url: /wd/hub/session (Caused by NewConnectionError('<urllib3.connection.HTTPConnection object at 0x7f0b140f8fa0>: Failed to establish a new connection: [Errno 111] Connection refused'))
[2025-05-19T08:34:33.294+0000] {MathDag.py:45} INFO - Đang crawl link 64/64: https://loigiaihay.com/de-so-43-de-thi-vao-lop-10-mon-toan-c44a49652.html
[2025-05-19T08:34:33.295+0000] {connectionpool.py:812} WARNING - Retrying (Retry(total=2, connect=None, read=None, redirect=None, status=None)) after connection broken by 'NewConnectionError('<urllib3.connection.HTTPConnection object at 0x7f0b140907c0>: Failed to establish a new connection: [Errno 111] Connection refused')': /wd/hub/session
[2025-05-19T08:34:33.296+0000] {connectionpool.py:812} WARNING - Retrying (Retry(total=1, connect=None, read=None, redirect=None, status=None)) after connection broken by 'NewConnectionError('<urllib3.connection.HTTPConnection object at 0x7f0b14090760>: Failed to establish a new connection: [Errno 111] Connection refused')': /wd/hub/session
[2025-05-19T08:34:33.296+0000] {connectionpool.py:812} WARNING - Retrying (Retry(total=0, connect=None, read=None, redirect=None, status=None)) after connection broken by 'NewConnectionError('<urllib3.connection.HTTPConnection object at 0x7f0b14090190>: Failed to establish a new connection: [Errno 111] Connection refused')': /wd/hub/session
[2025-05-19T08:34:33.297+0000] {MathDag.py:50} ERROR - Lỗi crawl link https://loigiaihay.com/de-so-43-de-thi-vao-lop-10-mon-toan-c44a49652.html: HTTPConnectionPool(host='localhost', port=4444): Max retries exceeded with url: /wd/hub/session (Caused by NewConnectionError('<urllib3.connection.HTTPConnection object at 0x7f0b140903a0>: Failed to establish a new connection: [Errno 111] Connection refused'))
[2025-05-19T08:34:33.318+0000] {python.py:177} INFO - Done. Returned value was: None
[2025-05-19T08:34:33.325+0000] {taskinstance.py:1322} INFO - Marking task as SUCCESS. dag_id=math_crawler_pipeline, task_id=extract_problem_and_solution, execution_date=20250519T083427, start_date=20250519T083432, end_date=20250519T083433
[2025-05-19T08:34:33.345+0000] {local_task_job.py:159} INFO - Task exited with return code 0
[2025-05-19T08:34:33.365+0000] {taskinstance.py:2582} INFO - 2 downstream tasks scheduled from follow-on schedule check
