[2025-05-19T08:23:40.925+0000] {taskinstance.py:1087} INFO - Dependencies all met for <TaskInstance: math_crawler_pipeline.extract_problem_and_solution manual__2025-05-19T08:23:37.365112+00:00 [queued]>
[2025-05-19T08:23:40.933+0000] {taskinstance.py:1087} INFO - Dependencies all met for <TaskInstance: math_crawler_pipeline.extract_problem_and_solution manual__2025-05-19T08:23:37.365112+00:00 [queued]>
[2025-05-19T08:23:40.933+0000] {taskinstance.py:1283} INFO - 
--------------------------------------------------------------------------------
[2025-05-19T08:23:40.933+0000] {taskinstance.py:1284} INFO - Starting attempt 1 of 3
[2025-05-19T08:23:40.933+0000] {taskinstance.py:1285} INFO - 
--------------------------------------------------------------------------------
[2025-05-19T08:23:40.945+0000] {taskinstance.py:1304} INFO - Executing <Task(PythonOperator): extract_problem_and_solution> on 2025-05-19 08:23:37.365112+00:00
[2025-05-19T08:23:40.951+0000] {standard_task_runner.py:55} INFO - Started process 1665 to run task
[2025-05-19T08:23:40.954+0000] {standard_task_runner.py:82} INFO - Running: ['***', 'tasks', 'run', 'math_crawler_pipeline', 'extract_problem_and_solution', 'manual__2025-05-19T08:23:37.365112+00:00', '--job-id', '28', '--raw', '--subdir', 'DAGS_FOLDER/MathDag.py', '--cfg-path', '/tmp/tmpw_5f3orb']
[2025-05-19T08:23:40.957+0000] {standard_task_runner.py:83} INFO - Job 28: Subtask extract_problem_and_solution
[2025-05-19T08:23:41.019+0000] {task_command.py:389} INFO - Running <TaskInstance: math_crawler_pipeline.extract_problem_and_solution manual__2025-05-19T08:23:37.365112+00:00 [running]> on host 23e48ed0cd15
[2025-05-19T08:23:41.108+0000] {taskinstance.py:1511} INFO - Exporting the following env vars:
AIRFLOW_CTX_DAG_OWNER=***
AIRFLOW_CTX_DAG_ID=math_crawler_pipeline
AIRFLOW_CTX_TASK_ID=extract_problem_and_solution
AIRFLOW_CTX_EXECUTION_DATE=2025-05-19T08:23:37.365112+00:00
AIRFLOW_CTX_TRY_NUMBER=1
AIRFLOW_CTX_DAG_RUN_ID=manual__2025-05-19T08:23:37.365112+00:00
[2025-05-19T08:23:41.125+0000] {MathDag.py:45} INFO - Đang crawl link 1/64: https://loigiaihay.com/de-tham-khao-thi-vao-10-toan-ha-noi-nam-2025-co-dap-an-va-loi-giai-chi-tiet-a179519.html
[2025-05-19T08:23:41.135+0000] {connectionpool.py:812} WARNING - Retrying (Retry(total=2, connect=None, read=None, redirect=None, status=None)) after connection broken by 'NewConnectionError('<urllib3.connection.HTTPConnection object at 0x7f0b14113c70>: Failed to establish a new connection: [Errno 111] Connection refused')': /wd/hub/session
[2025-05-19T08:23:41.136+0000] {connectionpool.py:812} WARNING - Retrying (Retry(total=1, connect=None, read=None, redirect=None, status=None)) after connection broken by 'NewConnectionError('<urllib3.connection.HTTPConnection object at 0x7f0b140c50a0>: Failed to establish a new connection: [Errno 111] Connection refused')': /wd/hub/session
[2025-05-19T08:23:41.138+0000] {connectionpool.py:812} WARNING - Retrying (Retry(total=0, connect=None, read=None, redirect=None, status=None)) after connection broken by 'NewConnectionError('<urllib3.connection.HTTPConnection object at 0x7f0b140c5220>: Failed to establish a new connection: [Errno 111] Connection refused')': /wd/hub/session
[2025-05-19T08:23:41.139+0000] {MathDag.py:50} ERROR - Lỗi crawl link https://loigiaihay.com/de-tham-khao-thi-vao-10-toan-ha-noi-nam-2025-co-dap-an-va-loi-giai-chi-tiet-a179519.html: HTTPConnectionPool(host='localhost', port=4444): Max retries exceeded with url: /wd/hub/session (Caused by NewConnectionError('<urllib3.connection.HTTPConnection object at 0x7f0b140c5370>: Failed to establish a new connection: [Errno 111] Connection refused'))
[2025-05-19T08:23:41.140+0000] {MathDag.py:45} INFO - Đang crawl link 2/64: https://loigiaihay.com/de-tham-khao-thi-vao-10-toan-ha-noi-nam-2025-co-dap-an-va-loi-giai-chi-tiet-de-2-a179539.html
[2025-05-19T08:23:41.142+0000] {connectionpool.py:812} WARNING - Retrying (Retry(total=2, connect=None, read=None, redirect=None, status=None)) after connection broken by 'NewConnectionError('<urllib3.connection.HTTPConnection object at 0x7f0b140c5910>: Failed to establish a new connection: [Errno 111] Connection refused')': /wd/hub/session
[2025-05-19T08:23:41.143+0000] {connectionpool.py:812} WARNING - Retrying (Retry(total=1, connect=None, read=None, redirect=None, status=None)) after connection broken by 'NewConnectionError('<urllib3.connection.HTTPConnection object at 0x7f0b140c5a30>: Failed to establish a new connection: [Errno 111] Connection refused')': /wd/hub/session
[2025-05-19T08:23:41.145+0000] {connectionpool.py:812} WARNING - Retrying (Retry(total=0, connect=None, read=None, redirect=None, status=None)) after connection broken by 'NewConnectionError('<urllib3.connection.HTTPConnection object at 0x7f0b140c5be0>: Failed to establish a new connection: [Errno 111] Connection refused')': /wd/hub/session
[2025-05-19T08:23:41.146+0000] {MathDag.py:50} ERROR - Lỗi crawl link https://loigiaihay.com/de-tham-khao-thi-vao-10-toan-ha-noi-nam-2025-co-dap-an-va-loi-giai-chi-tiet-de-2-a179539.html: HTTPConnectionPool(host='localhost', port=4444): Max retries exceeded with url: /wd/hub/session (Caused by NewConnectionError('<urllib3.connection.HTTPConnection object at 0x7f0b14113fd0>: Failed to establish a new connection: [Errno 111] Connection refused'))
[2025-05-19T08:23:41.149+0000] {MathDag.py:45} INFO - Đang crawl link 3/64: https://loigiaihay.com/de-tham-khao-thi-vao-10-toan-ha-noi-nam-2025-co-dap-an-va-loi-giai-chi-tiet-de-3-a181097.html
[2025-05-19T08:23:41.152+0000] {connectionpool.py:812} WARNING - Retrying (Retry(total=2, connect=None, read=None, redirect=None, status=None)) after connection broken by 'NewConnectionError('<urllib3.connection.HTTPConnection object at 0x7f0b140c5190>: Failed to establish a new connection: [Errno 111] Connection refused')': /wd/hub/session
[2025-05-19T08:23:41.153+0000] {connectionpool.py:812} WARNING - Retrying (Retry(total=1, connect=None, read=None, redirect=None, status=None)) after connection broken by 'NewConnectionError('<urllib3.connection.HTTPConnection object at 0x7f0b140c53d0>: Failed to establish a new connection: [Errno 111] Connection refused')': /wd/hub/session
[2025-05-19T08:23:41.156+0000] {connectionpool.py:812} WARNING - Retrying (Retry(total=0, connect=None, read=None, redirect=None, status=None)) after connection broken by 'NewConnectionError('<urllib3.connection.HTTPConnection object at 0x7f0b140c51c0>: Failed to establish a new connection: [Errno 111] Connection refused')': /wd/hub/session
[2025-05-19T08:23:41.159+0000] {MathDag.py:50} ERROR - Lỗi crawl link https://loigiaihay.com/de-tham-khao-thi-vao-10-toan-ha-noi-nam-2025-co-dap-an-va-loi-giai-chi-tiet-de-3-a181097.html: HTTPConnectionPool(host='localhost', port=4444): Max retries exceeded with url: /wd/hub/session (Caused by NewConnectionError('<urllib3.connection.HTTPConnection object at 0x7f0b140c5d30>: Failed to establish a new connection: [Errno 111] Connection refused'))
[2025-05-19T08:23:41.160+0000] {MathDag.py:45} INFO - Đang crawl link 4/64: https://loigiaihay.com/de-tham-khao-thi-vao-10-mon-toan-ha-noi-nam-2025-de-so-4-a181870.html
[2025-05-19T08:23:41.163+0000] {connectionpool.py:812} WARNING - Retrying (Retry(total=2, connect=None, read=None, redirect=None, status=None)) after connection broken by 'NewConnectionError('<urllib3.connection.HTTPConnection object at 0x7f0b140db310>: Failed to establish a new connection: [Errno 111] Connection refused')': /wd/hub/session
[2025-05-19T08:23:41.164+0000] {connectionpool.py:812} WARNING - Retrying (Retry(total=1, connect=None, read=None, redirect=None, status=None)) after connection broken by 'NewConnectionError('<urllib3.connection.HTTPConnection object at 0x7f0b140db430>: Failed to establish a new connection: [Errno 111] Connection refused')': /wd/hub/session
[2025-05-19T08:23:41.165+0000] {connectionpool.py:812} WARNING - Retrying (Retry(total=0, connect=None, read=None, redirect=None, status=None)) after connection broken by 'NewConnectionError('<urllib3.connection.HTTPConnection object at 0x7f0b140db5e0>: Failed to establish a new connection: [Errno 111] Connection refused')': /wd/hub/session
[2025-05-19T08:23:41.166+0000] {MathDag.py:50} ERROR - Lỗi crawl link https://loigiaihay.com/de-tham-khao-thi-vao-10-mon-toan-ha-noi-nam-2025-de-so-4-a181870.html: HTTPConnectionPool(host='localhost', port=4444): Max retries exceeded with url: /wd/hub/session (Caused by NewConnectionError('<urllib3.connection.HTTPConnection object at 0x7f0b140db730>: Failed to establish a new connection: [Errno 111] Connection refused'))
[2025-05-19T08:23:41.167+0000] {MathDag.py:45} INFO - Đang crawl link 5/64: https://loigiaihay.com/de-tham-khao-thi-vao-10-mon-toan-ha-noi-nam-2025-de-so-5-a182059.html
[2025-05-19T08:23:41.169+0000] {connectionpool.py:812} WARNING - Retrying (Retry(total=2, connect=None, read=None, redirect=None, status=None)) after connection broken by 'NewConnectionError('<urllib3.connection.HTTPConnection object at 0x7f0b140dbcd0>: Failed to establish a new connection: [Errno 111] Connection refused')': /wd/hub/session
[2025-05-19T08:23:41.172+0000] {connectionpool.py:812} WARNING - Retrying (Retry(total=1, connect=None, read=None, redirect=None, status=None)) after connection broken by 'NewConnectionError('<urllib3.connection.HTTPConnection object at 0x7f0b140dbdf0>: Failed to establish a new connection: [Errno 111] Connection refused')': /wd/hub/session
[2025-05-19T08:23:41.174+0000] {connectionpool.py:812} WARNING - Retrying (Retry(total=0, connect=None, read=None, redirect=None, status=None)) after connection broken by 'NewConnectionError('<urllib3.connection.HTTPConnection object at 0x7f0b1417b250>: Failed to establish a new connection: [Errno 111] Connection refused')': /wd/hub/session
[2025-05-19T08:23:41.176+0000] {MathDag.py:50} ERROR - Lỗi crawl link https://loigiaihay.com/de-tham-khao-thi-vao-10-mon-toan-ha-noi-nam-2025-de-so-5-a182059.html: HTTPConnectionPool(host='localhost', port=4444): Max retries exceeded with url: /wd/hub/session (Caused by NewConnectionError('<urllib3.connection.HTTPConnection object at 0x7f0b1417b790>: Failed to establish a new connection: [Errno 111] Connection refused'))
[2025-05-19T08:23:41.178+0000] {MathDag.py:45} INFO - Đang crawl link 6/64: https://loigiaihay.com/de-tham-khao-thi-vao-10-mon-toan-ha-noi-nam-2025-de-so-6-a182290.html
[2025-05-19T08:23:41.182+0000] {connectionpool.py:812} WARNING - Retrying (Retry(total=2, connect=None, read=None, redirect=None, status=None)) after connection broken by 'NewConnectionError('<urllib3.connection.HTTPConnection object at 0x7f0b140c5250>: Failed to establish a new connection: [Errno 111] Connection refused')': /wd/hub/session
[2025-05-19T08:23:41.187+0000] {connectionpool.py:812} WARNING - Retrying (Retry(total=1, connect=None, read=None, redirect=None, status=None)) after connection broken by 'NewConnectionError('<urllib3.connection.HTTPConnection object at 0x7f0b140c5d30>: Failed to establish a new connection: [Errno 111] Connection refused')': /wd/hub/session
[2025-05-19T08:23:41.190+0000] {connectionpool.py:812} WARNING - Retrying (Retry(total=0, connect=None, read=None, redirect=None, status=None)) after connection broken by 'NewConnectionError('<urllib3.connection.HTTPConnection object at 0x7f0b140c53d0>: Failed to establish a new connection: [Errno 111] Connection refused')': /wd/hub/session
[2025-05-19T08:23:41.191+0000] {MathDag.py:50} ERROR - Lỗi crawl link https://loigiaihay.com/de-tham-khao-thi-vao-10-mon-toan-ha-noi-nam-2025-de-so-6-a182290.html: HTTPConnectionPool(host='localhost', port=4444): Max retries exceeded with url: /wd/hub/session (Caused by NewConnectionError('<urllib3.connection.HTTPConnection object at 0x7f0b140c53a0>: Failed to establish a new connection: [Errno 111] Connection refused'))
[2025-05-19T08:23:41.192+0000] {MathDag.py:45} INFO - Đang crawl link 7/64: https://loigiaihay.com/de-tham-khao-thi-vao-10-mon-toan-ha-noi-nam-2025-de-so-7-a182562.html
[2025-05-19T08:23:41.193+0000] {connectionpool.py:812} WARNING - Retrying (Retry(total=2, connect=None, read=None, redirect=None, status=None)) after connection broken by 'NewConnectionError('<urllib3.connection.HTTPConnection object at 0x7f0b140db4c0>: Failed to establish a new connection: [Errno 111] Connection refused')': /wd/hub/session
[2025-05-19T08:23:41.196+0000] {connectionpool.py:812} WARNING - Retrying (Retry(total=1, connect=None, read=None, redirect=None, status=None)) after connection broken by 'NewConnectionError('<urllib3.connection.HTTPConnection object at 0x7f0b140db310>: Failed to establish a new connection: [Errno 111] Connection refused')': /wd/hub/session
[2025-05-19T08:23:41.197+0000] {connectionpool.py:812} WARNING - Retrying (Retry(total=0, connect=None, read=None, redirect=None, status=None)) after connection broken by 'NewConnectionError('<urllib3.connection.HTTPConnection object at 0x7f0b140db220>: Failed to establish a new connection: [Errno 111] Connection refused')': /wd/hub/session
[2025-05-19T08:23:41.200+0000] {MathDag.py:50} ERROR - Lỗi crawl link https://loigiaihay.com/de-tham-khao-thi-vao-10-mon-toan-ha-noi-nam-2025-de-so-7-a182562.html: HTTPConnectionPool(host='localhost', port=4444): Max retries exceeded with url: /wd/hub/session (Caused by NewConnectionError('<urllib3.connection.HTTPConnection object at 0x7f0b140dbf10>: Failed to establish a new connection: [Errno 111] Connection refused'))
[2025-05-19T08:23:41.200+0000] {MathDag.py:45} INFO - Đang crawl link 8/64: https://loigiaihay.com/de-tham-khao-thi-vao-10-mon-toan-ha-noi-nam-2025-de-so-8-a183073.html
[2025-05-19T08:23:41.202+0000] {connectionpool.py:812} WARNING - Retrying (Retry(total=2, connect=None, read=None, redirect=None, status=None)) after connection broken by 'NewConnectionError('<urllib3.connection.HTTPConnection object at 0x7f0b140f04f0>: Failed to establish a new connection: [Errno 111] Connection refused')': /wd/hub/session
[2025-05-19T08:23:41.203+0000] {connectionpool.py:812} WARNING - Retrying (Retry(total=1, connect=None, read=None, redirect=None, status=None)) after connection broken by 'NewConnectionError('<urllib3.connection.HTTPConnection object at 0x7f0b140f0610>: Failed to establish a new connection: [Errno 111] Connection refused')': /wd/hub/session
[2025-05-19T08:23:41.207+0000] {connectionpool.py:812} WARNING - Retrying (Retry(total=0, connect=None, read=None, redirect=None, status=None)) after connection broken by 'NewConnectionError('<urllib3.connection.HTTPConnection object at 0x7f0b140f07c0>: Failed to establish a new connection: [Errno 111] Connection refused')': /wd/hub/session
[2025-05-19T08:23:41.208+0000] {MathDag.py:50} ERROR - Lỗi crawl link https://loigiaihay.com/de-tham-khao-thi-vao-10-mon-toan-ha-noi-nam-2025-de-so-8-a183073.html: HTTPConnectionPool(host='localhost', port=4444): Max retries exceeded with url: /wd/hub/session (Caused by NewConnectionError('<urllib3.connection.HTTPConnection object at 0x7f0b14113c70>: Failed to establish a new connection: [Errno 111] Connection refused'))
[2025-05-19T08:23:41.208+0000] {MathDag.py:45} INFO - Đang crawl link 9/64: https://loigiaihay.com/de-tham-khao-thi-vao-10-mon-toan-ha-noi-nam-2025-de-so-9-a183564.html
[2025-05-19T08:23:41.210+0000] {connectionpool.py:812} WARNING - Retrying (Retry(total=2, connect=None, read=None, redirect=None, status=None)) after connection broken by 'NewConnectionError('<urllib3.connection.HTTPConnection object at 0x7f0b140db0d0>: Failed to establish a new connection: [Errno 111] Connection refused')': /wd/hub/session
[2025-05-19T08:23:41.211+0000] {connectionpool.py:812} WARNING - Retrying (Retry(total=1, connect=None, read=None, redirect=None, status=None)) after connection broken by 'NewConnectionError('<urllib3.connection.HTTPConnection object at 0x7f0b140db2e0>: Failed to establish a new connection: [Errno 111] Connection refused')': /wd/hub/session
[2025-05-19T08:23:41.212+0000] {connectionpool.py:812} WARNING - Retrying (Retry(total=0, connect=None, read=None, redirect=None, status=None)) after connection broken by 'NewConnectionError('<urllib3.connection.HTTPConnection object at 0x7f0b140db640>: Failed to establish a new connection: [Errno 111] Connection refused')': /wd/hub/session
[2025-05-19T08:23:41.215+0000] {MathDag.py:50} ERROR - Lỗi crawl link https://loigiaihay.com/de-tham-khao-thi-vao-10-mon-toan-ha-noi-nam-2025-de-so-9-a183564.html: HTTPConnectionPool(host='localhost', port=4444): Max retries exceeded with url: /wd/hub/session (Caused by NewConnectionError('<urllib3.connection.HTTPConnection object at 0x7f0b140db760>: Failed to establish a new connection: [Errno 111] Connection refused'))
[2025-05-19T08:23:41.215+0000] {MathDag.py:45} INFO - Đang crawl link 10/64: https://loigiaihay.com/de-tham-khao-thi-vao-10-mon-toan-ha-noi-nam-2025-de-so-10-a183809.html
[2025-05-19T08:23:41.218+0000] {connectionpool.py:812} WARNING - Retrying (Retry(total=2, connect=None, read=None, redirect=None, status=None)) after connection broken by 'NewConnectionError('<urllib3.connection.HTTPConnection object at 0x7f0b140dbb20>: Failed to establish a new connection: [Errno 111] Connection refused')': /wd/hub/session
[2025-05-19T08:23:41.219+0000] {connectionpool.py:812} WARNING - Retrying (Retry(total=1, connect=None, read=None, redirect=None, status=None)) after connection broken by 'NewConnectionError('<urllib3.connection.HTTPConnection object at 0x7f0b140db940>: Failed to establish a new connection: [Errno 111] Connection refused')': /wd/hub/session
[2025-05-19T08:23:41.220+0000] {connectionpool.py:812} WARNING - Retrying (Retry(total=0, connect=None, read=None, redirect=None, status=None)) after connection broken by 'NewConnectionError('<urllib3.connection.HTTPConnection object at 0x7f0b1417b790>: Failed to establish a new connection: [Errno 111] Connection refused')': /wd/hub/session
[2025-05-19T08:23:41.222+0000] {MathDag.py:50} ERROR - Lỗi crawl link https://loigiaihay.com/de-tham-khao-thi-vao-10-mon-toan-ha-noi-nam-2025-de-so-10-a183809.html: HTTPConnectionPool(host='localhost', port=4444): Max retries exceeded with url: /wd/hub/session (Caused by NewConnectionError('<urllib3.connection.HTTPConnection object at 0x7f0b1417b940>: Failed to establish a new connection: [Errno 111] Connection refused'))
[2025-05-19T08:23:41.222+0000] {MathDag.py:45} INFO - Đang crawl link 11/64: https://loigiaihay.com/de-tham-khao-thi-vao-10-mon-toan-ha-noi-nam-2025-de-so-11-a184285.html
[2025-05-19T08:23:41.223+0000] {connectionpool.py:812} WARNING - Retrying (Retry(total=2, connect=None, read=None, redirect=None, status=None)) after connection broken by 'NewConnectionError('<urllib3.connection.HTTPConnection object at 0x7f0b140c5250>: Failed to establish a new connection: [Errno 111] Connection refused')': /wd/hub/session
[2025-05-19T08:23:41.223+0000] {connectionpool.py:812} WARNING - Retrying (Retry(total=1, connect=None, read=None, redirect=None, status=None)) after connection broken by 'NewConnectionError('<urllib3.connection.HTTPConnection object at 0x7f0b140c5e80>: Failed to establish a new connection: [Errno 111] Connection refused')': /wd/hub/session
[2025-05-19T08:23:41.224+0000] {connectionpool.py:812} WARNING - Retrying (Retry(total=0, connect=None, read=None, redirect=None, status=None)) after connection broken by 'NewConnectionError('<urllib3.connection.HTTPConnection object at 0x7f0b140c5fa0>: Failed to establish a new connection: [Errno 111] Connection refused')': /wd/hub/session
[2025-05-19T08:23:41.225+0000] {MathDag.py:50} ERROR - Lỗi crawl link https://loigiaihay.com/de-tham-khao-thi-vao-10-mon-toan-ha-noi-nam-2025-de-so-11-a184285.html: HTTPConnectionPool(host='localhost', port=4444): Max retries exceeded with url: /wd/hub/session (Caused by NewConnectionError('<urllib3.connection.HTTPConnection object at 0x7f0b140c5a90>: Failed to establish a new connection: [Errno 111] Connection refused'))
[2025-05-19T08:23:41.226+0000] {MathDag.py:45} INFO - Đang crawl link 12/64: https://loigiaihay.com/de-tham-khao-thi-vao-10-toan-tp-ho-chi-minh-nam-2025-co-dap-an-va-loi-giai-chi-tiet-de-1-a179544.html
[2025-05-19T08:23:41.228+0000] {connectionpool.py:812} WARNING - Retrying (Retry(total=2, connect=None, read=None, redirect=None, status=None)) after connection broken by 'NewConnectionError('<urllib3.connection.HTTPConnection object at 0x7f0b1417b910>: Failed to establish a new connection: [Errno 111] Connection refused')': /wd/hub/session
[2025-05-19T08:23:41.229+0000] {connectionpool.py:812} WARNING - Retrying (Retry(total=1, connect=None, read=None, redirect=None, status=None)) after connection broken by 'NewConnectionError('<urllib3.connection.HTTPConnection object at 0x7f0b140db910>: Failed to establish a new connection: [Errno 111] Connection refused')': /wd/hub/session
[2025-05-19T08:23:41.230+0000] {connectionpool.py:812} WARNING - Retrying (Retry(total=0, connect=None, read=None, redirect=None, status=None)) after connection broken by 'NewConnectionError('<urllib3.connection.HTTPConnection object at 0x7f0b140db940>: Failed to establish a new connection: [Errno 111] Connection refused')': /wd/hub/session
[2025-05-19T08:23:41.230+0000] {MathDag.py:50} ERROR - Lỗi crawl link https://loigiaihay.com/de-tham-khao-thi-vao-10-toan-tp-ho-chi-minh-nam-2025-co-dap-an-va-loi-giai-chi-tiet-de-1-a179544.html: HTTPConnectionPool(host='localhost', port=4444): Max retries exceeded with url: /wd/hub/session (Caused by NewConnectionError('<urllib3.connection.HTTPConnection object at 0x7f0b140dbc40>: Failed to establish a new connection: [Errno 111] Connection refused'))
[2025-05-19T08:23:41.231+0000] {MathDag.py:45} INFO - Đang crawl link 13/64: https://loigiaihay.com/de-tham-khao-thi-vao-10-mon-toan-tp-ho-chi-minh-nam-2025-de-so-2-a181829.html
[2025-05-19T08:23:41.232+0000] {connectionpool.py:812} WARNING - Retrying (Retry(total=2, connect=None, read=None, redirect=None, status=None)) after connection broken by 'NewConnectionError('<urllib3.connection.HTTPConnection object at 0x7f0b140db760>: Failed to establish a new connection: [Errno 111] Connection refused')': /wd/hub/session
[2025-05-19T08:23:41.233+0000] {connectionpool.py:812} WARNING - Retrying (Retry(total=1, connect=None, read=None, redirect=None, status=None)) after connection broken by 'NewConnectionError('<urllib3.connection.HTTPConnection object at 0x7f0b140db610>: Failed to establish a new connection: [Errno 111] Connection refused')': /wd/hub/session
[2025-05-19T08:23:41.234+0000] {connectionpool.py:812} WARNING - Retrying (Retry(total=0, connect=None, read=None, redirect=None, status=None)) after connection broken by 'NewConnectionError('<urllib3.connection.HTTPConnection object at 0x7f0b140db580>: Failed to establish a new connection: [Errno 111] Connection refused')': /wd/hub/session
[2025-05-19T08:23:41.234+0000] {MathDag.py:50} ERROR - Lỗi crawl link https://loigiaihay.com/de-tham-khao-thi-vao-10-mon-toan-tp-ho-chi-minh-nam-2025-de-so-2-a181829.html: HTTPConnectionPool(host='localhost', port=4444): Max retries exceeded with url: /wd/hub/session (Caused by NewConnectionError('<urllib3.connection.HTTPConnection object at 0x7f0b140db1c0>: Failed to establish a new connection: [Errno 111] Connection refused'))
[2025-05-19T08:23:41.234+0000] {MathDag.py:45} INFO - Đang crawl link 14/64: https://loigiaihay.com/de-tham-khao-thi-vao-10-mon-toan-tp-ho-chi-minh-nam-2025-de-so-3-a181884.html
[2025-05-19T08:23:41.236+0000] {connectionpool.py:812} WARNING - Retrying (Retry(total=2, connect=None, read=None, redirect=None, status=None)) after connection broken by 'NewConnectionError('<urllib3.connection.HTTPConnection object at 0x7f0b140c5d90>: Failed to establish a new connection: [Errno 111] Connection refused')': /wd/hub/session
[2025-05-19T08:23:41.236+0000] {connectionpool.py:812} WARNING - Retrying (Retry(total=1, connect=None, read=None, redirect=None, status=None)) after connection broken by 'NewConnectionError('<urllib3.connection.HTTPConnection object at 0x7f0b140c5a00>: Failed to establish a new connection: [Errno 111] Connection refused')': /wd/hub/session
[2025-05-19T08:23:41.237+0000] {connectionpool.py:812} WARNING - Retrying (Retry(total=0, connect=None, read=None, redirect=None, status=None)) after connection broken by 'NewConnectionError('<urllib3.connection.HTTPConnection object at 0x7f0b140c56a0>: Failed to establish a new connection: [Errno 111] Connection refused')': /wd/hub/session
[2025-05-19T08:23:41.237+0000] {MathDag.py:50} ERROR - Lỗi crawl link https://loigiaihay.com/de-tham-khao-thi-vao-10-mon-toan-tp-ho-chi-minh-nam-2025-de-so-3-a181884.html: HTTPConnectionPool(host='localhost', port=4444): Max retries exceeded with url: /wd/hub/session (Caused by NewConnectionError('<urllib3.connection.HTTPConnection object at 0x7f0b140c5250>: Failed to establish a new connection: [Errno 111] Connection refused'))
[2025-05-19T08:23:41.238+0000] {MathDag.py:45} INFO - Đang crawl link 15/64: https://loigiaihay.com/de-tham-khao-thi-vao-10-mon-toan-tp-ho-chi-minh-nam-2025-de-so-4-a181981.html
[2025-05-19T08:23:41.240+0000] {connectionpool.py:812} WARNING - Retrying (Retry(total=2, connect=None, read=None, redirect=None, status=None)) after connection broken by 'NewConnectionError('<urllib3.connection.HTTPConnection object at 0x7f0b140c5520>: Failed to establish a new connection: [Errno 111] Connection refused')': /wd/hub/session
[2025-05-19T08:23:41.241+0000] {connectionpool.py:812} WARNING - Retrying (Retry(total=1, connect=None, read=None, redirect=None, status=None)) after connection broken by 'NewConnectionError('<urllib3.connection.HTTPConnection object at 0x7f0b141a7ee0>: Failed to establish a new connection: [Errno 111] Connection refused')': /wd/hub/session
[2025-05-19T08:23:41.243+0000] {connectionpool.py:812} WARNING - Retrying (Retry(total=0, connect=None, read=None, redirect=None, status=None)) after connection broken by 'NewConnectionError('<urllib3.connection.HTTPConnection object at 0x7f0b14113250>: Failed to establish a new connection: [Errno 111] Connection refused')': /wd/hub/session
[2025-05-19T08:23:41.244+0000] {MathDag.py:50} ERROR - Lỗi crawl link https://loigiaihay.com/de-tham-khao-thi-vao-10-mon-toan-tp-ho-chi-minh-nam-2025-de-so-4-a181981.html: HTTPConnectionPool(host='localhost', port=4444): Max retries exceeded with url: /wd/hub/session (Caused by NewConnectionError('<urllib3.connection.HTTPConnection object at 0x7f0b14113550>: Failed to establish a new connection: [Errno 111] Connection refused'))
[2025-05-19T08:23:41.244+0000] {MathDag.py:45} INFO - Đang crawl link 16/64: https://loigiaihay.com/de-tham-khao-thi-vao-10-mon-toan-tp-ho-chi-minh-nam-2025-de-so-5-a182269.html
[2025-05-19T08:23:41.248+0000] {connectionpool.py:812} WARNING - Retrying (Retry(total=2, connect=None, read=None, redirect=None, status=None)) after connection broken by 'NewConnectionError('<urllib3.connection.HTTPConnection object at 0x7f0b140c5b50>: Failed to establish a new connection: [Errno 111] Connection refused')': /wd/hub/session
[2025-05-19T08:23:41.249+0000] {connectionpool.py:812} WARNING - Retrying (Retry(total=1, connect=None, read=None, redirect=None, status=None)) after connection broken by 'NewConnectionError('<urllib3.connection.HTTPConnection object at 0x7f0b140c50d0>: Failed to establish a new connection: [Errno 111] Connection refused')': /wd/hub/session
[2025-05-19T08:23:41.251+0000] {connectionpool.py:812} WARNING - Retrying (Retry(total=0, connect=None, read=None, redirect=None, status=None)) after connection broken by 'NewConnectionError('<urllib3.connection.HTTPConnection object at 0x7f0b140c5340>: Failed to establish a new connection: [Errno 111] Connection refused')': /wd/hub/session
[2025-05-19T08:23:41.252+0000] {MathDag.py:50} ERROR - Lỗi crawl link https://loigiaihay.com/de-tham-khao-thi-vao-10-mon-toan-tp-ho-chi-minh-nam-2025-de-so-5-a182269.html: HTTPConnectionPool(host='localhost', port=4444): Max retries exceeded with url: /wd/hub/session (Caused by NewConnectionError('<urllib3.connection.HTTPConnection object at 0x7f0b140c5700>: Failed to establish a new connection: [Errno 111] Connection refused'))
[2025-05-19T08:23:41.253+0000] {MathDag.py:45} INFO - Đang crawl link 17/64: https://loigiaihay.com/de-tham-khao-thi-vao-10-mon-toan-tp-ho-chi-minh-nam-2025-de-so-6-a182568.html
[2025-05-19T08:23:41.255+0000] {connectionpool.py:812} WARNING - Retrying (Retry(total=2, connect=None, read=None, redirect=None, status=None)) after connection broken by 'NewConnectionError('<urllib3.connection.HTTPConnection object at 0x7f0b140db610>: Failed to establish a new connection: [Errno 111] Connection refused')': /wd/hub/session
[2025-05-19T08:23:41.259+0000] {connectionpool.py:812} WARNING - Retrying (Retry(total=1, connect=None, read=None, redirect=None, status=None)) after connection broken by 'NewConnectionError('<urllib3.connection.HTTPConnection object at 0x7f0b140db790>: Failed to establish a new connection: [Errno 111] Connection refused')': /wd/hub/session
[2025-05-19T08:23:41.265+0000] {connectionpool.py:812} WARNING - Retrying (Retry(total=0, connect=None, read=None, redirect=None, status=None)) after connection broken by 'NewConnectionError('<urllib3.connection.HTTPConnection object at 0x7f0b140db1f0>: Failed to establish a new connection: [Errno 111] Connection refused')': /wd/hub/session
[2025-05-19T08:23:41.268+0000] {MathDag.py:50} ERROR - Lỗi crawl link https://loigiaihay.com/de-tham-khao-thi-vao-10-mon-toan-tp-ho-chi-minh-nam-2025-de-so-6-a182568.html: HTTPConnectionPool(host='localhost', port=4444): Max retries exceeded with url: /wd/hub/session (Caused by NewConnectionError('<urllib3.connection.HTTPConnection object at 0x7f0b140dbdf0>: Failed to establish a new connection: [Errno 111] Connection refused'))
[2025-05-19T08:23:41.269+0000] {MathDag.py:45} INFO - Đang crawl link 18/64: https://loigiaihay.com/de-tham-khao-thi-vao-10-mon-toan-tp-ho-chi-minh-nam-2025-de-so-7-a182986.html
[2025-05-19T08:23:41.272+0000] {connectionpool.py:812} WARNING - Retrying (Retry(total=2, connect=None, read=None, redirect=None, status=None)) after connection broken by 'NewConnectionError('<urllib3.connection.HTTPConnection object at 0x7f0b1417b940>: Failed to establish a new connection: [Errno 111] Connection refused')': /wd/hub/session
[2025-05-19T08:23:41.275+0000] {connectionpool.py:812} WARNING - Retrying (Retry(total=1, connect=None, read=None, redirect=None, status=None)) after connection broken by 'NewConnectionError('<urllib3.connection.HTTPConnection object at 0x7f0b1417b640>: Failed to establish a new connection: [Errno 111] Connection refused')': /wd/hub/session
[2025-05-19T08:23:41.279+0000] {connectionpool.py:812} WARNING - Retrying (Retry(total=0, connect=None, read=None, redirect=None, status=None)) after connection broken by 'NewConnectionError('<urllib3.connection.HTTPConnection object at 0x7f0b140f0880>: Failed to establish a new connection: [Errno 111] Connection refused')': /wd/hub/session
[2025-05-19T08:23:41.281+0000] {MathDag.py:50} ERROR - Lỗi crawl link https://loigiaihay.com/de-tham-khao-thi-vao-10-mon-toan-tp-ho-chi-minh-nam-2025-de-so-7-a182986.html: HTTPConnectionPool(host='localhost', port=4444): Max retries exceeded with url: /wd/hub/session (Caused by NewConnectionError('<urllib3.connection.HTTPConnection object at 0x7f0b140f0a00>: Failed to establish a new connection: [Errno 111] Connection refused'))
[2025-05-19T08:23:41.283+0000] {MathDag.py:45} INFO - Đang crawl link 19/64: https://loigiaihay.com/de-tham-khao-thi-vao-10-mon-toan-tp-ho-chi-minh-nam-2025-de-so-8-a183544.html
[2025-05-19T08:23:41.286+0000] {connectionpool.py:812} WARNING - Retrying (Retry(total=2, connect=None, read=None, redirect=None, status=None)) after connection broken by 'NewConnectionError('<urllib3.connection.HTTPConnection object at 0x7f0b140c52e0>: Failed to establish a new connection: [Errno 111] Connection refused')': /wd/hub/session
[2025-05-19T08:23:41.286+0000] {connectionpool.py:812} WARNING - Retrying (Retry(total=1, connect=None, read=None, redirect=None, status=None)) after connection broken by 'NewConnectionError('<urllib3.connection.HTTPConnection object at 0x7f0b140c5550>: Failed to establish a new connection: [Errno 111] Connection refused')': /wd/hub/session
[2025-05-19T08:23:41.288+0000] {connectionpool.py:812} WARNING - Retrying (Retry(total=0, connect=None, read=None, redirect=None, status=None)) after connection broken by 'NewConnectionError('<urllib3.connection.HTTPConnection object at 0x7f0b140c5eb0>: Failed to establish a new connection: [Errno 111] Connection refused')': /wd/hub/session
[2025-05-19T08:23:41.294+0000] {MathDag.py:50} ERROR - Lỗi crawl link https://loigiaihay.com/de-tham-khao-thi-vao-10-mon-toan-tp-ho-chi-minh-nam-2025-de-so-8-a183544.html: HTTPConnectionPool(host='localhost', port=4444): Max retries exceeded with url: /wd/hub/session (Caused by NewConnectionError('<urllib3.connection.HTTPConnection object at 0x7f0b1416e820>: Failed to establish a new connection: [Errno 111] Connection refused'))
[2025-05-19T08:23:41.295+0000] {MathDag.py:45} INFO - Đang crawl link 20/64: https://loigiaihay.com/de-tham-khao-thi-vao-10-mon-toan-tp-ho-chi-minh-nam-2025-de-so-9-a184122.html
[2025-05-19T08:23:41.298+0000] {connectionpool.py:812} WARNING - Retrying (Retry(total=2, connect=None, read=None, redirect=None, status=None)) after connection broken by 'NewConnectionError('<urllib3.connection.HTTPConnection object at 0x7f0b140db1f0>: Failed to establish a new connection: [Errno 111] Connection refused')': /wd/hub/session
[2025-05-19T08:23:41.300+0000] {connectionpool.py:812} WARNING - Retrying (Retry(total=1, connect=None, read=None, redirect=None, status=None)) after connection broken by 'NewConnectionError('<urllib3.connection.HTTPConnection object at 0x7f0b140db5b0>: Failed to establish a new connection: [Errno 111] Connection refused')': /wd/hub/session
[2025-05-19T08:23:41.304+0000] {connectionpool.py:812} WARNING - Retrying (Retry(total=0, connect=None, read=None, redirect=None, status=None)) after connection broken by 'NewConnectionError('<urllib3.connection.HTTPConnection object at 0x7f0b140db2e0>: Failed to establish a new connection: [Errno 111] Connection refused')': /wd/hub/session
[2025-05-19T08:23:41.306+0000] {MathDag.py:50} ERROR - Lỗi crawl link https://loigiaihay.com/de-tham-khao-thi-vao-10-mon-toan-tp-ho-chi-minh-nam-2025-de-so-9-a184122.html: HTTPConnectionPool(host='localhost', port=4444): Max retries exceeded with url: /wd/hub/session (Caused by NewConnectionError('<urllib3.connection.HTTPConnection object at 0x7f0b140db220>: Failed to establish a new connection: [Errno 111] Connection refused'))
[2025-05-19T08:23:41.307+0000] {MathDag.py:45} INFO - Đang crawl link 21/64: https://loigiaihay.com/de-tham-khao-thi-vao-10-mon-toan-tp-ho-chi-minh-nam-2025-de-so-10-a184527.html
[2025-05-19T08:23:41.314+0000] {connectionpool.py:812} WARNING - Retrying (Retry(total=2, connect=None, read=None, redirect=None, status=None)) after connection broken by 'NewConnectionError('<urllib3.connection.HTTPConnection object at 0x7f0b140f0dc0>: Failed to establish a new connection: [Errno 111] Connection refused')': /wd/hub/session
[2025-05-19T08:23:41.317+0000] {connectionpool.py:812} WARNING - Retrying (Retry(total=1, connect=None, read=None, redirect=None, status=None)) after connection broken by 'NewConnectionError('<urllib3.connection.HTTPConnection object at 0x7f0b140f0ee0>: Failed to establish a new connection: [Errno 111] Connection refused')': /wd/hub/session
[2025-05-19T08:23:41.320+0000] {connectionpool.py:812} WARNING - Retrying (Retry(total=0, connect=None, read=None, redirect=None, status=None)) after connection broken by 'NewConnectionError('<urllib3.connection.HTTPConnection object at 0x7f0b140fb0d0>: Failed to establish a new connection: [Errno 111] Connection refused')': /wd/hub/session
[2025-05-19T08:23:41.323+0000] {MathDag.py:50} ERROR - Lỗi crawl link https://loigiaihay.com/de-tham-khao-thi-vao-10-mon-toan-tp-ho-chi-minh-nam-2025-de-so-10-a184527.html: HTTPConnectionPool(host='localhost', port=4444): Max retries exceeded with url: /wd/hub/session (Caused by NewConnectionError('<urllib3.connection.HTTPConnection object at 0x7f0b140fb220>: Failed to establish a new connection: [Errno 111] Connection refused'))
[2025-05-19T08:23:41.324+0000] {MathDag.py:45} INFO - Đang crawl link 22/64: https://loigiaihay.com/de-so-1-de-thi-vao-lop-10-mon-toan-c44a49454.html
[2025-05-19T08:23:41.327+0000] {connectionpool.py:812} WARNING - Retrying (Retry(total=2, connect=None, read=None, redirect=None, status=None)) after connection broken by 'NewConnectionError('<urllib3.connection.HTTPConnection object at 0x7f0b140f0fd0>: Failed to establish a new connection: [Errno 111] Connection refused')': /wd/hub/session
[2025-05-19T08:23:41.328+0000] {connectionpool.py:812} WARNING - Retrying (Retry(total=1, connect=None, read=None, redirect=None, status=None)) after connection broken by 'NewConnectionError('<urllib3.connection.HTTPConnection object at 0x7f0b140f0ca0>: Failed to establish a new connection: [Errno 111] Connection refused')': /wd/hub/session
[2025-05-19T08:23:41.329+0000] {connectionpool.py:812} WARNING - Retrying (Retry(total=0, connect=None, read=None, redirect=None, status=None)) after connection broken by 'NewConnectionError('<urllib3.connection.HTTPConnection object at 0x7f0b140f0be0>: Failed to establish a new connection: [Errno 111] Connection refused')': /wd/hub/session
[2025-05-19T08:23:41.330+0000] {MathDag.py:50} ERROR - Lỗi crawl link https://loigiaihay.com/de-so-1-de-thi-vao-lop-10-mon-toan-c44a49454.html: HTTPConnectionPool(host='localhost', port=4444): Max retries exceeded with url: /wd/hub/session (Caused by NewConnectionError('<urllib3.connection.HTTPConnection object at 0x7f0b140db040>: Failed to establish a new connection: [Errno 111] Connection refused'))
[2025-05-19T08:23:41.330+0000] {MathDag.py:45} INFO - Đang crawl link 23/64: https://loigiaihay.com/de-so-2-de-thi-vao-lop-10-mon-toan-c44a49464.html
[2025-05-19T08:23:41.332+0000] {connectionpool.py:812} WARNING - Retrying (Retry(total=2, connect=None, read=None, redirect=None, status=None)) after connection broken by 'NewConnectionError('<urllib3.connection.HTTPConnection object at 0x7f0b140db1f0>: Failed to establish a new connection: [Errno 111] Connection refused')': /wd/hub/session
[2025-05-19T08:23:41.333+0000] {connectionpool.py:812} WARNING - Retrying (Retry(total=1, connect=None, read=None, redirect=None, status=None)) after connection broken by 'NewConnectionError('<urllib3.connection.HTTPConnection object at 0x7f0b140dbdf0>: Failed to establish a new connection: [Errno 111] Connection refused')': /wd/hub/session
[2025-05-19T08:23:41.334+0000] {connectionpool.py:812} WARNING - Retrying (Retry(total=0, connect=None, read=None, redirect=None, status=None)) after connection broken by 'NewConnectionError('<urllib3.connection.HTTPConnection object at 0x7f0b140db0d0>: Failed to establish a new connection: [Errno 111] Connection refused')': /wd/hub/session
[2025-05-19T08:23:41.335+0000] {MathDag.py:50} ERROR - Lỗi crawl link https://loigiaihay.com/de-so-2-de-thi-vao-lop-10-mon-toan-c44a49464.html: HTTPConnectionPool(host='localhost', port=4444): Max retries exceeded with url: /wd/hub/session (Caused by NewConnectionError('<urllib3.connection.HTTPConnection object at 0x7f0b14113f10>: Failed to establish a new connection: [Errno 111] Connection refused'))
[2025-05-19T08:23:41.336+0000] {MathDag.py:45} INFO - Đang crawl link 24/64: https://loigiaihay.com/de-so-3-de-thi-vao-lop-10-mon-toan-c44a49465.html
[2025-05-19T08:23:41.337+0000] {connectionpool.py:812} WARNING - Retrying (Retry(total=2, connect=None, read=None, redirect=None, status=None)) after connection broken by 'NewConnectionError('<urllib3.connection.HTTPConnection object at 0x7f0b140c5f10>: Failed to establish a new connection: [Errno 111] Connection refused')': /wd/hub/session
[2025-05-19T08:23:41.338+0000] {connectionpool.py:812} WARNING - Retrying (Retry(total=1, connect=None, read=None, redirect=None, status=None)) after connection broken by 'NewConnectionError('<urllib3.connection.HTTPConnection object at 0x7f0b140c59a0>: Failed to establish a new connection: [Errno 111] Connection refused')': /wd/hub/session
[2025-05-19T08:23:41.339+0000] {connectionpool.py:812} WARNING - Retrying (Retry(total=0, connect=None, read=None, redirect=None, status=None)) after connection broken by 'NewConnectionError('<urllib3.connection.HTTPConnection object at 0x7f0b140c5850>: Failed to establish a new connection: [Errno 111] Connection refused')': /wd/hub/session
[2025-05-19T08:23:41.340+0000] {MathDag.py:50} ERROR - Lỗi crawl link https://loigiaihay.com/de-so-3-de-thi-vao-lop-10-mon-toan-c44a49465.html: HTTPConnectionPool(host='localhost', port=4444): Max retries exceeded with url: /wd/hub/session (Caused by NewConnectionError('<urllib3.connection.HTTPConnection object at 0x7f0b140c5b80>: Failed to establish a new connection: [Errno 111] Connection refused'))
[2025-05-19T08:23:41.340+0000] {MathDag.py:45} INFO - Đang crawl link 25/64: https://loigiaihay.com/de-so-4-de-thi-vao-lop-10-mon-toan-c44a49466.html
[2025-05-19T08:23:41.342+0000] {connectionpool.py:812} WARNING - Retrying (Retry(total=2, connect=None, read=None, redirect=None, status=None)) after connection broken by 'NewConnectionError('<urllib3.connection.HTTPConnection object at 0x7f0b140fb850>: Failed to establish a new connection: [Errno 111] Connection refused')': /wd/hub/session
[2025-05-19T08:23:41.344+0000] {connectionpool.py:812} WARNING - Retrying (Retry(total=1, connect=None, read=None, redirect=None, status=None)) after connection broken by 'NewConnectionError('<urllib3.connection.HTTPConnection object at 0x7f0b140c5970>: Failed to establish a new connection: [Errno 111] Connection refused')': /wd/hub/session
[2025-05-19T08:23:41.344+0000] {connectionpool.py:812} WARNING - Retrying (Retry(total=0, connect=None, read=None, redirect=None, status=None)) after connection broken by 'NewConnectionError('<urllib3.connection.HTTPConnection object at 0x7f0b140c5820>: Failed to establish a new connection: [Errno 111] Connection refused')': /wd/hub/session
[2025-05-19T08:23:41.345+0000] {MathDag.py:50} ERROR - Lỗi crawl link https://loigiaihay.com/de-so-4-de-thi-vao-lop-10-mon-toan-c44a49466.html: HTTPConnectionPool(host='localhost', port=4444): Max retries exceeded with url: /wd/hub/session (Caused by NewConnectionError('<urllib3.connection.HTTPConnection object at 0x7f0b140c5850>: Failed to establish a new connection: [Errno 111] Connection refused'))
[2025-05-19T08:23:41.346+0000] {MathDag.py:45} INFO - Đang crawl link 26/64: https://loigiaihay.com/de-so-5-de-thi-vao-lop-10-mon-toan-c44a49467.html
[2025-05-19T08:23:41.348+0000] {connectionpool.py:812} WARNING - Retrying (Retry(total=2, connect=None, read=None, redirect=None, status=None)) after connection broken by 'NewConnectionError('<urllib3.connection.HTTPConnection object at 0x7f0b141131f0>: Failed to establish a new connection: [Errno 111] Connection refused')': /wd/hub/session
[2025-05-19T08:23:41.350+0000] {connectionpool.py:812} WARNING - Retrying (Retry(total=1, connect=None, read=None, redirect=None, status=None)) after connection broken by 'NewConnectionError('<urllib3.connection.HTTPConnection object at 0x7f0b14113340>: Failed to establish a new connection: [Errno 111] Connection refused')': /wd/hub/session
[2025-05-19T08:23:41.351+0000] {connectionpool.py:812} WARNING - Retrying (Retry(total=0, connect=None, read=None, redirect=None, status=None)) after connection broken by 'NewConnectionError('<urllib3.connection.HTTPConnection object at 0x7f0b140db5e0>: Failed to establish a new connection: [Errno 111] Connection refused')': /wd/hub/session
[2025-05-19T08:23:41.352+0000] {MathDag.py:50} ERROR - Lỗi crawl link https://loigiaihay.com/de-so-5-de-thi-vao-lop-10-mon-toan-c44a49467.html: HTTPConnectionPool(host='localhost', port=4444): Max retries exceeded with url: /wd/hub/session (Caused by NewConnectionError('<urllib3.connection.HTTPConnection object at 0x7f0b140db760>: Failed to establish a new connection: [Errno 111] Connection refused'))
[2025-05-19T08:23:41.352+0000] {MathDag.py:45} INFO - Đang crawl link 27/64: https://loigiaihay.com/de-so-6-de-thi-vao-lop-10-mon-toan-c44a49468.html
[2025-05-19T08:23:41.353+0000] {connectionpool.py:812} WARNING - Retrying (Retry(total=2, connect=None, read=None, redirect=None, status=None)) after connection broken by 'NewConnectionError('<urllib3.connection.HTTPConnection object at 0x7f0b140db0a0>: Failed to establish a new connection: [Errno 111] Connection refused')': /wd/hub/session
[2025-05-19T08:23:41.354+0000] {connectionpool.py:812} WARNING - Retrying (Retry(total=1, connect=None, read=None, redirect=None, status=None)) after connection broken by 'NewConnectionError('<urllib3.connection.HTTPConnection object at 0x7f0b140db280>: Failed to establish a new connection: [Errno 111] Connection refused')': /wd/hub/session
[2025-05-19T08:23:41.354+0000] {connectionpool.py:812} WARNING - Retrying (Retry(total=0, connect=None, read=None, redirect=None, status=None)) after connection broken by 'NewConnectionError('<urllib3.connection.HTTPConnection object at 0x7f0b140f0fa0>: Failed to establish a new connection: [Errno 111] Connection refused')': /wd/hub/session
[2025-05-19T08:23:41.355+0000] {MathDag.py:50} ERROR - Lỗi crawl link https://loigiaihay.com/de-so-6-de-thi-vao-lop-10-mon-toan-c44a49468.html: HTTPConnectionPool(host='localhost', port=4444): Max retries exceeded with url: /wd/hub/session (Caused by NewConnectionError('<urllib3.connection.HTTPConnection object at 0x7f0b140f0e50>: Failed to establish a new connection: [Errno 111] Connection refused'))
[2025-05-19T08:23:41.355+0000] {MathDag.py:45} INFO - Đang crawl link 28/64: https://loigiaihay.com/de-so-7-de-thi-vao-lop-10-mon-toan-c44a49469.html
[2025-05-19T08:23:41.356+0000] {connectionpool.py:812} WARNING - Retrying (Retry(total=2, connect=None, read=None, redirect=None, status=None)) after connection broken by 'NewConnectionError('<urllib3.connection.HTTPConnection object at 0x7f0b140fb430>: Failed to establish a new connection: [Errno 111] Connection refused')': /wd/hub/session
[2025-05-19T08:23:41.356+0000] {connectionpool.py:812} WARNING - Retrying (Retry(total=1, connect=None, read=None, redirect=None, status=None)) after connection broken by 'NewConnectionError('<urllib3.connection.HTTPConnection object at 0x7f0b140fb550>: Failed to establish a new connection: [Errno 111] Connection refused')': /wd/hub/session
[2025-05-19T08:23:41.357+0000] {connectionpool.py:812} WARNING - Retrying (Retry(total=0, connect=None, read=None, redirect=None, status=None)) after connection broken by 'NewConnectionError('<urllib3.connection.HTTPConnection object at 0x7f0b140fbbb0>: Failed to establish a new connection: [Errno 111] Connection refused')': /wd/hub/session
[2025-05-19T08:23:41.357+0000] {MathDag.py:50} ERROR - Lỗi crawl link https://loigiaihay.com/de-so-7-de-thi-vao-lop-10-mon-toan-c44a49469.html: HTTPConnectionPool(host='localhost', port=4444): Max retries exceeded with url: /wd/hub/session (Caused by NewConnectionError('<urllib3.connection.HTTPConnection object at 0x7f0b140f0df0>: Failed to establish a new connection: [Errno 111] Connection refused'))
[2025-05-19T08:23:41.358+0000] {MathDag.py:45} INFO - Đang crawl link 29/64: https://loigiaihay.com/de-so-8-de-thi-vao-lop-10-mon-toan-c44a49470.html
[2025-05-19T08:23:41.360+0000] {connectionpool.py:812} WARNING - Retrying (Retry(total=2, connect=None, read=None, redirect=None, status=None)) after connection broken by 'NewConnectionError('<urllib3.connection.HTTPConnection object at 0x7f0b140db220>: Failed to establish a new connection: [Errno 111] Connection refused')': /wd/hub/session
[2025-05-19T08:23:41.360+0000] {connectionpool.py:812} WARNING - Retrying (Retry(total=1, connect=None, read=None, redirect=None, status=None)) after connection broken by 'NewConnectionError('<urllib3.connection.HTTPConnection object at 0x7f0b140db3d0>: Failed to establish a new connection: [Errno 111] Connection refused')': /wd/hub/session
[2025-05-19T08:23:41.361+0000] {connectionpool.py:812} WARNING - Retrying (Retry(total=0, connect=None, read=None, redirect=None, status=None)) after connection broken by 'NewConnectionError('<urllib3.connection.HTTPConnection object at 0x7f0b140db4c0>: Failed to establish a new connection: [Errno 111] Connection refused')': /wd/hub/session
[2025-05-19T08:23:41.362+0000] {MathDag.py:50} ERROR - Lỗi crawl link https://loigiaihay.com/de-so-8-de-thi-vao-lop-10-mon-toan-c44a49470.html: HTTPConnectionPool(host='localhost', port=4444): Max retries exceeded with url: /wd/hub/session (Caused by NewConnectionError('<urllib3.connection.HTTPConnection object at 0x7f0b140dbbb0>: Failed to establish a new connection: [Errno 111] Connection refused'))
[2025-05-19T08:23:41.362+0000] {MathDag.py:45} INFO - Đang crawl link 30/64: https://loigiaihay.com/de-so-9-de-thi-vao-lop-10-mon-toan-c44a49471.html
[2025-05-19T08:23:41.363+0000] {connectionpool.py:812} WARNING - Retrying (Retry(total=2, connect=None, read=None, redirect=None, status=None)) after connection broken by 'NewConnectionError('<urllib3.connection.HTTPConnection object at 0x7f0b140c5df0>: Failed to establish a new connection: [Errno 111] Connection refused')': /wd/hub/session
[2025-05-19T08:23:41.363+0000] {connectionpool.py:812} WARNING - Retrying (Retry(total=1, connect=None, read=None, redirect=None, status=None)) after connection broken by 'NewConnectionError('<urllib3.connection.HTTPConnection object at 0x7f0b140c5610>: Failed to establish a new connection: [Errno 111] Connection refused')': /wd/hub/session
[2025-05-19T08:23:41.364+0000] {connectionpool.py:812} WARNING - Retrying (Retry(total=0, connect=None, read=None, redirect=None, status=None)) after connection broken by 'NewConnectionError('<urllib3.connection.HTTPConnection object at 0x7f0b140c5af0>: Failed to establish a new connection: [Errno 111] Connection refused')': /wd/hub/session
[2025-05-19T08:23:41.364+0000] {MathDag.py:50} ERROR - Lỗi crawl link https://loigiaihay.com/de-so-9-de-thi-vao-lop-10-mon-toan-c44a49471.html: HTTPConnectionPool(host='localhost', port=4444): Max retries exceeded with url: /wd/hub/session (Caused by NewConnectionError('<urllib3.connection.HTTPConnection object at 0x7f0b140c5ca0>: Failed to establish a new connection: [Errno 111] Connection refused'))
[2025-05-19T08:23:41.365+0000] {MathDag.py:45} INFO - Đang crawl link 31/64: https://loigiaihay.com/de-so-10-de-thi-vao-lop-10-mon-toan-c44a49472.html
[2025-05-19T08:23:41.366+0000] {connectionpool.py:812} WARNING - Retrying (Retry(total=2, connect=None, read=None, redirect=None, status=None)) after connection broken by 'NewConnectionError('<urllib3.connection.HTTPConnection object at 0x7f0b140fbf70>: Failed to establish a new connection: [Errno 111] Connection refused')': /wd/hub/session
[2025-05-19T08:23:41.367+0000] {connectionpool.py:812} WARNING - Retrying (Retry(total=1, connect=None, read=None, redirect=None, status=None)) after connection broken by 'NewConnectionError('<urllib3.connection.HTTPConnection object at 0x7f0b140890d0>: Failed to establish a new connection: [Errno 111] Connection refused')': /wd/hub/session
[2025-05-19T08:23:41.367+0000] {connectionpool.py:812} WARNING - Retrying (Retry(total=0, connect=None, read=None, redirect=None, status=None)) after connection broken by 'NewConnectionError('<urllib3.connection.HTTPConnection object at 0x7f0b14089280>: Failed to establish a new connection: [Errno 111] Connection refused')': /wd/hub/session
[2025-05-19T08:23:41.368+0000] {MathDag.py:50} ERROR - Lỗi crawl link https://loigiaihay.com/de-so-10-de-thi-vao-lop-10-mon-toan-c44a49472.html: HTTPConnectionPool(host='localhost', port=4444): Max retries exceeded with url: /wd/hub/session (Caused by NewConnectionError('<urllib3.connection.HTTPConnection object at 0x7f0b140893d0>: Failed to establish a new connection: [Errno 111] Connection refused'))
[2025-05-19T08:23:41.369+0000] {MathDag.py:45} INFO - Đang crawl link 32/64: https://loigiaihay.com/de-so-11-de-thi-vao-lop-10-mon-toan-c44a49473.html
[2025-05-19T08:23:41.369+0000] {connectionpool.py:812} WARNING - Retrying (Retry(total=2, connect=None, read=None, redirect=None, status=None)) after connection broken by 'NewConnectionError('<urllib3.connection.HTTPConnection object at 0x7f0b140c5730>: Failed to establish a new connection: [Errno 111] Connection refused')': /wd/hub/session
[2025-05-19T08:23:41.370+0000] {connectionpool.py:812} WARNING - Retrying (Retry(total=1, connect=None, read=None, redirect=None, status=None)) after connection broken by 'NewConnectionError('<urllib3.connection.HTTPConnection object at 0x7f0b14113340>: Failed to establish a new connection: [Errno 111] Connection refused')': /wd/hub/session
[2025-05-19T08:23:41.370+0000] {connectionpool.py:812} WARNING - Retrying (Retry(total=0, connect=None, read=None, redirect=None, status=None)) after connection broken by 'NewConnectionError('<urllib3.connection.HTTPConnection object at 0x7f0b14113f70>: Failed to establish a new connection: [Errno 111] Connection refused')': /wd/hub/session
[2025-05-19T08:23:41.371+0000] {MathDag.py:50} ERROR - Lỗi crawl link https://loigiaihay.com/de-so-11-de-thi-vao-lop-10-mon-toan-c44a49473.html: HTTPConnectionPool(host='localhost', port=4444): Max retries exceeded with url: /wd/hub/session (Caused by NewConnectionError('<urllib3.connection.HTTPConnection object at 0x7f0b140db1c0>: Failed to establish a new connection: [Errno 111] Connection refused'))
[2025-05-19T08:23:41.371+0000] {MathDag.py:45} INFO - Đang crawl link 33/64: https://loigiaihay.com/de-so-12-de-thi-vao-lop-10-mon-toan-c44a49474.html
[2025-05-19T08:23:41.372+0000] {connectionpool.py:812} WARNING - Retrying (Retry(total=2, connect=None, read=None, redirect=None, status=None)) after connection broken by 'NewConnectionError('<urllib3.connection.HTTPConnection object at 0x7f0b140db790>: Failed to establish a new connection: [Errno 111] Connection refused')': /wd/hub/session
[2025-05-19T08:23:41.373+0000] {connectionpool.py:812} WARNING - Retrying (Retry(total=1, connect=None, read=None, redirect=None, status=None)) after connection broken by 'NewConnectionError('<urllib3.connection.HTTPConnection object at 0x7f0b140db040>: Failed to establish a new connection: [Errno 111] Connection refused')': /wd/hub/session
[2025-05-19T08:23:41.373+0000] {connectionpool.py:812} WARNING - Retrying (Retry(total=0, connect=None, read=None, redirect=None, status=None)) after connection broken by 'NewConnectionError('<urllib3.connection.HTTPConnection object at 0x7f0b140f0ee0>: Failed to establish a new connection: [Errno 111] Connection refused')': /wd/hub/session
[2025-05-19T08:23:41.374+0000] {MathDag.py:50} ERROR - Lỗi crawl link https://loigiaihay.com/de-so-12-de-thi-vao-lop-10-mon-toan-c44a49474.html: HTTPConnectionPool(host='localhost', port=4444): Max retries exceeded with url: /wd/hub/session (Caused by NewConnectionError('<urllib3.connection.HTTPConnection object at 0x7f0b140f0e80>: Failed to establish a new connection: [Errno 111] Connection refused'))
[2025-05-19T08:23:41.375+0000] {MathDag.py:45} INFO - Đang crawl link 34/64: https://loigiaihay.com/de-so-13-de-thi-vao-lop-10-mon-toan-c44a49515.html
[2025-05-19T08:23:41.375+0000] {connectionpool.py:812} WARNING - Retrying (Retry(total=2, connect=None, read=None, redirect=None, status=None)) after connection broken by 'NewConnectionError('<urllib3.connection.HTTPConnection object at 0x7f0b140898e0>: Failed to establish a new connection: [Errno 111] Connection refused')': /wd/hub/session
[2025-05-19T08:23:41.376+0000] {connectionpool.py:812} WARNING - Retrying (Retry(total=1, connect=None, read=None, redirect=None, status=None)) after connection broken by 'NewConnectionError('<urllib3.connection.HTTPConnection object at 0x7f0b14089a00>: Failed to establish a new connection: [Errno 111] Connection refused')': /wd/hub/session
[2025-05-19T08:23:41.376+0000] {connectionpool.py:812} WARNING - Retrying (Retry(total=0, connect=None, read=None, redirect=None, status=None)) after connection broken by 'NewConnectionError('<urllib3.connection.HTTPConnection object at 0x7f0b14089bb0>: Failed to establish a new connection: [Errno 111] Connection refused')': /wd/hub/session
[2025-05-19T08:23:41.377+0000] {MathDag.py:50} ERROR - Lỗi crawl link https://loigiaihay.com/de-so-13-de-thi-vao-lop-10-mon-toan-c44a49515.html: HTTPConnectionPool(host='localhost', port=4444): Max retries exceeded with url: /wd/hub/session (Caused by NewConnectionError('<urllib3.connection.HTTPConnection object at 0x7f0b14089d00>: Failed to establish a new connection: [Errno 111] Connection refused'))
[2025-05-19T08:23:41.377+0000] {MathDag.py:45} INFO - Đang crawl link 35/64: https://loigiaihay.com/de-so-14-de-thi-vao-lop-10-mon-toan-c44a49529.html
[2025-05-19T08:23:41.378+0000] {connectionpool.py:812} WARNING - Retrying (Retry(total=2, connect=None, read=None, redirect=None, status=None)) after connection broken by 'NewConnectionError('<urllib3.connection.HTTPConnection object at 0x7f0b140db250>: Failed to establish a new connection: [Errno 111] Connection refused')': /wd/hub/session
[2025-05-19T08:23:41.379+0000] {connectionpool.py:812} WARNING - Retrying (Retry(total=1, connect=None, read=None, redirect=None, status=None)) after connection broken by 'NewConnectionError('<urllib3.connection.HTTPConnection object at 0x7f0b140db5b0>: Failed to establish a new connection: [Errno 111] Connection refused')': /wd/hub/session
[2025-05-19T08:23:41.380+0000] {connectionpool.py:812} WARNING - Retrying (Retry(total=0, connect=None, read=None, redirect=None, status=None)) after connection broken by 'NewConnectionError('<urllib3.connection.HTTPConnection object at 0x7f0b140db3a0>: Failed to establish a new connection: [Errno 111] Connection refused')': /wd/hub/session
[2025-05-19T08:23:41.380+0000] {MathDag.py:50} ERROR - Lỗi crawl link https://loigiaihay.com/de-so-14-de-thi-vao-lop-10-mon-toan-c44a49529.html: HTTPConnectionPool(host='localhost', port=4444): Max retries exceeded with url: /wd/hub/session (Caused by NewConnectionError('<urllib3.connection.HTTPConnection object at 0x7f0b140dba00>: Failed to establish a new connection: [Errno 111] Connection refused'))
[2025-05-19T08:23:41.380+0000] {MathDag.py:45} INFO - Đang crawl link 36/64: https://loigiaihay.com/de-so-15-de-thi-vao-lop-10-mon-toan-c44a49531.html
[2025-05-19T08:23:41.382+0000] {connectionpool.py:812} WARNING - Retrying (Retry(total=2, connect=None, read=None, redirect=None, status=None)) after connection broken by 'NewConnectionError('<urllib3.connection.HTTPConnection object at 0x7f0b140c5b50>: Failed to establish a new connection: [Errno 111] Connection refused')': /wd/hub/session
[2025-05-19T08:23:41.382+0000] {connectionpool.py:812} WARNING - Retrying (Retry(total=1, connect=None, read=None, redirect=None, status=None)) after connection broken by 'NewConnectionError('<urllib3.connection.HTTPConnection object at 0x7f0b140c5df0>: Failed to establish a new connection: [Errno 111] Connection refused')': /wd/hub/session
[2025-05-19T08:23:41.383+0000] {connectionpool.py:812} WARNING - Retrying (Retry(total=0, connect=None, read=None, redirect=None, status=None)) after connection broken by 'NewConnectionError('<urllib3.connection.HTTPConnection object at 0x7f0b140c5a00>: Failed to establish a new connection: [Errno 111] Connection refused')': /wd/hub/session
[2025-05-19T08:23:41.384+0000] {MathDag.py:50} ERROR - Lỗi crawl link https://loigiaihay.com/de-so-15-de-thi-vao-lop-10-mon-toan-c44a49531.html: HTTPConnectionPool(host='localhost', port=4444): Max retries exceeded with url: /wd/hub/session (Caused by NewConnectionError('<urllib3.connection.HTTPConnection object at 0x7f0b14089e50>: Failed to establish a new connection: [Errno 111] Connection refused'))
[2025-05-19T08:23:41.384+0000] {MathDag.py:45} INFO - Đang crawl link 37/64: https://loigiaihay.com/de-so-16-de-thi-vao-lop-10-mon-toan-c44a49533.html
[2025-05-19T08:23:41.386+0000] {connectionpool.py:812} WARNING - Retrying (Retry(total=2, connect=None, read=None, redirect=None, status=None)) after connection broken by 'NewConnectionError('<urllib3.connection.HTTPConnection object at 0x7f0b1409b340>: Failed to establish a new connection: [Errno 111] Connection refused')': /wd/hub/session
[2025-05-19T08:23:41.386+0000] {connectionpool.py:812} WARNING - Retrying (Retry(total=1, connect=None, read=None, redirect=None, status=None)) after connection broken by 'NewConnectionError('<urllib3.connection.HTTPConnection object at 0x7f0b1409b460>: Failed to establish a new connection: [Errno 111] Connection refused')': /wd/hub/session
[2025-05-19T08:23:41.387+0000] {connectionpool.py:812} WARNING - Retrying (Retry(total=0, connect=None, read=None, redirect=None, status=None)) after connection broken by 'NewConnectionError('<urllib3.connection.HTTPConnection object at 0x7f0b1409b610>: Failed to establish a new connection: [Errno 111] Connection refused')': /wd/hub/session
[2025-05-19T08:23:41.388+0000] {MathDag.py:50} ERROR - Lỗi crawl link https://loigiaihay.com/de-so-16-de-thi-vao-lop-10-mon-toan-c44a49533.html: HTTPConnectionPool(host='localhost', port=4444): Max retries exceeded with url: /wd/hub/session (Caused by NewConnectionError('<urllib3.connection.HTTPConnection object at 0x7f0b1409b790>: Failed to establish a new connection: [Errno 111] Connection refused'))
[2025-05-19T08:23:41.388+0000] {MathDag.py:45} INFO - Đang crawl link 38/64: https://loigiaihay.com/de-so-17-de-thi-vao-lop-10-mon-toan-c44a49536.html
[2025-05-19T08:23:41.389+0000] {connectionpool.py:812} WARNING - Retrying (Retry(total=2, connect=None, read=None, redirect=None, status=None)) after connection broken by 'NewConnectionError('<urllib3.connection.HTTPConnection object at 0x7f0b140c5e50>: Failed to establish a new connection: [Errno 111] Connection refused')': /wd/hub/session
[2025-05-19T08:23:41.390+0000] {connectionpool.py:812} WARNING - Retrying (Retry(total=1, connect=None, read=None, redirect=None, status=None)) after connection broken by 'NewConnectionError('<urllib3.connection.HTTPConnection object at 0x7f0b14113340>: Failed to establish a new connection: [Errno 111] Connection refused')': /wd/hub/session
[2025-05-19T08:23:41.391+0000] {connectionpool.py:812} WARNING - Retrying (Retry(total=0, connect=None, read=None, redirect=None, status=None)) after connection broken by 'NewConnectionError('<urllib3.connection.HTTPConnection object at 0x7f0b140db1c0>: Failed to establish a new connection: [Errno 111] Connection refused')': /wd/hub/session
[2025-05-19T08:23:41.391+0000] {MathDag.py:50} ERROR - Lỗi crawl link https://loigiaihay.com/de-so-17-de-thi-vao-lop-10-mon-toan-c44a49536.html: HTTPConnectionPool(host='localhost', port=4444): Max retries exceeded with url: /wd/hub/session (Caused by NewConnectionError('<urllib3.connection.HTTPConnection object at 0x7f0b140db790>: Failed to establish a new connection: [Errno 111] Connection refused'))
[2025-05-19T08:23:41.391+0000] {MathDag.py:45} INFO - Đang crawl link 39/64: https://loigiaihay.com/de-so-18-de-thi-vao-lop-10-mon-toan-c44a49538.html
[2025-05-19T08:23:41.392+0000] {connectionpool.py:812} WARNING - Retrying (Retry(total=2, connect=None, read=None, redirect=None, status=None)) after connection broken by 'NewConnectionError('<urllib3.connection.HTTPConnection object at 0x7f0b140dba90>: Failed to establish a new connection: [Errno 111] Connection refused')': /wd/hub/session
[2025-05-19T08:23:41.393+0000] {connectionpool.py:812} WARNING - Retrying (Retry(total=1, connect=None, read=None, redirect=None, status=None)) after connection broken by 'NewConnectionError('<urllib3.connection.HTTPConnection object at 0x7f0b140f0e50>: Failed to establish a new connection: [Errno 111] Connection refused')': /wd/hub/session
[2025-05-19T08:23:41.393+0000] {connectionpool.py:812} WARNING - Retrying (Retry(total=0, connect=None, read=None, redirect=None, status=None)) after connection broken by 'NewConnectionError('<urllib3.connection.HTTPConnection object at 0x7f0b140f0eb0>: Failed to establish a new connection: [Errno 111] Connection refused')': /wd/hub/session
[2025-05-19T08:23:41.394+0000] {MathDag.py:50} ERROR - Lỗi crawl link https://loigiaihay.com/de-so-18-de-thi-vao-lop-10-mon-toan-c44a49538.html: HTTPConnectionPool(host='localhost', port=4444): Max retries exceeded with url: /wd/hub/session (Caused by NewConnectionError('<urllib3.connection.HTTPConnection object at 0x7f0b14089df0>: Failed to establish a new connection: [Errno 111] Connection refused'))
[2025-05-19T08:23:41.394+0000] {MathDag.py:45} INFO - Đang crawl link 40/64: https://loigiaihay.com/de-so-19-de-thi-vao-lop-10-mon-toan-c44a49540.html
[2025-05-19T08:23:41.395+0000] {connectionpool.py:812} WARNING - Retrying (Retry(total=2, connect=None, read=None, redirect=None, status=None)) after connection broken by 'NewConnectionError('<urllib3.connection.HTTPConnection object at 0x7f0b1409bd90>: Failed to establish a new connection: [Errno 111] Connection refused')': /wd/hub/session
[2025-05-19T08:23:41.396+0000] {connectionpool.py:812} WARNING - Retrying (Retry(total=1, connect=None, read=None, redirect=None, status=None)) after connection broken by 'NewConnectionError('<urllib3.connection.HTTPConnection object at 0x7f0b1409beb0>: Failed to establish a new connection: [Errno 111] Connection refused')': /wd/hub/session
[2025-05-19T08:23:41.397+0000] {connectionpool.py:812} WARNING - Retrying (Retry(total=0, connect=None, read=None, redirect=None, status=None)) after connection broken by 'NewConnectionError('<urllib3.connection.HTTPConnection object at 0x7f0b140af0a0>: Failed to establish a new connection: [Errno 111] Connection refused')': /wd/hub/session
[2025-05-19T08:23:41.398+0000] {MathDag.py:50} ERROR - Lỗi crawl link https://loigiaihay.com/de-so-19-de-thi-vao-lop-10-mon-toan-c44a49540.html: HTTPConnectionPool(host='localhost', port=4444): Max retries exceeded with url: /wd/hub/session (Caused by NewConnectionError('<urllib3.connection.HTTPConnection object at 0x7f0b140af1f0>: Failed to establish a new connection: [Errno 111] Connection refused'))
[2025-05-19T08:23:41.398+0000] {MathDag.py:45} INFO - Đang crawl link 41/64: https://loigiaihay.com/de-so-20-de-thi-vao-lop-10-mon-toan-c44a49541.html
[2025-05-19T08:23:41.399+0000] {connectionpool.py:812} WARNING - Retrying (Retry(total=2, connect=None, read=None, redirect=None, status=None)) after connection broken by 'NewConnectionError('<urllib3.connection.HTTPConnection object at 0x7f0b140dbe20>: Failed to establish a new connection: [Errno 111] Connection refused')': /wd/hub/session
[2025-05-19T08:23:41.399+0000] {connectionpool.py:812} WARNING - Retrying (Retry(total=1, connect=None, read=None, redirect=None, status=None)) after connection broken by 'NewConnectionError('<urllib3.connection.HTTPConnection object at 0x7f0b140dbeb0>: Failed to establish a new connection: [Errno 111] Connection refused')': /wd/hub/session
[2025-05-19T08:23:41.400+0000] {connectionpool.py:812} WARNING - Retrying (Retry(total=0, connect=None, read=None, redirect=None, status=None)) after connection broken by 'NewConnectionError('<urllib3.connection.HTTPConnection object at 0x7f0b140db3a0>: Failed to establish a new connection: [Errno 111] Connection refused')': /wd/hub/session
[2025-05-19T08:23:41.400+0000] {MathDag.py:50} ERROR - Lỗi crawl link https://loigiaihay.com/de-so-20-de-thi-vao-lop-10-mon-toan-c44a49541.html: HTTPConnectionPool(host='localhost', port=4444): Max retries exceeded with url: /wd/hub/session (Caused by NewConnectionError('<urllib3.connection.HTTPConnection object at 0x7f0b140dbca0>: Failed to establish a new connection: [Errno 111] Connection refused'))
[2025-05-19T08:23:41.401+0000] {MathDag.py:45} INFO - Đang crawl link 42/64: https://loigiaihay.com/de-so-21-de-thi-vao-lop-10-mon-toan-c44a49573.html
[2025-05-19T08:23:41.402+0000] {connectionpool.py:812} WARNING - Retrying (Retry(total=2, connect=None, read=None, redirect=None, status=None)) after connection broken by 'NewConnectionError('<urllib3.connection.HTTPConnection object at 0x7f0b140c57f0>: Failed to establish a new connection: [Errno 111] Connection refused')': /wd/hub/session
[2025-05-19T08:23:41.402+0000] {connectionpool.py:812} WARNING - Retrying (Retry(total=1, connect=None, read=None, redirect=None, status=None)) after connection broken by 'NewConnectionError('<urllib3.connection.HTTPConnection object at 0x7f0b140c5370>: Failed to establish a new connection: [Errno 111] Connection refused')': /wd/hub/session
[2025-05-19T08:23:41.403+0000] {connectionpool.py:812} WARNING - Retrying (Retry(total=0, connect=None, read=None, redirect=None, status=None)) after connection broken by 'NewConnectionError('<urllib3.connection.HTTPConnection object at 0x7f0b140c5e80>: Failed to establish a new connection: [Errno 111] Connection refused')': /wd/hub/session
[2025-05-19T08:23:41.403+0000] {MathDag.py:50} ERROR - Lỗi crawl link https://loigiaihay.com/de-so-21-de-thi-vao-lop-10-mon-toan-c44a49573.html: HTTPConnectionPool(host='localhost', port=4444): Max retries exceeded with url: /wd/hub/session (Caused by NewConnectionError('<urllib3.connection.HTTPConnection object at 0x7f0b1409b850>: Failed to establish a new connection: [Errno 111] Connection refused'))
[2025-05-19T08:23:41.403+0000] {MathDag.py:45} INFO - Đang crawl link 43/64: https://loigiaihay.com/de-so-22-de-thi-vao-lop-10-mon-toan-c44a49582.html
[2025-05-19T08:23:41.405+0000] {connectionpool.py:812} WARNING - Retrying (Retry(total=2, connect=None, read=None, redirect=None, status=None)) after connection broken by 'NewConnectionError('<urllib3.connection.HTTPConnection object at 0x7f0b140af7f0>: Failed to establish a new connection: [Errno 111] Connection refused')': /wd/hub/session
[2025-05-19T08:23:41.405+0000] {connectionpool.py:812} WARNING - Retrying (Retry(total=1, connect=None, read=None, redirect=None, status=None)) after connection broken by 'NewConnectionError('<urllib3.connection.HTTPConnection object at 0x7f0b140af910>: Failed to establish a new connection: [Errno 111] Connection refused')': /wd/hub/session
[2025-05-19T08:23:41.406+0000] {connectionpool.py:812} WARNING - Retrying (Retry(total=0, connect=None, read=None, redirect=None, status=None)) after connection broken by 'NewConnectionError('<urllib3.connection.HTTPConnection object at 0x7f0b140afac0>: Failed to establish a new connection: [Errno 111] Connection refused')': /wd/hub/session
[2025-05-19T08:23:41.406+0000] {MathDag.py:50} ERROR - Lỗi crawl link https://loigiaihay.com/de-so-22-de-thi-vao-lop-10-mon-toan-c44a49582.html: HTTPConnectionPool(host='localhost', port=4444): Max retries exceeded with url: /wd/hub/session (Caused by NewConnectionError('<urllib3.connection.HTTPConnection object at 0x7f0b140afc10>: Failed to establish a new connection: [Errno 111] Connection refused'))
[2025-05-19T08:23:41.407+0000] {MathDag.py:45} INFO - Đang crawl link 44/64: https://loigiaihay.com/de-so-23-de-thi-vao-lop-10-mon-toan-c44a49583.html
[2025-05-19T08:23:41.408+0000] {connectionpool.py:812} WARNING - Retrying (Retry(total=2, connect=None, read=None, redirect=None, status=None)) after connection broken by 'NewConnectionError('<urllib3.connection.HTTPConnection object at 0x7f0b140c5e50>: Failed to establish a new connection: [Errno 111] Connection refused')': /wd/hub/session
[2025-05-19T08:23:41.409+0000] {connectionpool.py:812} WARNING - Retrying (Retry(total=1, connect=None, read=None, redirect=None, status=None)) after connection broken by 'NewConnectionError('<urllib3.connection.HTTPConnection object at 0x7f0b14113430>: Failed to establish a new connection: [Errno 111] Connection refused')': /wd/hub/session
[2025-05-19T08:23:41.409+0000] {connectionpool.py:812} WARNING - Retrying (Retry(total=0, connect=None, read=None, redirect=None, status=None)) after connection broken by 'NewConnectionError('<urllib3.connection.HTTPConnection object at 0x7f0b140db580>: Failed to establish a new connection: [Errno 111] Connection refused')': /wd/hub/session
[2025-05-19T08:23:41.410+0000] {MathDag.py:50} ERROR - Lỗi crawl link https://loigiaihay.com/de-so-23-de-thi-vao-lop-10-mon-toan-c44a49583.html: HTTPConnectionPool(host='localhost', port=4444): Max retries exceeded with url: /wd/hub/session (Caused by NewConnectionError('<urllib3.connection.HTTPConnection object at 0x7f0b140db220>: Failed to establish a new connection: [Errno 111] Connection refused'))
[2025-05-19T08:23:41.410+0000] {MathDag.py:45} INFO - Đang crawl link 45/64: https://loigiaihay.com/de-so-24-de-thi-vao-lop-10-mon-toan-c44a49585.html
[2025-05-19T08:23:41.411+0000] {connectionpool.py:812} WARNING - Retrying (Retry(total=2, connect=None, read=None, redirect=None, status=None)) after connection broken by 'NewConnectionError('<urllib3.connection.HTTPConnection object at 0x7f0b140dbe80>: Failed to establish a new connection: [Errno 111] Connection refused')': /wd/hub/session
[2025-05-19T08:23:41.412+0000] {connectionpool.py:812} WARNING - Retrying (Retry(total=1, connect=None, read=None, redirect=None, status=None)) after connection broken by 'NewConnectionError('<urllib3.connection.HTTPConnection object at 0x7f0b140f0c70>: Failed to establish a new connection: [Errno 111] Connection refused')': /wd/hub/session
[2025-05-19T08:23:41.412+0000] {connectionpool.py:812} WARNING - Retrying (Retry(total=0, connect=None, read=None, redirect=None, status=None)) after connection broken by 'NewConnectionError('<urllib3.connection.HTTPConnection object at 0x7f0b140f0bb0>: Failed to establish a new connection: [Errno 111] Connection refused')': /wd/hub/session
[2025-05-19T08:23:41.413+0000] {MathDag.py:50} ERROR - Lỗi crawl link https://loigiaihay.com/de-so-24-de-thi-vao-lop-10-mon-toan-c44a49585.html: HTTPConnectionPool(host='localhost', port=4444): Max retries exceeded with url: /wd/hub/session (Caused by NewConnectionError('<urllib3.connection.HTTPConnection object at 0x7f0b140afd00>: Failed to establish a new connection: [Errno 111] Connection refused'))
[2025-05-19T08:23:41.413+0000] {MathDag.py:45} INFO - Đang crawl link 46/64: https://loigiaihay.com/de-so-25-de-thi-vao-lop-10-mon-toan-c44a49613.html
[2025-05-19T08:23:41.414+0000] {connectionpool.py:812} WARNING - Retrying (Retry(total=2, connect=None, read=None, redirect=None, status=None)) after connection broken by 'NewConnectionError('<urllib3.connection.HTTPConnection object at 0x7f0b14043250>: Failed to establish a new connection: [Errno 111] Connection refused')': /wd/hub/session
[2025-05-19T08:23:41.414+0000] {connectionpool.py:812} WARNING - Retrying (Retry(total=1, connect=None, read=None, redirect=None, status=None)) after connection broken by 'NewConnectionError('<urllib3.connection.HTTPConnection object at 0x7f0b14043370>: Failed to establish a new connection: [Errno 111] Connection refused')': /wd/hub/session
[2025-05-19T08:23:41.415+0000] {connectionpool.py:812} WARNING - Retrying (Retry(total=0, connect=None, read=None, redirect=None, status=None)) after connection broken by 'NewConnectionError('<urllib3.connection.HTTPConnection object at 0x7f0b14043520>: Failed to establish a new connection: [Errno 111] Connection refused')': /wd/hub/session
[2025-05-19T08:23:41.416+0000] {MathDag.py:50} ERROR - Lỗi crawl link https://loigiaihay.com/de-so-25-de-thi-vao-lop-10-mon-toan-c44a49613.html: HTTPConnectionPool(host='localhost', port=4444): Max retries exceeded with url: /wd/hub/session (Caused by NewConnectionError('<urllib3.connection.HTTPConnection object at 0x7f0b14043670>: Failed to establish a new connection: [Errno 111] Connection refused'))
[2025-05-19T08:23:41.417+0000] {MathDag.py:45} INFO - Đang crawl link 47/64: https://loigiaihay.com/de-so-26-de-thi-vao-lop-10-mon-toan-c44a49614.html
[2025-05-19T08:23:41.418+0000] {connectionpool.py:812} WARNING - Retrying (Retry(total=2, connect=None, read=None, redirect=None, status=None)) after connection broken by 'NewConnectionError('<urllib3.connection.HTTPConnection object at 0x7f0b1409bca0>: Failed to establish a new connection: [Errno 111] Connection refused')': /wd/hub/session
[2025-05-19T08:23:41.418+0000] {connectionpool.py:812} WARNING - Retrying (Retry(total=1, connect=None, read=None, redirect=None, status=None)) after connection broken by 'NewConnectionError('<urllib3.connection.HTTPConnection object at 0x7f0b1409baf0>: Failed to establish a new connection: [Errno 111] Connection refused')': /wd/hub/session
[2025-05-19T08:23:41.419+0000] {connectionpool.py:812} WARNING - Retrying (Retry(total=0, connect=None, read=None, redirect=None, status=None)) after connection broken by 'NewConnectionError('<urllib3.connection.HTTPConnection object at 0x7f0b1409b040>: Failed to establish a new connection: [Errno 111] Connection refused')': /wd/hub/session
[2025-05-19T08:23:41.419+0000] {MathDag.py:50} ERROR - Lỗi crawl link https://loigiaihay.com/de-so-26-de-thi-vao-lop-10-mon-toan-c44a49614.html: HTTPConnectionPool(host='localhost', port=4444): Max retries exceeded with url: /wd/hub/session (Caused by NewConnectionError('<urllib3.connection.HTTPConnection object at 0x7f0b1409b4f0>: Failed to establish a new connection: [Errno 111] Connection refused'))
[2025-05-19T08:23:41.420+0000] {MathDag.py:45} INFO - Đang crawl link 48/64: https://loigiaihay.com/de-so-27-de-thi-vao-lop-10-mon-toan-c44a49615.html
[2025-05-19T08:23:41.421+0000] {connectionpool.py:812} WARNING - Retrying (Retry(total=2, connect=None, read=None, redirect=None, status=None)) after connection broken by 'NewConnectionError('<urllib3.connection.HTTPConnection object at 0x7f0b1409b130>: Failed to establish a new connection: [Errno 111] Connection refused')': /wd/hub/session
[2025-05-19T08:23:41.422+0000] {connectionpool.py:812} WARNING - Retrying (Retry(total=1, connect=None, read=None, redirect=None, status=None)) after connection broken by 'NewConnectionError('<urllib3.connection.HTTPConnection object at 0x7f0b14113fd0>: Failed to establish a new connection: [Errno 111] Connection refused')': /wd/hub/session
[2025-05-19T08:23:41.422+0000] {connectionpool.py:812} WARNING - Retrying (Retry(total=0, connect=None, read=None, redirect=None, status=None)) after connection broken by 'NewConnectionError('<urllib3.connection.HTTPConnection object at 0x7f0b14089fd0>: Failed to establish a new connection: [Errno 111] Connection refused')': /wd/hub/session
[2025-05-19T08:23:41.423+0000] {MathDag.py:50} ERROR - Lỗi crawl link https://loigiaihay.com/de-so-27-de-thi-vao-lop-10-mon-toan-c44a49615.html: HTTPConnectionPool(host='localhost', port=4444): Max retries exceeded with url: /wd/hub/session (Caused by NewConnectionError('<urllib3.connection.HTTPConnection object at 0x7f0b14089fa0>: Failed to establish a new connection: [Errno 111] Connection refused'))
[2025-05-19T08:23:41.423+0000] {MathDag.py:45} INFO - Đang crawl link 49/64: https://loigiaihay.com/de-so-28-de-thi-vao-lop-10-mon-toan-c44a49616.html
[2025-05-19T08:23:41.424+0000] {connectionpool.py:812} WARNING - Retrying (Retry(total=2, connect=None, read=None, redirect=None, status=None)) after connection broken by 'NewConnectionError('<urllib3.connection.HTTPConnection object at 0x7f0b140899d0>: Failed to establish a new connection: [Errno 111] Connection refused')': /wd/hub/session
[2025-05-19T08:23:41.425+0000] {connectionpool.py:812} WARNING - Retrying (Retry(total=1, connect=None, read=None, redirect=None, status=None)) after connection broken by 'NewConnectionError('<urllib3.connection.HTTPConnection object at 0x7f0b14089490>: Failed to establish a new connection: [Errno 111] Connection refused')': /wd/hub/session
[2025-05-19T08:23:41.426+0000] {connectionpool.py:812} WARNING - Retrying (Retry(total=0, connect=None, read=None, redirect=None, status=None)) after connection broken by 'NewConnectionError('<urllib3.connection.HTTPConnection object at 0x7f0b14089d60>: Failed to establish a new connection: [Errno 111] Connection refused')': /wd/hub/session
[2025-05-19T08:23:41.426+0000] {MathDag.py:50} ERROR - Lỗi crawl link https://loigiaihay.com/de-so-28-de-thi-vao-lop-10-mon-toan-c44a49616.html: HTTPConnectionPool(host='localhost', port=4444): Max retries exceeded with url: /wd/hub/session (Caused by NewConnectionError('<urllib3.connection.HTTPConnection object at 0x7f0b140897f0>: Failed to establish a new connection: [Errno 111] Connection refused'))
[2025-05-19T08:23:41.426+0000] {MathDag.py:45} INFO - Đang crawl link 50/64: https://loigiaihay.com/de-so-29-de-thi-vao-lop-10-mon-toan-c44a49621.html
[2025-05-19T08:23:41.428+0000] {connectionpool.py:812} WARNING - Retrying (Retry(total=2, connect=None, read=None, redirect=None, status=None)) after connection broken by 'NewConnectionError('<urllib3.connection.HTTPConnection object at 0x7f0b140fbd90>: Failed to establish a new connection: [Errno 111] Connection refused')': /wd/hub/session
[2025-05-19T08:23:41.428+0000] {connectionpool.py:812} WARNING - Retrying (Retry(total=1, connect=None, read=None, redirect=None, status=None)) after connection broken by 'NewConnectionError('<urllib3.connection.HTTPConnection object at 0x7f0b14089730>: Failed to establish a new connection: [Errno 111] Connection refused')': /wd/hub/session
[2025-05-19T08:23:41.429+0000] {connectionpool.py:812} WARNING - Retrying (Retry(total=0, connect=None, read=None, redirect=None, status=None)) after connection broken by 'NewConnectionError('<urllib3.connection.HTTPConnection object at 0x7f0b14089850>: Failed to establish a new connection: [Errno 111] Connection refused')': /wd/hub/session
[2025-05-19T08:23:41.429+0000] {MathDag.py:50} ERROR - Lỗi crawl link https://loigiaihay.com/de-so-29-de-thi-vao-lop-10-mon-toan-c44a49621.html: HTTPConnectionPool(host='localhost', port=4444): Max retries exceeded with url: /wd/hub/session (Caused by NewConnectionError('<urllib3.connection.HTTPConnection object at 0x7f0b14089880>: Failed to establish a new connection: [Errno 111] Connection refused'))
[2025-05-19T08:23:41.429+0000] {MathDag.py:45} INFO - Đang crawl link 51/64: https://loigiaihay.com/de-so-30-de-thi-vao-lop-10-mon-toan-c44a49629.html
[2025-05-19T08:23:41.430+0000] {connectionpool.py:812} WARNING - Retrying (Retry(total=2, connect=None, read=None, redirect=None, status=None)) after connection broken by 'NewConnectionError('<urllib3.connection.HTTPConnection object at 0x7f0b14089610>: Failed to establish a new connection: [Errno 111] Connection refused')': /wd/hub/session
[2025-05-19T08:23:41.431+0000] {connectionpool.py:812} WARNING - Retrying (Retry(total=1, connect=None, read=None, redirect=None, status=None)) after connection broken by 'NewConnectionError('<urllib3.connection.HTTPConnection object at 0x7f0b14089fa0>: Failed to establish a new connection: [Errno 111] Connection refused')': /wd/hub/session
[2025-05-19T08:23:41.432+0000] {connectionpool.py:812} WARNING - Retrying (Retry(total=0, connect=None, read=None, redirect=None, status=None)) after connection broken by 'NewConnectionError('<urllib3.connection.HTTPConnection object at 0x7f0b14113ca0>: Failed to establish a new connection: [Errno 111] Connection refused')': /wd/hub/session
[2025-05-19T08:23:41.433+0000] {MathDag.py:50} ERROR - Lỗi crawl link https://loigiaihay.com/de-so-30-de-thi-vao-lop-10-mon-toan-c44a49629.html: HTTPConnectionPool(host='localhost', port=4444): Max retries exceeded with url: /wd/hub/session (Caused by NewConnectionError('<urllib3.connection.HTTPConnection object at 0x7f0b14113250>: Failed to establish a new connection: [Errno 111] Connection refused'))
[2025-05-19T08:23:41.433+0000] {MathDag.py:45} INFO - Đang crawl link 52/64: https://loigiaihay.com/de-so-31-de-thi-vao-lop-10-mon-toan-c44a49640.html
[2025-05-19T08:23:41.434+0000] {connectionpool.py:812} WARNING - Retrying (Retry(total=2, connect=None, read=None, redirect=None, status=None)) after connection broken by 'NewConnectionError('<urllib3.connection.HTTPConnection object at 0x7f0b1409b7c0>: Failed to establish a new connection: [Errno 111] Connection refused')': /wd/hub/session
[2025-05-19T08:23:41.435+0000] {connectionpool.py:812} WARNING - Retrying (Retry(total=1, connect=None, read=None, redirect=None, status=None)) after connection broken by 'NewConnectionError('<urllib3.connection.HTTPConnection object at 0x7f0b1409bf70>: Failed to establish a new connection: [Errno 111] Connection refused')': /wd/hub/session
[2025-05-19T08:23:41.435+0000] {connectionpool.py:812} WARNING - Retrying (Retry(total=0, connect=None, read=None, redirect=None, status=None)) after connection broken by 'NewConnectionError('<urllib3.connection.HTTPConnection object at 0x7f0b1409b520>: Failed to establish a new connection: [Errno 111] Connection refused')': /wd/hub/session
[2025-05-19T08:23:41.436+0000] {MathDag.py:50} ERROR - Lỗi crawl link https://loigiaihay.com/de-so-31-de-thi-vao-lop-10-mon-toan-c44a49640.html: HTTPConnectionPool(host='localhost', port=4444): Max retries exceeded with url: /wd/hub/session (Caused by NewConnectionError('<urllib3.connection.HTTPConnection object at 0x7f0b1409b3a0>: Failed to establish a new connection: [Errno 111] Connection refused'))
[2025-05-19T08:23:41.436+0000] {MathDag.py:45} INFO - Đang crawl link 53/64: https://loigiaihay.com/de-so-32-de-thi-vao-lop-10-mon-toan-c44a49639.html
[2025-05-19T08:23:41.438+0000] {connectionpool.py:812} WARNING - Retrying (Retry(total=2, connect=None, read=None, redirect=None, status=None)) after connection broken by 'NewConnectionError('<urllib3.connection.HTTPConnection object at 0x7f0b140fbf40>: Failed to establish a new connection: [Errno 111] Connection refused')': /wd/hub/session
[2025-05-19T08:23:41.439+0000] {connectionpool.py:812} WARNING - Retrying (Retry(total=1, connect=None, read=None, redirect=None, status=None)) after connection broken by 'NewConnectionError('<urllib3.connection.HTTPConnection object at 0x7f0b140fbe80>: Failed to establish a new connection: [Errno 111] Connection refused')': /wd/hub/session
[2025-05-19T08:23:41.439+0000] {connectionpool.py:812} WARNING - Retrying (Retry(total=0, connect=None, read=None, redirect=None, status=None)) after connection broken by 'NewConnectionError('<urllib3.connection.HTTPConnection object at 0x7f0b140fbbe0>: Failed to establish a new connection: [Errno 111] Connection refused')': /wd/hub/session
[2025-05-19T08:23:41.441+0000] {MathDag.py:50} ERROR - Lỗi crawl link https://loigiaihay.com/de-so-32-de-thi-vao-lop-10-mon-toan-c44a49639.html: HTTPConnectionPool(host='localhost', port=4444): Max retries exceeded with url: /wd/hub/session (Caused by NewConnectionError('<urllib3.connection.HTTPConnection object at 0x7f0b1409b2b0>: Failed to establish a new connection: [Errno 111] Connection refused'))
[2025-05-19T08:23:41.441+0000] {MathDag.py:45} INFO - Đang crawl link 54/64: https://loigiaihay.com/de-so-33-de-thi-vao-lop-10-mon-toan-c44a49641.html
[2025-05-19T08:23:41.442+0000] {connectionpool.py:812} WARNING - Retrying (Retry(total=2, connect=None, read=None, redirect=None, status=None)) after connection broken by 'NewConnectionError('<urllib3.connection.HTTPConnection object at 0x7f0b1409b7f0>: Failed to establish a new connection: [Errno 111] Connection refused')': /wd/hub/session
[2025-05-19T08:23:41.443+0000] {connectionpool.py:812} WARNING - Retrying (Retry(total=1, connect=None, read=None, redirect=None, status=None)) after connection broken by 'NewConnectionError('<urllib3.connection.HTTPConnection object at 0x7f0b1409b1f0>: Failed to establish a new connection: [Errno 111] Connection refused')': /wd/hub/session
[2025-05-19T08:23:41.444+0000] {connectionpool.py:812} WARNING - Retrying (Retry(total=0, connect=None, read=None, redirect=None, status=None)) after connection broken by 'NewConnectionError('<urllib3.connection.HTTPConnection object at 0x7f0b1409b160>: Failed to establish a new connection: [Errno 111] Connection refused')': /wd/hub/session
[2025-05-19T08:23:41.445+0000] {MathDag.py:50} ERROR - Lỗi crawl link https://loigiaihay.com/de-so-33-de-thi-vao-lop-10-mon-toan-c44a49641.html: HTTPConnectionPool(host='localhost', port=4444): Max retries exceeded with url: /wd/hub/session (Caused by NewConnectionError('<urllib3.connection.HTTPConnection object at 0x7f0b14113fd0>: Failed to establish a new connection: [Errno 111] Connection refused'))
[2025-05-19T08:23:41.445+0000] {MathDag.py:45} INFO - Đang crawl link 55/64: https://loigiaihay.com/de-so-34-de-thi-vao-lop-10-mon-toan-c44a49643.html
[2025-05-19T08:23:41.446+0000] {connectionpool.py:812} WARNING - Retrying (Retry(total=2, connect=None, read=None, redirect=None, status=None)) after connection broken by 'NewConnectionError('<urllib3.connection.HTTPConnection object at 0x7f0b14089910>: Failed to establish a new connection: [Errno 111] Connection refused')': /wd/hub/session
[2025-05-19T08:23:41.447+0000] {connectionpool.py:812} WARNING - Retrying (Retry(total=1, connect=None, read=None, redirect=None, status=None)) after connection broken by 'NewConnectionError('<urllib3.connection.HTTPConnection object at 0x7f0b14089c10>: Failed to establish a new connection: [Errno 111] Connection refused')': /wd/hub/session
[2025-05-19T08:23:41.447+0000] {connectionpool.py:812} WARNING - Retrying (Retry(total=0, connect=None, read=None, redirect=None, status=None)) after connection broken by 'NewConnectionError('<urllib3.connection.HTTPConnection object at 0x7f0b14089550>: Failed to establish a new connection: [Errno 111] Connection refused')': /wd/hub/session
[2025-05-19T08:23:41.448+0000] {MathDag.py:50} ERROR - Lỗi crawl link https://loigiaihay.com/de-so-34-de-thi-vao-lop-10-mon-toan-c44a49643.html: HTTPConnectionPool(host='localhost', port=4444): Max retries exceeded with url: /wd/hub/session (Caused by NewConnectionError('<urllib3.connection.HTTPConnection object at 0x7f0b14089070>: Failed to establish a new connection: [Errno 111] Connection refused'))
[2025-05-19T08:23:41.448+0000] {MathDag.py:45} INFO - Đang crawl link 56/64: https://loigiaihay.com/de-so-35-de-thi-vao-lop-10-mon-toan-c44a49644.html
[2025-05-19T08:23:41.449+0000] {connectionpool.py:812} WARNING - Retrying (Retry(total=2, connect=None, read=None, redirect=None, status=None)) after connection broken by 'NewConnectionError('<urllib3.connection.HTTPConnection object at 0x7f0b140fbac0>: Failed to establish a new connection: [Errno 111] Connection refused')': /wd/hub/session
[2025-05-19T08:23:41.449+0000] {connectionpool.py:812} WARNING - Retrying (Retry(total=1, connect=None, read=None, redirect=None, status=None)) after connection broken by 'NewConnectionError('<urllib3.connection.HTTPConnection object at 0x7f0b140fb070>: Failed to establish a new connection: [Errno 111] Connection refused')': /wd/hub/session
[2025-05-19T08:23:41.450+0000] {connectionpool.py:812} WARNING - Retrying (Retry(total=0, connect=None, read=None, redirect=None, status=None)) after connection broken by 'NewConnectionError('<urllib3.connection.HTTPConnection object at 0x7f0b140fb9a0>: Failed to establish a new connection: [Errno 111] Connection refused')': /wd/hub/session
[2025-05-19T08:23:41.450+0000] {MathDag.py:50} ERROR - Lỗi crawl link https://loigiaihay.com/de-so-35-de-thi-vao-lop-10-mon-toan-c44a49644.html: HTTPConnectionPool(host='localhost', port=4444): Max retries exceeded with url: /wd/hub/session (Caused by NewConnectionError('<urllib3.connection.HTTPConnection object at 0x7f0b140fb760>: Failed to establish a new connection: [Errno 111] Connection refused'))
[2025-05-19T08:23:41.451+0000] {MathDag.py:45} INFO - Đang crawl link 57/64: https://loigiaihay.com/de-so-36-de-thi-vao-lop-10-mon-toan-c44a49645.html
[2025-05-19T08:23:41.452+0000] {connectionpool.py:812} WARNING - Retrying (Retry(total=2, connect=None, read=None, redirect=None, status=None)) after connection broken by 'NewConnectionError('<urllib3.connection.HTTPConnection object at 0x7f0b140fb700>: Failed to establish a new connection: [Errno 111] Connection refused')': /wd/hub/session
[2025-05-19T08:23:41.453+0000] {connectionpool.py:812} WARNING - Retrying (Retry(total=1, connect=None, read=None, redirect=None, status=None)) after connection broken by 'NewConnectionError('<urllib3.connection.HTTPConnection object at 0x7f0b140fb7f0>: Failed to establish a new connection: [Errno 111] Connection refused')': /wd/hub/session
[2025-05-19T08:23:41.453+0000] {connectionpool.py:812} WARNING - Retrying (Retry(total=0, connect=None, read=None, redirect=None, status=None)) after connection broken by 'NewConnectionError('<urllib3.connection.HTTPConnection object at 0x7f0b140fbac0>: Failed to establish a new connection: [Errno 111] Connection refused')': /wd/hub/session
[2025-05-19T08:23:41.454+0000] {MathDag.py:50} ERROR - Lỗi crawl link https://loigiaihay.com/de-so-36-de-thi-vao-lop-10-mon-toan-c44a49645.html: HTTPConnectionPool(host='localhost', port=4444): Max retries exceeded with url: /wd/hub/session (Caused by NewConnectionError('<urllib3.connection.HTTPConnection object at 0x7f0b140fb3d0>: Failed to establish a new connection: [Errno 111] Connection refused'))
[2025-05-19T08:23:41.454+0000] {MathDag.py:45} INFO - Đang crawl link 58/64: https://loigiaihay.com/de-so-37-de-thi-vao-lop-10-mon-toan-c44a49646.html
[2025-05-19T08:23:41.455+0000] {connectionpool.py:812} WARNING - Retrying (Retry(total=2, connect=None, read=None, redirect=None, status=None)) after connection broken by 'NewConnectionError('<urllib3.connection.HTTPConnection object at 0x7f0b14089820>: Failed to establish a new connection: [Errno 111] Connection refused')': /wd/hub/session
[2025-05-19T08:23:41.455+0000] {connectionpool.py:812} WARNING - Retrying (Retry(total=1, connect=None, read=None, redirect=None, status=None)) after connection broken by 'NewConnectionError('<urllib3.connection.HTTPConnection object at 0x7f0b14089550>: Failed to establish a new connection: [Errno 111] Connection refused')': /wd/hub/session
[2025-05-19T08:23:41.456+0000] {connectionpool.py:812} WARNING - Retrying (Retry(total=0, connect=None, read=None, redirect=None, status=None)) after connection broken by 'NewConnectionError('<urllib3.connection.HTTPConnection object at 0x7f0b14089670>: Failed to establish a new connection: [Errno 111] Connection refused')': /wd/hub/session
[2025-05-19T08:23:41.456+0000] {MathDag.py:50} ERROR - Lỗi crawl link https://loigiaihay.com/de-so-37-de-thi-vao-lop-10-mon-toan-c44a49646.html: HTTPConnectionPool(host='localhost', port=4444): Max retries exceeded with url: /wd/hub/session (Caused by NewConnectionError('<urllib3.connection.HTTPConnection object at 0x7f0b14089ee0>: Failed to establish a new connection: [Errno 111] Connection refused'))
[2025-05-19T08:23:41.456+0000] {MathDag.py:45} INFO - Đang crawl link 59/64: https://loigiaihay.com/de-so-38-de-thi-vao-lop-10-mon-toan-c44a49647.html
[2025-05-19T08:23:41.457+0000] {connectionpool.py:812} WARNING - Retrying (Retry(total=2, connect=None, read=None, redirect=None, status=None)) after connection broken by 'NewConnectionError('<urllib3.connection.HTTPConnection object at 0x7f0b1409b4f0>: Failed to establish a new connection: [Errno 111] Connection refused')': /wd/hub/session
[2025-05-19T08:23:41.458+0000] {connectionpool.py:812} WARNING - Retrying (Retry(total=1, connect=None, read=None, redirect=None, status=None)) after connection broken by 'NewConnectionError('<urllib3.connection.HTTPConnection object at 0x7f0b1409b190>: Failed to establish a new connection: [Errno 111] Connection refused')': /wd/hub/session
[2025-05-19T08:23:41.459+0000] {connectionpool.py:812} WARNING - Retrying (Retry(total=0, connect=None, read=None, redirect=None, status=None)) after connection broken by 'NewConnectionError('<urllib3.connection.HTTPConnection object at 0x7f0b1409b100>: Failed to establish a new connection: [Errno 111] Connection refused')': /wd/hub/session
[2025-05-19T08:23:41.459+0000] {MathDag.py:50} ERROR - Lỗi crawl link https://loigiaihay.com/de-so-38-de-thi-vao-lop-10-mon-toan-c44a49647.html: HTTPConnectionPool(host='localhost', port=4444): Max retries exceeded with url: /wd/hub/session (Caused by NewConnectionError('<urllib3.connection.HTTPConnection object at 0x7f0b1409b5e0>: Failed to establish a new connection: [Errno 111] Connection refused'))
[2025-05-19T08:23:41.459+0000] {MathDag.py:45} INFO - Đang crawl link 60/64: https://loigiaihay.com/de-so-39-de-thi-vao-lop-10-mon-toan-c44a49648.html
[2025-05-19T08:23:41.461+0000] {connectionpool.py:812} WARNING - Retrying (Retry(total=2, connect=None, read=None, redirect=None, status=None)) after connection broken by 'NewConnectionError('<urllib3.connection.HTTPConnection object at 0x7f0b140db370>: Failed to establish a new connection: [Errno 111] Connection refused')': /wd/hub/session
[2025-05-19T08:23:41.461+0000] {connectionpool.py:812} WARNING - Retrying (Retry(total=1, connect=None, read=None, redirect=None, status=None)) after connection broken by 'NewConnectionError('<urllib3.connection.HTTPConnection object at 0x7f0b140db6a0>: Failed to establish a new connection: [Errno 111] Connection refused')': /wd/hub/session
[2025-05-19T08:23:41.462+0000] {connectionpool.py:812} WARNING - Retrying (Retry(total=0, connect=None, read=None, redirect=None, status=None)) after connection broken by 'NewConnectionError('<urllib3.connection.HTTPConnection object at 0x7f0b1409b820>: Failed to establish a new connection: [Errno 111] Connection refused')': /wd/hub/session
[2025-05-19T08:23:41.462+0000] {MathDag.py:50} ERROR - Lỗi crawl link https://loigiaihay.com/de-so-39-de-thi-vao-lop-10-mon-toan-c44a49648.html: HTTPConnectionPool(host='localhost', port=4444): Max retries exceeded with url: /wd/hub/session (Caused by NewConnectionError('<urllib3.connection.HTTPConnection object at 0x7f0b1409b610>: Failed to establish a new connection: [Errno 111] Connection refused'))
[2025-05-19T08:23:41.463+0000] {MathDag.py:45} INFO - Đang crawl link 61/64: https://loigiaihay.com/de-so-40-de-thi-vao-lop-10-mon-toan-c44a49649.html
[2025-05-19T08:23:41.464+0000] {connectionpool.py:812} WARNING - Retrying (Retry(total=2, connect=None, read=None, redirect=None, status=None)) after connection broken by 'NewConnectionError('<urllib3.connection.HTTPConnection object at 0x7f0b14113430>: Failed to establish a new connection: [Errno 111] Connection refused')': /wd/hub/session
[2025-05-19T08:23:41.465+0000] {connectionpool.py:812} WARNING - Retrying (Retry(total=1, connect=None, read=None, redirect=None, status=None)) after connection broken by 'NewConnectionError('<urllib3.connection.HTTPConnection object at 0x7f0b14089b80>: Failed to establish a new connection: [Errno 111] Connection refused')': /wd/hub/session
[2025-05-19T08:23:41.465+0000] {connectionpool.py:812} WARNING - Retrying (Retry(total=0, connect=None, read=None, redirect=None, status=None)) after connection broken by 'NewConnectionError('<urllib3.connection.HTTPConnection object at 0x7f0b14089850>: Failed to establish a new connection: [Errno 111] Connection refused')': /wd/hub/session
[2025-05-19T08:23:41.466+0000] {MathDag.py:50} ERROR - Lỗi crawl link https://loigiaihay.com/de-so-40-de-thi-vao-lop-10-mon-toan-c44a49649.html: HTTPConnectionPool(host='localhost', port=4444): Max retries exceeded with url: /wd/hub/session (Caused by NewConnectionError('<urllib3.connection.HTTPConnection object at 0x7f0b14089700>: Failed to establish a new connection: [Errno 111] Connection refused'))
[2025-05-19T08:23:41.466+0000] {MathDag.py:45} INFO - Đang crawl link 62/64: https://loigiaihay.com/de-so-41-de-thi-vao-lop-10-mon-toan-c44a49650.html
[2025-05-19T08:23:41.467+0000] {connectionpool.py:812} WARNING - Retrying (Retry(total=2, connect=None, read=None, redirect=None, status=None)) after connection broken by 'NewConnectionError('<urllib3.connection.HTTPConnection object at 0x7f0b14089bb0>: Failed to establish a new connection: [Errno 111] Connection refused')': /wd/hub/session
[2025-05-19T08:23:41.468+0000] {connectionpool.py:812} WARNING - Retrying (Retry(total=1, connect=None, read=None, redirect=None, status=None)) after connection broken by 'NewConnectionError('<urllib3.connection.HTTPConnection object at 0x7f0b1417b7c0>: Failed to establish a new connection: [Errno 111] Connection refused')': /wd/hub/session
[2025-05-19T08:23:41.468+0000] {connectionpool.py:812} WARNING - Retrying (Retry(total=0, connect=None, read=None, redirect=None, status=None)) after connection broken by 'NewConnectionError('<urllib3.connection.HTTPConnection object at 0x7f0b140fbb50>: Failed to establish a new connection: [Errno 111] Connection refused')': /wd/hub/session
[2025-05-19T08:23:41.469+0000] {MathDag.py:50} ERROR - Lỗi crawl link https://loigiaihay.com/de-so-41-de-thi-vao-lop-10-mon-toan-c44a49650.html: HTTPConnectionPool(host='localhost', port=4444): Max retries exceeded with url: /wd/hub/session (Caused by NewConnectionError('<urllib3.connection.HTTPConnection object at 0x7f0b140fb1f0>: Failed to establish a new connection: [Errno 111] Connection refused'))
[2025-05-19T08:23:41.469+0000] {MathDag.py:45} INFO - Đang crawl link 63/64: https://loigiaihay.com/de-so-42-de-thi-vao-lop-10-mon-toan-c44a49651.html
[2025-05-19T08:23:41.470+0000] {connectionpool.py:812} WARNING - Retrying (Retry(total=2, connect=None, read=None, redirect=None, status=None)) after connection broken by 'NewConnectionError('<urllib3.connection.HTTPConnection object at 0x7f0b140fb970>: Failed to establish a new connection: [Errno 111] Connection refused')': /wd/hub/session
[2025-05-19T08:23:41.471+0000] {connectionpool.py:812} WARNING - Retrying (Retry(total=1, connect=None, read=None, redirect=None, status=None)) after connection broken by 'NewConnectionError('<urllib3.connection.HTTPConnection object at 0x7f0b140fb0d0>: Failed to establish a new connection: [Errno 111] Connection refused')': /wd/hub/session
[2025-05-19T08:23:41.472+0000] {connectionpool.py:812} WARNING - Retrying (Retry(total=0, connect=None, read=None, redirect=None, status=None)) after connection broken by 'NewConnectionError('<urllib3.connection.HTTPConnection object at 0x7f0b140db2b0>: Failed to establish a new connection: [Errno 111] Connection refused')': /wd/hub/session
[2025-05-19T08:23:41.473+0000] {MathDag.py:50} ERROR - Lỗi crawl link https://loigiaihay.com/de-so-42-de-thi-vao-lop-10-mon-toan-c44a49651.html: HTTPConnectionPool(host='localhost', port=4444): Max retries exceeded with url: /wd/hub/session (Caused by NewConnectionError('<urllib3.connection.HTTPConnection object at 0x7f0b140db1f0>: Failed to establish a new connection: [Errno 111] Connection refused'))
[2025-05-19T08:23:41.473+0000] {MathDag.py:45} INFO - Đang crawl link 64/64: https://loigiaihay.com/de-so-43-de-thi-vao-lop-10-mon-toan-c44a49652.html
[2025-05-19T08:23:41.474+0000] {connectionpool.py:812} WARNING - Retrying (Retry(total=2, connect=None, read=None, redirect=None, status=None)) after connection broken by 'NewConnectionError('<urllib3.connection.HTTPConnection object at 0x7f0b14089bb0>: Failed to establish a new connection: [Errno 111] Connection refused')': /wd/hub/session
[2025-05-19T08:23:41.475+0000] {connectionpool.py:812} WARNING - Retrying (Retry(total=1, connect=None, read=None, redirect=None, status=None)) after connection broken by 'NewConnectionError('<urllib3.connection.HTTPConnection object at 0x7f0b14089a30>: Failed to establish a new connection: [Errno 111] Connection refused')': /wd/hub/session
[2025-05-19T08:23:41.475+0000] {connectionpool.py:812} WARNING - Retrying (Retry(total=0, connect=None, read=None, redirect=None, status=None)) after connection broken by 'NewConnectionError('<urllib3.connection.HTTPConnection object at 0x7f0b14089820>: Failed to establish a new connection: [Errno 111] Connection refused')': /wd/hub/session
[2025-05-19T08:23:41.476+0000] {MathDag.py:50} ERROR - Lỗi crawl link https://loigiaihay.com/de-so-43-de-thi-vao-lop-10-mon-toan-c44a49652.html: HTTPConnectionPool(host='localhost', port=4444): Max retries exceeded with url: /wd/hub/session (Caused by NewConnectionError('<urllib3.connection.HTTPConnection object at 0x7f0b14089e80>: Failed to establish a new connection: [Errno 111] Connection refused'))
[2025-05-19T08:23:41.487+0000] {python.py:177} INFO - Done. Returned value was: None
[2025-05-19T08:23:41.496+0000] {taskinstance.py:1322} INFO - Marking task as SUCCESS. dag_id=math_crawler_pipeline, task_id=extract_problem_and_solution, execution_date=20250519T082337, start_date=20250519T082340, end_date=20250519T082341
[2025-05-19T08:23:41.542+0000] {local_task_job.py:159} INFO - Task exited with return code 0
[2025-05-19T08:23:41.567+0000] {taskinstance.py:2582} INFO - 2 downstream tasks scheduled from follow-on schedule check
