[2025-05-19T08:37:32.057+0000] {taskinstance.py:1087} INFO - Dependencies all met for <TaskInstance: math_crawler_pipeline.extract_problem_and_solution manual__2025-05-19T08:37:28.424982+00:00 [queued]>
[2025-05-19T08:37:32.064+0000] {taskinstance.py:1087} INFO - Dependencies all met for <TaskInstance: math_crawler_pipeline.extract_problem_and_solution manual__2025-05-19T08:37:28.424982+00:00 [queued]>
[2025-05-19T08:37:32.064+0000] {taskinstance.py:1283} INFO - 
--------------------------------------------------------------------------------
[2025-05-19T08:37:32.065+0000] {taskinstance.py:1284} INFO - Starting attempt 1 of 3
[2025-05-19T08:37:32.065+0000] {taskinstance.py:1285} INFO - 
--------------------------------------------------------------------------------
[2025-05-19T08:37:32.074+0000] {taskinstance.py:1304} INFO - Executing <Task(PythonOperator): extract_problem_and_solution> on 2025-05-19 08:37:28.424982+00:00
[2025-05-19T08:37:32.079+0000] {standard_task_runner.py:55} INFO - Started process 2026 to run task
[2025-05-19T08:37:32.082+0000] {standard_task_runner.py:82} INFO - Running: ['***', 'tasks', 'run', 'math_crawler_pipeline', 'extract_problem_and_solution', 'manual__2025-05-19T08:37:28.424982+00:00', '--job-id', '36', '--raw', '--subdir', 'DAGS_FOLDER/MathDag.py', '--cfg-path', '/tmp/tmpzday5r46']
[2025-05-19T08:37:32.085+0000] {standard_task_runner.py:83} INFO - Job 36: Subtask extract_problem_and_solution
[2025-05-19T08:37:32.147+0000] {task_command.py:389} INFO - Running <TaskInstance: math_crawler_pipeline.extract_problem_and_solution manual__2025-05-19T08:37:28.424982+00:00 [running]> on host 23e48ed0cd15
[2025-05-19T08:37:32.235+0000] {taskinstance.py:1511} INFO - Exporting the following env vars:
AIRFLOW_CTX_DAG_OWNER=***
AIRFLOW_CTX_DAG_ID=math_crawler_pipeline
AIRFLOW_CTX_TASK_ID=extract_problem_and_solution
AIRFLOW_CTX_EXECUTION_DATE=2025-05-19T08:37:28.424982+00:00
AIRFLOW_CTX_TRY_NUMBER=1
AIRFLOW_CTX_DAG_RUN_ID=manual__2025-05-19T08:37:28.424982+00:00
[2025-05-19T08:37:32.246+0000] {MathDag.py:45} INFO - Đang crawl link 1/64: https://loigiaihay.com/de-tham-khao-thi-vao-10-toan-ha-noi-nam-2025-co-dap-an-va-loi-giai-chi-tiet-a179519.html
[2025-05-19T08:37:32.251+0000] {connectionpool.py:812} WARNING - Retrying (Retry(total=2, connect=None, read=None, redirect=None, status=None)) after connection broken by 'NewConnectionError('<urllib3.connection.HTTPConnection object at 0x7f0b1412e3d0>: Failed to establish a new connection: [Errno 111] Connection refused')': /wd/hub/session
[2025-05-19T08:37:32.252+0000] {connectionpool.py:812} WARNING - Retrying (Retry(total=1, connect=None, read=None, redirect=None, status=None)) after connection broken by 'NewConnectionError('<urllib3.connection.HTTPConnection object at 0x7f0b1412eb80>: Failed to establish a new connection: [Errno 111] Connection refused')': /wd/hub/session
[2025-05-19T08:37:32.253+0000] {connectionpool.py:812} WARNING - Retrying (Retry(total=0, connect=None, read=None, redirect=None, status=None)) after connection broken by 'NewConnectionError('<urllib3.connection.HTTPConnection object at 0x7f0b1412ed00>: Failed to establish a new connection: [Errno 111] Connection refused')': /wd/hub/session
[2025-05-19T08:37:32.253+0000] {MathDag.py:50} ERROR - Lỗi crawl link https://loigiaihay.com/de-tham-khao-thi-vao-10-toan-ha-noi-nam-2025-co-dap-an-va-loi-giai-chi-tiet-a179519.html: HTTPConnectionPool(host='localhost', port=4444): Max retries exceeded with url: /wd/hub/session (Caused by NewConnectionError('<urllib3.connection.HTTPConnection object at 0x7f0b1412ee50>: Failed to establish a new connection: [Errno 111] Connection refused'))
[2025-05-19T08:37:32.254+0000] {MathDag.py:45} INFO - Đang crawl link 2/64: https://loigiaihay.com/de-tham-khao-thi-vao-10-toan-ha-noi-nam-2025-co-dap-an-va-loi-giai-chi-tiet-de-2-a179539.html
[2025-05-19T08:37:32.255+0000] {connectionpool.py:812} WARNING - Retrying (Retry(total=2, connect=None, read=None, redirect=None, status=None)) after connection broken by 'NewConnectionError('<urllib3.connection.HTTPConnection object at 0x7f0b140d0430>: Failed to establish a new connection: [Errno 111] Connection refused')': /wd/hub/session
[2025-05-19T08:37:32.256+0000] {connectionpool.py:812} WARNING - Retrying (Retry(total=1, connect=None, read=None, redirect=None, status=None)) after connection broken by 'NewConnectionError('<urllib3.connection.HTTPConnection object at 0x7f0b1412ec10>: Failed to establish a new connection: [Errno 111] Connection refused')': /wd/hub/session
[2025-05-19T08:37:32.257+0000] {connectionpool.py:812} WARNING - Retrying (Retry(total=0, connect=None, read=None, redirect=None, status=None)) after connection broken by 'NewConnectionError('<urllib3.connection.HTTPConnection object at 0x7f0b1412ee20>: Failed to establish a new connection: [Errno 111] Connection refused')': /wd/hub/session
[2025-05-19T08:37:32.257+0000] {MathDag.py:50} ERROR - Lỗi crawl link https://loigiaihay.com/de-tham-khao-thi-vao-10-toan-ha-noi-nam-2025-co-dap-an-va-loi-giai-chi-tiet-de-2-a179539.html: HTTPConnectionPool(host='localhost', port=4444): Max retries exceeded with url: /wd/hub/session (Caused by NewConnectionError('<urllib3.connection.HTTPConnection object at 0x7f0b1412edf0>: Failed to establish a new connection: [Errno 111] Connection refused'))
[2025-05-19T08:37:32.258+0000] {MathDag.py:45} INFO - Đang crawl link 3/64: https://loigiaihay.com/de-tham-khao-thi-vao-10-toan-ha-noi-nam-2025-co-dap-an-va-loi-giai-chi-tiet-de-3-a181097.html
[2025-05-19T08:37:32.259+0000] {connectionpool.py:812} WARNING - Retrying (Retry(total=2, connect=None, read=None, redirect=None, status=None)) after connection broken by 'NewConnectionError('<urllib3.connection.HTTPConnection object at 0x7f0b14107610>: Failed to establish a new connection: [Errno 111] Connection refused')': /wd/hub/session
[2025-05-19T08:37:32.259+0000] {connectionpool.py:812} WARNING - Retrying (Retry(total=1, connect=None, read=None, redirect=None, status=None)) after connection broken by 'NewConnectionError('<urllib3.connection.HTTPConnection object at 0x7f0b140d05b0>: Failed to establish a new connection: [Errno 111] Connection refused')': /wd/hub/session
[2025-05-19T08:37:32.260+0000] {connectionpool.py:812} WARNING - Retrying (Retry(total=0, connect=None, read=None, redirect=None, status=None)) after connection broken by 'NewConnectionError('<urllib3.connection.HTTPConnection object at 0x7f0b140d0700>: Failed to establish a new connection: [Errno 111] Connection refused')': /wd/hub/session
[2025-05-19T08:37:32.261+0000] {MathDag.py:50} ERROR - Lỗi crawl link https://loigiaihay.com/de-tham-khao-thi-vao-10-toan-ha-noi-nam-2025-co-dap-an-va-loi-giai-chi-tiet-de-3-a181097.html: HTTPConnectionPool(host='localhost', port=4444): Max retries exceeded with url: /wd/hub/session (Caused by NewConnectionError('<urllib3.connection.HTTPConnection object at 0x7f0b140d0850>: Failed to establish a new connection: [Errno 111] Connection refused'))
[2025-05-19T08:37:32.261+0000] {MathDag.py:45} INFO - Đang crawl link 4/64: https://loigiaihay.com/de-tham-khao-thi-vao-10-mon-toan-ha-noi-nam-2025-de-so-4-a181870.html
[2025-05-19T08:37:32.262+0000] {connectionpool.py:812} WARNING - Retrying (Retry(total=2, connect=None, read=None, redirect=None, status=None)) after connection broken by 'NewConnectionError('<urllib3.connection.HTTPConnection object at 0x7f0b140d0df0>: Failed to establish a new connection: [Errno 111] Connection refused')': /wd/hub/session
[2025-05-19T08:37:32.262+0000] {connectionpool.py:812} WARNING - Retrying (Retry(total=1, connect=None, read=None, redirect=None, status=None)) after connection broken by 'NewConnectionError('<urllib3.connection.HTTPConnection object at 0x7f0b140d0f10>: Failed to establish a new connection: [Errno 111] Connection refused')': /wd/hub/session
[2025-05-19T08:37:32.263+0000] {connectionpool.py:812} WARNING - Retrying (Retry(total=0, connect=None, read=None, redirect=None, status=None)) after connection broken by 'NewConnectionError('<urllib3.connection.HTTPConnection object at 0x7f0b140e5100>: Failed to establish a new connection: [Errno 111] Connection refused')': /wd/hub/session
[2025-05-19T08:37:32.264+0000] {MathDag.py:50} ERROR - Lỗi crawl link https://loigiaihay.com/de-tham-khao-thi-vao-10-mon-toan-ha-noi-nam-2025-de-so-4-a181870.html: HTTPConnectionPool(host='localhost', port=4444): Max retries exceeded with url: /wd/hub/session (Caused by NewConnectionError('<urllib3.connection.HTTPConnection object at 0x7f0b140e5250>: Failed to establish a new connection: [Errno 111] Connection refused'))
[2025-05-19T08:37:32.264+0000] {MathDag.py:45} INFO - Đang crawl link 5/64: https://loigiaihay.com/de-tham-khao-thi-vao-10-mon-toan-ha-noi-nam-2025-de-so-5-a182059.html
[2025-05-19T08:37:32.265+0000] {connectionpool.py:812} WARNING - Retrying (Retry(total=2, connect=None, read=None, redirect=None, status=None)) after connection broken by 'NewConnectionError('<urllib3.connection.HTTPConnection object at 0x7f0b140d0a30>: Failed to establish a new connection: [Errno 111] Connection refused')': /wd/hub/session
[2025-05-19T08:37:32.266+0000] {connectionpool.py:812} WARNING - Retrying (Retry(total=1, connect=None, read=None, redirect=None, status=None)) after connection broken by 'NewConnectionError('<urllib3.connection.HTTPConnection object at 0x7f0b140d0e20>: Failed to establish a new connection: [Errno 111] Connection refused')': /wd/hub/session
[2025-05-19T08:37:32.266+0000] {connectionpool.py:812} WARNING - Retrying (Retry(total=0, connect=None, read=None, redirect=None, status=None)) after connection broken by 'NewConnectionError('<urllib3.connection.HTTPConnection object at 0x7f0b140d0eb0>: Failed to establish a new connection: [Errno 111] Connection refused')': /wd/hub/session
[2025-05-19T08:37:32.266+0000] {MathDag.py:50} ERROR - Lỗi crawl link https://loigiaihay.com/de-tham-khao-thi-vao-10-mon-toan-ha-noi-nam-2025-de-so-5-a182059.html: HTTPConnectionPool(host='localhost', port=4444): Max retries exceeded with url: /wd/hub/session (Caused by NewConnectionError('<urllib3.connection.HTTPConnection object at 0x7f0b140d0d00>: Failed to establish a new connection: [Errno 111] Connection refused'))
[2025-05-19T08:37:32.267+0000] {MathDag.py:45} INFO - Đang crawl link 6/64: https://loigiaihay.com/de-tham-khao-thi-vao-10-mon-toan-ha-noi-nam-2025-de-so-6-a182290.html
[2025-05-19T08:37:32.267+0000] {connectionpool.py:812} WARNING - Retrying (Retry(total=2, connect=None, read=None, redirect=None, status=None)) after connection broken by 'NewConnectionError('<urllib3.connection.HTTPConnection object at 0x7f0b140d05b0>: Failed to establish a new connection: [Errno 111] Connection refused')': /wd/hub/session
[2025-05-19T08:37:32.268+0000] {connectionpool.py:812} WARNING - Retrying (Retry(total=1, connect=None, read=None, redirect=None, status=None)) after connection broken by 'NewConnectionError('<urllib3.connection.HTTPConnection object at 0x7f0b14107130>: Failed to establish a new connection: [Errno 111] Connection refused')': /wd/hub/session
[2025-05-19T08:37:32.268+0000] {connectionpool.py:812} WARNING - Retrying (Retry(total=0, connect=None, read=None, redirect=None, status=None)) after connection broken by 'NewConnectionError('<urllib3.connection.HTTPConnection object at 0x7f0b14107e80>: Failed to establish a new connection: [Errno 111] Connection refused')': /wd/hub/session
[2025-05-19T08:37:32.269+0000] {MathDag.py:50} ERROR - Lỗi crawl link https://loigiaihay.com/de-tham-khao-thi-vao-10-mon-toan-ha-noi-nam-2025-de-so-6-a182290.html: HTTPConnectionPool(host='localhost', port=4444): Max retries exceeded with url: /wd/hub/session (Caused by NewConnectionError('<urllib3.connection.HTTPConnection object at 0x7f0b1412eb20>: Failed to establish a new connection: [Errno 111] Connection refused'))
[2025-05-19T08:37:32.269+0000] {MathDag.py:45} INFO - Đang crawl link 7/64: https://loigiaihay.com/de-tham-khao-thi-vao-10-mon-toan-ha-noi-nam-2025-de-so-7-a182562.html
[2025-05-19T08:37:32.270+0000] {connectionpool.py:812} WARNING - Retrying (Retry(total=2, connect=None, read=None, redirect=None, status=None)) after connection broken by 'NewConnectionError('<urllib3.connection.HTTPConnection object at 0x7f0b1414a7f0>: Failed to establish a new connection: [Errno 111] Connection refused')': /wd/hub/session
[2025-05-19T08:37:32.272+0000] {connectionpool.py:812} WARNING - Retrying (Retry(total=1, connect=None, read=None, redirect=None, status=None)) after connection broken by 'NewConnectionError('<urllib3.connection.HTTPConnection object at 0x7f0b140e51c0>: Failed to establish a new connection: [Errno 111] Connection refused')': /wd/hub/session
[2025-05-19T08:37:32.273+0000] {connectionpool.py:812} WARNING - Retrying (Retry(total=0, connect=None, read=None, redirect=None, status=None)) after connection broken by 'NewConnectionError('<urllib3.connection.HTTPConnection object at 0x7f0b140e5160>: Failed to establish a new connection: [Errno 111] Connection refused')': /wd/hub/session
[2025-05-19T08:37:32.274+0000] {MathDag.py:50} ERROR - Lỗi crawl link https://loigiaihay.com/de-tham-khao-thi-vao-10-mon-toan-ha-noi-nam-2025-de-so-7-a182562.html: HTTPConnectionPool(host='localhost', port=4444): Max retries exceeded with url: /wd/hub/session (Caused by NewConnectionError('<urllib3.connection.HTTPConnection object at 0x7f0b140e58e0>: Failed to establish a new connection: [Errno 111] Connection refused'))
[2025-05-19T08:37:32.276+0000] {MathDag.py:45} INFO - Đang crawl link 8/64: https://loigiaihay.com/de-tham-khao-thi-vao-10-mon-toan-ha-noi-nam-2025-de-so-8-a183073.html
[2025-05-19T08:37:32.278+0000] {connectionpool.py:812} WARNING - Retrying (Retry(total=2, connect=None, read=None, redirect=None, status=None)) after connection broken by 'NewConnectionError('<urllib3.connection.HTTPConnection object at 0x7f0b140e5e80>: Failed to establish a new connection: [Errno 111] Connection refused')': /wd/hub/session
[2025-05-19T08:37:32.280+0000] {connectionpool.py:812} WARNING - Retrying (Retry(total=1, connect=None, read=None, redirect=None, status=None)) after connection broken by 'NewConnectionError('<urllib3.connection.HTTPConnection object at 0x7f0b140f6040>: Failed to establish a new connection: [Errno 111] Connection refused')': /wd/hub/session
[2025-05-19T08:37:32.281+0000] {connectionpool.py:812} WARNING - Retrying (Retry(total=0, connect=None, read=None, redirect=None, status=None)) after connection broken by 'NewConnectionError('<urllib3.connection.HTTPConnection object at 0x7f0b1417c910>: Failed to establish a new connection: [Errno 111] Connection refused')': /wd/hub/session
[2025-05-19T08:37:32.281+0000] {MathDag.py:50} ERROR - Lỗi crawl link https://loigiaihay.com/de-tham-khao-thi-vao-10-mon-toan-ha-noi-nam-2025-de-so-8-a183073.html: HTTPConnectionPool(host='localhost', port=4444): Max retries exceeded with url: /wd/hub/session (Caused by NewConnectionError('<urllib3.connection.HTTPConnection object at 0x7f0b140e58b0>: Failed to establish a new connection: [Errno 111] Connection refused'))
[2025-05-19T08:37:32.281+0000] {MathDag.py:45} INFO - Đang crawl link 9/64: https://loigiaihay.com/de-tham-khao-thi-vao-10-mon-toan-ha-noi-nam-2025-de-so-9-a183564.html
[2025-05-19T08:37:32.282+0000] {connectionpool.py:812} WARNING - Retrying (Retry(total=2, connect=None, read=None, redirect=None, status=None)) after connection broken by 'NewConnectionError('<urllib3.connection.HTTPConnection object at 0x7f0b140e56a0>: Failed to establish a new connection: [Errno 111] Connection refused')': /wd/hub/session
[2025-05-19T08:37:32.283+0000] {connectionpool.py:812} WARNING - Retrying (Retry(total=1, connect=None, read=None, redirect=None, status=None)) after connection broken by 'NewConnectionError('<urllib3.connection.HTTPConnection object at 0x7f0b140e5340>: Failed to establish a new connection: [Errno 111] Connection refused')': /wd/hub/session
[2025-05-19T08:37:32.283+0000] {connectionpool.py:812} WARNING - Retrying (Retry(total=0, connect=None, read=None, redirect=None, status=None)) after connection broken by 'NewConnectionError('<urllib3.connection.HTTPConnection object at 0x7f0b141074c0>: Failed to establish a new connection: [Errno 111] Connection refused')': /wd/hub/session
[2025-05-19T08:37:32.284+0000] {MathDag.py:50} ERROR - Lỗi crawl link https://loigiaihay.com/de-tham-khao-thi-vao-10-mon-toan-ha-noi-nam-2025-de-so-9-a183564.html: HTTPConnectionPool(host='localhost', port=4444): Max retries exceeded with url: /wd/hub/session (Caused by NewConnectionError('<urllib3.connection.HTTPConnection object at 0x7f0b14107460>: Failed to establish a new connection: [Errno 111] Connection refused'))
[2025-05-19T08:37:32.284+0000] {MathDag.py:45} INFO - Đang crawl link 10/64: https://loigiaihay.com/de-tham-khao-thi-vao-10-mon-toan-ha-noi-nam-2025-de-so-10-a183809.html
[2025-05-19T08:37:32.285+0000] {connectionpool.py:812} WARNING - Retrying (Retry(total=2, connect=None, read=None, redirect=None, status=None)) after connection broken by 'NewConnectionError('<urllib3.connection.HTTPConnection object at 0x7f0b140d09d0>: Failed to establish a new connection: [Errno 111] Connection refused')': /wd/hub/session
[2025-05-19T08:37:32.285+0000] {connectionpool.py:812} WARNING - Retrying (Retry(total=1, connect=None, read=None, redirect=None, status=None)) after connection broken by 'NewConnectionError('<urllib3.connection.HTTPConnection object at 0x7f0b140d0b20>: Failed to establish a new connection: [Errno 111] Connection refused')': /wd/hub/session
[2025-05-19T08:37:32.286+0000] {connectionpool.py:812} WARNING - Retrying (Retry(total=0, connect=None, read=None, redirect=None, status=None)) after connection broken by 'NewConnectionError('<urllib3.connection.HTTPConnection object at 0x7f0b140d0bb0>: Failed to establish a new connection: [Errno 111] Connection refused')': /wd/hub/session
[2025-05-19T08:37:32.286+0000] {MathDag.py:50} ERROR - Lỗi crawl link https://loigiaihay.com/de-tham-khao-thi-vao-10-mon-toan-ha-noi-nam-2025-de-so-10-a183809.html: HTTPConnectionPool(host='localhost', port=4444): Max retries exceeded with url: /wd/hub/session (Caused by NewConnectionError('<urllib3.connection.HTTPConnection object at 0x7f0b140d0fa0>: Failed to establish a new connection: [Errno 111] Connection refused'))
[2025-05-19T08:37:32.286+0000] {MathDag.py:45} INFO - Đang crawl link 11/64: https://loigiaihay.com/de-tham-khao-thi-vao-10-mon-toan-ha-noi-nam-2025-de-so-11-a184285.html
[2025-05-19T08:37:32.287+0000] {connectionpool.py:812} WARNING - Retrying (Retry(total=2, connect=None, read=None, redirect=None, status=None)) after connection broken by 'NewConnectionError('<urllib3.connection.HTTPConnection object at 0x7f0b140d0190>: Failed to establish a new connection: [Errno 111] Connection refused')': /wd/hub/session
[2025-05-19T08:37:32.287+0000] {connectionpool.py:812} WARNING - Retrying (Retry(total=1, connect=None, read=None, redirect=None, status=None)) after connection broken by 'NewConnectionError('<urllib3.connection.HTTPConnection object at 0x7f0b1412ec70>: Failed to establish a new connection: [Errno 111] Connection refused')': /wd/hub/session
[2025-05-19T08:37:32.288+0000] {connectionpool.py:812} WARNING - Retrying (Retry(total=0, connect=None, read=None, redirect=None, status=None)) after connection broken by 'NewConnectionError('<urllib3.connection.HTTPConnection object at 0x7f0b1412ee50>: Failed to establish a new connection: [Errno 111] Connection refused')': /wd/hub/session
[2025-05-19T08:37:32.288+0000] {MathDag.py:50} ERROR - Lỗi crawl link https://loigiaihay.com/de-tham-khao-thi-vao-10-mon-toan-ha-noi-nam-2025-de-so-11-a184285.html: HTTPConnectionPool(host='localhost', port=4444): Max retries exceeded with url: /wd/hub/session (Caused by NewConnectionError('<urllib3.connection.HTTPConnection object at 0x7f0b1412e760>: Failed to establish a new connection: [Errno 111] Connection refused'))
[2025-05-19T08:37:32.289+0000] {MathDag.py:45} INFO - Đang crawl link 12/64: https://loigiaihay.com/de-tham-khao-thi-vao-10-toan-tp-ho-chi-minh-nam-2025-co-dap-an-va-loi-giai-chi-tiet-de-1-a179544.html
[2025-05-19T08:37:32.290+0000] {connectionpool.py:812} WARNING - Retrying (Retry(total=2, connect=None, read=None, redirect=None, status=None)) after connection broken by 'NewConnectionError('<urllib3.connection.HTTPConnection object at 0x7f0b140d0ac0>: Failed to establish a new connection: [Errno 111] Connection refused')': /wd/hub/session
[2025-05-19T08:37:32.290+0000] {connectionpool.py:812} WARNING - Retrying (Retry(total=1, connect=None, read=None, redirect=None, status=None)) after connection broken by 'NewConnectionError('<urllib3.connection.HTTPConnection object at 0x7f0b140d0940>: Failed to establish a new connection: [Errno 111] Connection refused')': /wd/hub/session
[2025-05-19T08:37:32.291+0000] {connectionpool.py:812} WARNING - Retrying (Retry(total=0, connect=None, read=None, redirect=None, status=None)) after connection broken by 'NewConnectionError('<urllib3.connection.HTTPConnection object at 0x7f0b140d06d0>: Failed to establish a new connection: [Errno 111] Connection refused')': /wd/hub/session
[2025-05-19T08:37:32.291+0000] {MathDag.py:50} ERROR - Lỗi crawl link https://loigiaihay.com/de-tham-khao-thi-vao-10-toan-tp-ho-chi-minh-nam-2025-co-dap-an-va-loi-giai-chi-tiet-de-1-a179544.html: HTTPConnectionPool(host='localhost', port=4444): Max retries exceeded with url: /wd/hub/session (Caused by NewConnectionError('<urllib3.connection.HTTPConnection object at 0x7f0b14107220>: Failed to establish a new connection: [Errno 111] Connection refused'))
[2025-05-19T08:37:32.292+0000] {MathDag.py:45} INFO - Đang crawl link 13/64: https://loigiaihay.com/de-tham-khao-thi-vao-10-mon-toan-tp-ho-chi-minh-nam-2025-de-so-2-a181829.html
[2025-05-19T08:37:32.293+0000] {connectionpool.py:812} WARNING - Retrying (Retry(total=2, connect=None, read=None, redirect=None, status=None)) after connection broken by 'NewConnectionError('<urllib3.connection.HTTPConnection object at 0x7f0b140e55e0>: Failed to establish a new connection: [Errno 111] Connection refused')': /wd/hub/session
[2025-05-19T08:37:32.293+0000] {connectionpool.py:812} WARNING - Retrying (Retry(total=1, connect=None, read=None, redirect=None, status=None)) after connection broken by 'NewConnectionError('<urllib3.connection.HTTPConnection object at 0x7f0b140e5700>: Failed to establish a new connection: [Errno 111] Connection refused')': /wd/hub/session
[2025-05-19T08:37:32.293+0000] {connectionpool.py:812} WARNING - Retrying (Retry(total=0, connect=None, read=None, redirect=None, status=None)) after connection broken by 'NewConnectionError('<urllib3.connection.HTTPConnection object at 0x7f0b140e54c0>: Failed to establish a new connection: [Errno 111] Connection refused')': /wd/hub/session
[2025-05-19T08:37:32.294+0000] {MathDag.py:50} ERROR - Lỗi crawl link https://loigiaihay.com/de-tham-khao-thi-vao-10-mon-toan-tp-ho-chi-minh-nam-2025-de-so-2-a181829.html: HTTPConnectionPool(host='localhost', port=4444): Max retries exceeded with url: /wd/hub/session (Caused by NewConnectionError('<urllib3.connection.HTTPConnection object at 0x7f0b140e5160>: Failed to establish a new connection: [Errno 111] Connection refused'))
[2025-05-19T08:37:32.294+0000] {MathDag.py:45} INFO - Đang crawl link 14/64: https://loigiaihay.com/de-tham-khao-thi-vao-10-mon-toan-tp-ho-chi-minh-nam-2025-de-so-3-a181884.html
[2025-05-19T08:37:32.295+0000] {connectionpool.py:812} WARNING - Retrying (Retry(total=2, connect=None, read=None, redirect=None, status=None)) after connection broken by 'NewConnectionError('<urllib3.connection.HTTPConnection object at 0x7f0b1412efd0>: Failed to establish a new connection: [Errno 111] Connection refused')': /wd/hub/session
[2025-05-19T08:37:32.295+0000] {connectionpool.py:812} WARNING - Retrying (Retry(total=1, connect=None, read=None, redirect=None, status=None)) after connection broken by 'NewConnectionError('<urllib3.connection.HTTPConnection object at 0x7f0b140f6040>: Failed to establish a new connection: [Errno 111] Connection refused')': /wd/hub/session
[2025-05-19T08:37:32.295+0000] {connectionpool.py:812} WARNING - Retrying (Retry(total=0, connect=None, read=None, redirect=None, status=None)) after connection broken by 'NewConnectionError('<urllib3.connection.HTTPConnection object at 0x7f0b140f61c0>: Failed to establish a new connection: [Errno 111] Connection refused')': /wd/hub/session
[2025-05-19T08:37:32.296+0000] {MathDag.py:50} ERROR - Lỗi crawl link https://loigiaihay.com/de-tham-khao-thi-vao-10-mon-toan-tp-ho-chi-minh-nam-2025-de-so-3-a181884.html: HTTPConnectionPool(host='localhost', port=4444): Max retries exceeded with url: /wd/hub/session (Caused by NewConnectionError('<urllib3.connection.HTTPConnection object at 0x7f0b140f6310>: Failed to establish a new connection: [Errno 111] Connection refused'))
[2025-05-19T08:37:32.296+0000] {MathDag.py:45} INFO - Đang crawl link 15/64: https://loigiaihay.com/de-tham-khao-thi-vao-10-mon-toan-tp-ho-chi-minh-nam-2025-de-so-4-a181981.html
[2025-05-19T08:37:32.298+0000] {connectionpool.py:812} WARNING - Retrying (Retry(total=2, connect=None, read=None, redirect=None, status=None)) after connection broken by 'NewConnectionError('<urllib3.connection.HTTPConnection object at 0x7f0b141afcd0>: Failed to establish a new connection: [Errno 111] Connection refused')': /wd/hub/session
[2025-05-19T08:37:32.298+0000] {connectionpool.py:812} WARNING - Retrying (Retry(total=1, connect=None, read=None, redirect=None, status=None)) after connection broken by 'NewConnectionError('<urllib3.connection.HTTPConnection object at 0x7f0b1412eb20>: Failed to establish a new connection: [Errno 111] Connection refused')': /wd/hub/session
[2025-05-19T08:37:32.299+0000] {connectionpool.py:812} WARNING - Retrying (Retry(total=0, connect=None, read=None, redirect=None, status=None)) after connection broken by 'NewConnectionError('<urllib3.connection.HTTPConnection object at 0x7f0b1412e310>: Failed to establish a new connection: [Errno 111] Connection refused')': /wd/hub/session
[2025-05-19T08:37:32.299+0000] {MathDag.py:50} ERROR - Lỗi crawl link https://loigiaihay.com/de-tham-khao-thi-vao-10-mon-toan-tp-ho-chi-minh-nam-2025-de-so-4-a181981.html: HTTPConnectionPool(host='localhost', port=4444): Max retries exceeded with url: /wd/hub/session (Caused by NewConnectionError('<urllib3.connection.HTTPConnection object at 0x7f0b140e5940>: Failed to establish a new connection: [Errno 111] Connection refused'))
[2025-05-19T08:37:32.299+0000] {MathDag.py:45} INFO - Đang crawl link 16/64: https://loigiaihay.com/de-tham-khao-thi-vao-10-mon-toan-tp-ho-chi-minh-nam-2025-de-so-5-a182269.html
[2025-05-19T08:37:32.300+0000] {connectionpool.py:812} WARNING - Retrying (Retry(total=2, connect=None, read=None, redirect=None, status=None)) after connection broken by 'NewConnectionError('<urllib3.connection.HTTPConnection object at 0x7f0b140e5730>: Failed to establish a new connection: [Errno 111] Connection refused')': /wd/hub/session
[2025-05-19T08:37:32.301+0000] {connectionpool.py:812} WARNING - Retrying (Retry(total=1, connect=None, read=None, redirect=None, status=None)) after connection broken by 'NewConnectionError('<urllib3.connection.HTTPConnection object at 0x7f0b140e5460>: Failed to establish a new connection: [Errno 111] Connection refused')': /wd/hub/session
[2025-05-19T08:37:32.301+0000] {connectionpool.py:812} WARNING - Retrying (Retry(total=0, connect=None, read=None, redirect=None, status=None)) after connection broken by 'NewConnectionError('<urllib3.connection.HTTPConnection object at 0x7f0b14107e80>: Failed to establish a new connection: [Errno 111] Connection refused')': /wd/hub/session
[2025-05-19T08:37:32.301+0000] {MathDag.py:50} ERROR - Lỗi crawl link https://loigiaihay.com/de-tham-khao-thi-vao-10-mon-toan-tp-ho-chi-minh-nam-2025-de-so-5-a182269.html: HTTPConnectionPool(host='localhost', port=4444): Max retries exceeded with url: /wd/hub/session (Caused by NewConnectionError('<urllib3.connection.HTTPConnection object at 0x7f0b14107460>: Failed to establish a new connection: [Errno 111] Connection refused'))
[2025-05-19T08:37:32.302+0000] {MathDag.py:45} INFO - Đang crawl link 17/64: https://loigiaihay.com/de-tham-khao-thi-vao-10-mon-toan-tp-ho-chi-minh-nam-2025-de-so-6-a182568.html
[2025-05-19T08:37:32.302+0000] {connectionpool.py:812} WARNING - Retrying (Retry(total=2, connect=None, read=None, redirect=None, status=None)) after connection broken by 'NewConnectionError('<urllib3.connection.HTTPConnection object at 0x7f0b140d0a90>: Failed to establish a new connection: [Errno 111] Connection refused')': /wd/hub/session
[2025-05-19T08:37:32.303+0000] {connectionpool.py:812} WARNING - Retrying (Retry(total=1, connect=None, read=None, redirect=None, status=None)) after connection broken by 'NewConnectionError('<urllib3.connection.HTTPConnection object at 0x7f0b140d09d0>: Failed to establish a new connection: [Errno 111] Connection refused')': /wd/hub/session
[2025-05-19T08:37:32.303+0000] {connectionpool.py:812} WARNING - Retrying (Retry(total=0, connect=None, read=None, redirect=None, status=None)) after connection broken by 'NewConnectionError('<urllib3.connection.HTTPConnection object at 0x7f0b140d0e80>: Failed to establish a new connection: [Errno 111] Connection refused')': /wd/hub/session
[2025-05-19T08:37:32.304+0000] {MathDag.py:50} ERROR - Lỗi crawl link https://loigiaihay.com/de-tham-khao-thi-vao-10-mon-toan-tp-ho-chi-minh-nam-2025-de-so-6-a182568.html: HTTPConnectionPool(host='localhost', port=4444): Max retries exceeded with url: /wd/hub/session (Caused by NewConnectionError('<urllib3.connection.HTTPConnection object at 0x7f0b140d0f70>: Failed to establish a new connection: [Errno 111] Connection refused'))
[2025-05-19T08:37:32.304+0000] {MathDag.py:45} INFO - Đang crawl link 18/64: https://loigiaihay.com/de-tham-khao-thi-vao-10-mon-toan-tp-ho-chi-minh-nam-2025-de-so-7-a182986.html
[2025-05-19T08:37:32.305+0000] {connectionpool.py:812} WARNING - Retrying (Retry(total=2, connect=None, read=None, redirect=None, status=None)) after connection broken by 'NewConnectionError('<urllib3.connection.HTTPConnection object at 0x7f0b140f6940>: Failed to establish a new connection: [Errno 111] Connection refused')': /wd/hub/session
[2025-05-19T08:37:32.306+0000] {connectionpool.py:812} WARNING - Retrying (Retry(total=1, connect=None, read=None, redirect=None, status=None)) after connection broken by 'NewConnectionError('<urllib3.connection.HTTPConnection object at 0x7f0b140f6a60>: Failed to establish a new connection: [Errno 111] Connection refused')': /wd/hub/session
[2025-05-19T08:37:32.306+0000] {connectionpool.py:812} WARNING - Retrying (Retry(total=0, connect=None, read=None, redirect=None, status=None)) after connection broken by 'NewConnectionError('<urllib3.connection.HTTPConnection object at 0x7f0b140d0b50>: Failed to establish a new connection: [Errno 111] Connection refused')': /wd/hub/session
[2025-05-19T08:37:32.306+0000] {MathDag.py:50} ERROR - Lỗi crawl link https://loigiaihay.com/de-tham-khao-thi-vao-10-mon-toan-tp-ho-chi-minh-nam-2025-de-so-7-a182986.html: HTTPConnectionPool(host='localhost', port=4444): Max retries exceeded with url: /wd/hub/session (Caused by NewConnectionError('<urllib3.connection.HTTPConnection object at 0x7f0b140d0d60>: Failed to establish a new connection: [Errno 111] Connection refused'))
[2025-05-19T08:37:32.307+0000] {MathDag.py:45} INFO - Đang crawl link 19/64: https://loigiaihay.com/de-tham-khao-thi-vao-10-mon-toan-tp-ho-chi-minh-nam-2025-de-so-8-a183544.html
[2025-05-19T08:37:32.307+0000] {connectionpool.py:812} WARNING - Retrying (Retry(total=2, connect=None, read=None, redirect=None, status=None)) after connection broken by 'NewConnectionError('<urllib3.connection.HTTPConnection object at 0x7f0b140d0dc0>: Failed to establish a new connection: [Errno 111] Connection refused')': /wd/hub/session
[2025-05-19T08:37:32.308+0000] {connectionpool.py:812} WARNING - Retrying (Retry(total=1, connect=None, read=None, redirect=None, status=None)) after connection broken by 'NewConnectionError('<urllib3.connection.HTTPConnection object at 0x7f0b14107610>: Failed to establish a new connection: [Errno 111] Connection refused')': /wd/hub/session
[2025-05-19T08:37:32.308+0000] {connectionpool.py:812} WARNING - Retrying (Retry(total=0, connect=None, read=None, redirect=None, status=None)) after connection broken by 'NewConnectionError('<urllib3.connection.HTTPConnection object at 0x7f0b141074c0>: Failed to establish a new connection: [Errno 111] Connection refused')': /wd/hub/session
[2025-05-19T08:37:32.309+0000] {MathDag.py:50} ERROR - Lỗi crawl link https://loigiaihay.com/de-tham-khao-thi-vao-10-mon-toan-tp-ho-chi-minh-nam-2025-de-so-8-a183544.html: HTTPConnectionPool(host='localhost', port=4444): Max retries exceeded with url: /wd/hub/session (Caused by NewConnectionError('<urllib3.connection.HTTPConnection object at 0x7f0b1417c910>: Failed to establish a new connection: [Errno 111] Connection refused'))
[2025-05-19T08:37:32.309+0000] {MathDag.py:45} INFO - Đang crawl link 20/64: https://loigiaihay.com/de-tham-khao-thi-vao-10-mon-toan-tp-ho-chi-minh-nam-2025-de-so-9-a184122.html
[2025-05-19T08:37:32.310+0000] {connectionpool.py:812} WARNING - Retrying (Retry(total=2, connect=None, read=None, redirect=None, status=None)) after connection broken by 'NewConnectionError('<urllib3.connection.HTTPConnection object at 0x7f0b140e54f0>: Failed to establish a new connection: [Errno 111] Connection refused')': /wd/hub/session
[2025-05-19T08:37:32.310+0000] {connectionpool.py:812} WARNING - Retrying (Retry(total=1, connect=None, read=None, redirect=None, status=None)) after connection broken by 'NewConnectionError('<urllib3.connection.HTTPConnection object at 0x7f0b140e5190>: Failed to establish a new connection: [Errno 111] Connection refused')': /wd/hub/session
[2025-05-19T08:37:32.311+0000] {connectionpool.py:812} WARNING - Retrying (Retry(total=0, connect=None, read=None, redirect=None, status=None)) after connection broken by 'NewConnectionError('<urllib3.connection.HTTPConnection object at 0x7f0b140e5280>: Failed to establish a new connection: [Errno 111] Connection refused')': /wd/hub/session
[2025-05-19T08:37:32.311+0000] {MathDag.py:50} ERROR - Lỗi crawl link https://loigiaihay.com/de-tham-khao-thi-vao-10-mon-toan-tp-ho-chi-minh-nam-2025-de-so-9-a184122.html: HTTPConnectionPool(host='localhost', port=4444): Max retries exceeded with url: /wd/hub/session (Caused by NewConnectionError('<urllib3.connection.HTTPConnection object at 0x7f0b1414a130>: Failed to establish a new connection: [Errno 111] Connection refused'))
[2025-05-19T08:37:32.311+0000] {MathDag.py:45} INFO - Đang crawl link 21/64: https://loigiaihay.com/de-tham-khao-thi-vao-10-mon-toan-tp-ho-chi-minh-nam-2025-de-so-10-a184527.html
[2025-05-19T08:37:32.312+0000] {connectionpool.py:812} WARNING - Retrying (Retry(total=2, connect=None, read=None, redirect=None, status=None)) after connection broken by 'NewConnectionError('<urllib3.connection.HTTPConnection object at 0x7f0b140f6640>: Failed to establish a new connection: [Errno 111] Connection refused')': /wd/hub/session
[2025-05-19T08:37:32.313+0000] {connectionpool.py:812} WARNING - Retrying (Retry(total=1, connect=None, read=None, redirect=None, status=None)) after connection broken by 'NewConnectionError('<urllib3.connection.HTTPConnection object at 0x7f0b140f6790>: Failed to establish a new connection: [Errno 111] Connection refused')': /wd/hub/session
[2025-05-19T08:37:32.313+0000] {connectionpool.py:812} WARNING - Retrying (Retry(total=0, connect=None, read=None, redirect=None, status=None)) after connection broken by 'NewConnectionError('<urllib3.connection.HTTPConnection object at 0x7f0b140f6ca0>: Failed to establish a new connection: [Errno 111] Connection refused')': /wd/hub/session
[2025-05-19T08:37:32.314+0000] {MathDag.py:50} ERROR - Lỗi crawl link https://loigiaihay.com/de-tham-khao-thi-vao-10-mon-toan-tp-ho-chi-minh-nam-2025-de-so-10-a184527.html: HTTPConnectionPool(host='localhost', port=4444): Max retries exceeded with url: /wd/hub/session (Caused by NewConnectionError('<urllib3.connection.HTTPConnection object at 0x7f0b140f6df0>: Failed to establish a new connection: [Errno 111] Connection refused'))
[2025-05-19T08:37:32.314+0000] {MathDag.py:45} INFO - Đang crawl link 22/64: https://loigiaihay.com/de-so-1-de-thi-vao-lop-10-mon-toan-c44a49454.html
[2025-05-19T08:37:32.315+0000] {connectionpool.py:812} WARNING - Retrying (Retry(total=2, connect=None, read=None, redirect=None, status=None)) after connection broken by 'NewConnectionError('<urllib3.connection.HTTPConnection object at 0x7f0b140e54f0>: Failed to establish a new connection: [Errno 111] Connection refused')': /wd/hub/session
[2025-05-19T08:37:32.315+0000] {connectionpool.py:812} WARNING - Retrying (Retry(total=1, connect=None, read=None, redirect=None, status=None)) after connection broken by 'NewConnectionError('<urllib3.connection.HTTPConnection object at 0x7f0b140e55e0>: Failed to establish a new connection: [Errno 111] Connection refused')': /wd/hub/session
[2025-05-19T08:37:32.316+0000] {connectionpool.py:812} WARNING - Retrying (Retry(total=0, connect=None, read=None, redirect=None, status=None)) after connection broken by 'NewConnectionError('<urllib3.connection.HTTPConnection object at 0x7f0b140e5460>: Failed to establish a new connection: [Errno 111] Connection refused')': /wd/hub/session
[2025-05-19T08:37:32.316+0000] {MathDag.py:50} ERROR - Lỗi crawl link https://loigiaihay.com/de-so-1-de-thi-vao-lop-10-mon-toan-c44a49454.html: HTTPConnectionPool(host='localhost', port=4444): Max retries exceeded with url: /wd/hub/session (Caused by NewConnectionError('<urllib3.connection.HTTPConnection object at 0x7f0b140e5430>: Failed to establish a new connection: [Errno 111] Connection refused'))
[2025-05-19T08:37:32.316+0000] {MathDag.py:45} INFO - Đang crawl link 23/64: https://loigiaihay.com/de-so-2-de-thi-vao-lop-10-mon-toan-c44a49464.html
[2025-05-19T08:37:32.318+0000] {connectionpool.py:812} WARNING - Retrying (Retry(total=2, connect=None, read=None, redirect=None, status=None)) after connection broken by 'NewConnectionError('<urllib3.connection.HTTPConnection object at 0x7f0b140d0dc0>: Failed to establish a new connection: [Errno 111] Connection refused')': /wd/hub/session
[2025-05-19T08:37:32.318+0000] {connectionpool.py:812} WARNING - Retrying (Retry(total=1, connect=None, read=None, redirect=None, status=None)) after connection broken by 'NewConnectionError('<urllib3.connection.HTTPConnection object at 0x7f0b140d0c10>: Failed to establish a new connection: [Errno 111] Connection refused')': /wd/hub/session
[2025-05-19T08:37:32.319+0000] {connectionpool.py:812} WARNING - Retrying (Retry(total=0, connect=None, read=None, redirect=None, status=None)) after connection broken by 'NewConnectionError('<urllib3.connection.HTTPConnection object at 0x7f0b140d0820>: Failed to establish a new connection: [Errno 111] Connection refused')': /wd/hub/session
[2025-05-19T08:37:32.319+0000] {MathDag.py:50} ERROR - Lỗi crawl link https://loigiaihay.com/de-so-2-de-thi-vao-lop-10-mon-toan-c44a49464.html: HTTPConnectionPool(host='localhost', port=4444): Max retries exceeded with url: /wd/hub/session (Caused by NewConnectionError('<urllib3.connection.HTTPConnection object at 0x7f0b140d0a00>: Failed to establish a new connection: [Errno 111] Connection refused'))
[2025-05-19T08:37:32.319+0000] {MathDag.py:45} INFO - Đang crawl link 24/64: https://loigiaihay.com/de-so-3-de-thi-vao-lop-10-mon-toan-c44a49465.html
[2025-05-19T08:37:32.320+0000] {connectionpool.py:812} WARNING - Retrying (Retry(total=2, connect=None, read=None, redirect=None, status=None)) after connection broken by 'NewConnectionError('<urllib3.connection.HTTPConnection object at 0x7f0b140861f0>: Failed to establish a new connection: [Errno 111] Connection refused')': /wd/hub/session
[2025-05-19T08:37:32.320+0000] {connectionpool.py:812} WARNING - Retrying (Retry(total=1, connect=None, read=None, redirect=None, status=None)) after connection broken by 'NewConnectionError('<urllib3.connection.HTTPConnection object at 0x7f0b14086310>: Failed to establish a new connection: [Errno 111] Connection refused')': /wd/hub/session
[2025-05-19T08:37:32.321+0000] {connectionpool.py:812} WARNING - Retrying (Retry(total=0, connect=None, read=None, redirect=None, status=None)) after connection broken by 'NewConnectionError('<urllib3.connection.HTTPConnection object at 0x7f0b140864c0>: Failed to establish a new connection: [Errno 111] Connection refused')': /wd/hub/session
[2025-05-19T08:37:32.321+0000] {MathDag.py:50} ERROR - Lỗi crawl link https://loigiaihay.com/de-so-3-de-thi-vao-lop-10-mon-toan-c44a49465.html: HTTPConnectionPool(host='localhost', port=4444): Max retries exceeded with url: /wd/hub/session (Caused by NewConnectionError('<urllib3.connection.HTTPConnection object at 0x7f0b14086610>: Failed to establish a new connection: [Errno 111] Connection refused'))
[2025-05-19T08:37:32.322+0000] {MathDag.py:45} INFO - Đang crawl link 25/64: https://loigiaihay.com/de-so-4-de-thi-vao-lop-10-mon-toan-c44a49466.html
[2025-05-19T08:37:32.323+0000] {connectionpool.py:812} WARNING - Retrying (Retry(total=2, connect=None, read=None, redirect=None, status=None)) after connection broken by 'NewConnectionError('<urllib3.connection.HTTPConnection object at 0x7f0b140d0970>: Failed to establish a new connection: [Errno 111] Connection refused')': /wd/hub/session
[2025-05-19T08:37:32.323+0000] {connectionpool.py:812} WARNING - Retrying (Retry(total=1, connect=None, read=None, redirect=None, status=None)) after connection broken by 'NewConnectionError('<urllib3.connection.HTTPConnection object at 0x7f0b140d0d60>: Failed to establish a new connection: [Errno 111] Connection refused')': /wd/hub/session
[2025-05-19T08:37:32.323+0000] {connectionpool.py:812} WARNING - Retrying (Retry(total=0, connect=None, read=None, redirect=None, status=None)) after connection broken by 'NewConnectionError('<urllib3.connection.HTTPConnection object at 0x7f0b140d0d90>: Failed to establish a new connection: [Errno 111] Connection refused')': /wd/hub/session
[2025-05-19T08:37:32.324+0000] {MathDag.py:50} ERROR - Lỗi crawl link https://loigiaihay.com/de-so-4-de-thi-vao-lop-10-mon-toan-c44a49466.html: HTTPConnectionPool(host='localhost', port=4444): Max retries exceeded with url: /wd/hub/session (Caused by NewConnectionError('<urllib3.connection.HTTPConnection object at 0x7f0b140d0ca0>: Failed to establish a new connection: [Errno 111] Connection refused'))
[2025-05-19T08:37:32.324+0000] {MathDag.py:45} INFO - Đang crawl link 26/64: https://loigiaihay.com/de-so-5-de-thi-vao-lop-10-mon-toan-c44a49467.html
[2025-05-19T08:37:32.325+0000] {connectionpool.py:812} WARNING - Retrying (Retry(total=2, connect=None, read=None, redirect=None, status=None)) after connection broken by 'NewConnectionError('<urllib3.connection.HTTPConnection object at 0x7f0b141072e0>: Failed to establish a new connection: [Errno 111] Connection refused')': /wd/hub/session
[2025-05-19T08:37:32.326+0000] {connectionpool.py:812} WARNING - Retrying (Retry(total=1, connect=None, read=None, redirect=None, status=None)) after connection broken by 'NewConnectionError('<urllib3.connection.HTTPConnection object at 0x7f0b1414a130>: Failed to establish a new connection: [Errno 111] Connection refused')': /wd/hub/session
[2025-05-19T08:37:32.326+0000] {connectionpool.py:812} WARNING - Retrying (Retry(total=0, connect=None, read=None, redirect=None, status=None)) after connection broken by 'NewConnectionError('<urllib3.connection.HTTPConnection object at 0x7f0b140e5880>: Failed to establish a new connection: [Errno 111] Connection refused')': /wd/hub/session
[2025-05-19T08:37:32.326+0000] {MathDag.py:50} ERROR - Lỗi crawl link https://loigiaihay.com/de-so-5-de-thi-vao-lop-10-mon-toan-c44a49467.html: HTTPConnectionPool(host='localhost', port=4444): Max retries exceeded with url: /wd/hub/session (Caused by NewConnectionError('<urllib3.connection.HTTPConnection object at 0x7f0b140e5bb0>: Failed to establish a new connection: [Errno 111] Connection refused'))
[2025-05-19T08:37:32.327+0000] {MathDag.py:45} INFO - Đang crawl link 27/64: https://loigiaihay.com/de-so-6-de-thi-vao-lop-10-mon-toan-c44a49468.html
[2025-05-19T08:37:32.327+0000] {connectionpool.py:812} WARNING - Retrying (Retry(total=2, connect=None, read=None, redirect=None, status=None)) after connection broken by 'NewConnectionError('<urllib3.connection.HTTPConnection object at 0x7f0b140e55b0>: Failed to establish a new connection: [Errno 111] Connection refused')': /wd/hub/session
[2025-05-19T08:37:32.328+0000] {connectionpool.py:812} WARNING - Retrying (Retry(total=1, connect=None, read=None, redirect=None, status=None)) after connection broken by 'NewConnectionError('<urllib3.connection.HTTPConnection object at 0x7f0b14086880>: Failed to establish a new connection: [Errno 111] Connection refused')': /wd/hub/session
[2025-05-19T08:37:32.328+0000] {connectionpool.py:812} WARNING - Retrying (Retry(total=0, connect=None, read=None, redirect=None, status=None)) after connection broken by 'NewConnectionError('<urllib3.connection.HTTPConnection object at 0x7f0b14086490>: Failed to establish a new connection: [Errno 111] Connection refused')': /wd/hub/session
[2025-05-19T08:37:32.329+0000] {MathDag.py:50} ERROR - Lỗi crawl link https://loigiaihay.com/de-so-6-de-thi-vao-lop-10-mon-toan-c44a49468.html: HTTPConnectionPool(host='localhost', port=4444): Max retries exceeded with url: /wd/hub/session (Caused by NewConnectionError('<urllib3.connection.HTTPConnection object at 0x7f0b140864f0>: Failed to establish a new connection: [Errno 111] Connection refused'))
[2025-05-19T08:37:32.329+0000] {MathDag.py:45} INFO - Đang crawl link 28/64: https://loigiaihay.com/de-so-7-de-thi-vao-lop-10-mon-toan-c44a49469.html
[2025-05-19T08:37:32.330+0000] {connectionpool.py:812} WARNING - Retrying (Retry(total=2, connect=None, read=None, redirect=None, status=None)) after connection broken by 'NewConnectionError('<urllib3.connection.HTTPConnection object at 0x7f0b14086c40>: Failed to establish a new connection: [Errno 111] Connection refused')': /wd/hub/session
[2025-05-19T08:37:32.330+0000] {connectionpool.py:812} WARNING - Retrying (Retry(total=1, connect=None, read=None, redirect=None, status=None)) after connection broken by 'NewConnectionError('<urllib3.connection.HTTPConnection object at 0x7f0b1412ef40>: Failed to establish a new connection: [Errno 111] Connection refused')': /wd/hub/session
[2025-05-19T08:37:32.331+0000] {connectionpool.py:812} WARNING - Retrying (Retry(total=0, connect=None, read=None, redirect=None, status=None)) after connection broken by 'NewConnectionError('<urllib3.connection.HTTPConnection object at 0x7f0b140e5220>: Failed to establish a new connection: [Errno 111] Connection refused')': /wd/hub/session
[2025-05-19T08:37:32.332+0000] {MathDag.py:50} ERROR - Lỗi crawl link https://loigiaihay.com/de-so-7-de-thi-vao-lop-10-mon-toan-c44a49469.html: HTTPConnectionPool(host='localhost', port=4444): Max retries exceeded with url: /wd/hub/session (Caused by NewConnectionError('<urllib3.connection.HTTPConnection object at 0x7f0b140e5910>: Failed to establish a new connection: [Errno 111] Connection refused'))
[2025-05-19T08:37:32.332+0000] {MathDag.py:45} INFO - Đang crawl link 29/64: https://loigiaihay.com/de-so-8-de-thi-vao-lop-10-mon-toan-c44a49470.html
[2025-05-19T08:37:32.333+0000] {connectionpool.py:812} WARNING - Retrying (Retry(total=2, connect=None, read=None, redirect=None, status=None)) after connection broken by 'NewConnectionError('<urllib3.connection.HTTPConnection object at 0x7f0b140e5850>: Failed to establish a new connection: [Errno 111] Connection refused')': /wd/hub/session
[2025-05-19T08:37:32.333+0000] {connectionpool.py:812} WARNING - Retrying (Retry(total=1, connect=None, read=None, redirect=None, status=None)) after connection broken by 'NewConnectionError('<urllib3.connection.HTTPConnection object at 0x7f0b14107160>: Failed to establish a new connection: [Errno 111] Connection refused')': /wd/hub/session
[2025-05-19T08:37:32.334+0000] {connectionpool.py:812} WARNING - Retrying (Retry(total=0, connect=None, read=None, redirect=None, status=None)) after connection broken by 'NewConnectionError('<urllib3.connection.HTTPConnection object at 0x7f0b141075b0>: Failed to establish a new connection: [Errno 111] Connection refused')': /wd/hub/session
[2025-05-19T08:37:32.334+0000] {MathDag.py:50} ERROR - Lỗi crawl link https://loigiaihay.com/de-so-8-de-thi-vao-lop-10-mon-toan-c44a49470.html: HTTPConnectionPool(host='localhost', port=4444): Max retries exceeded with url: /wd/hub/session (Caused by NewConnectionError('<urllib3.connection.HTTPConnection object at 0x7f0b140f6eb0>: Failed to establish a new connection: [Errno 111] Connection refused'))
[2025-05-19T08:37:32.335+0000] {MathDag.py:45} INFO - Đang crawl link 30/64: https://loigiaihay.com/de-so-9-de-thi-vao-lop-10-mon-toan-c44a49471.html
[2025-05-19T08:37:32.335+0000] {connectionpool.py:812} WARNING - Retrying (Retry(total=2, connect=None, read=None, redirect=None, status=None)) after connection broken by 'NewConnectionError('<urllib3.connection.HTTPConnection object at 0x7f0b140d0e50>: Failed to establish a new connection: [Errno 111] Connection refused')': /wd/hub/session
[2025-05-19T08:37:32.336+0000] {connectionpool.py:812} WARNING - Retrying (Retry(total=1, connect=None, read=None, redirect=None, status=None)) after connection broken by 'NewConnectionError('<urllib3.connection.HTTPConnection object at 0x7f0b140d0c40>: Failed to establish a new connection: [Errno 111] Connection refused')': /wd/hub/session
[2025-05-19T08:37:32.336+0000] {connectionpool.py:812} WARNING - Retrying (Retry(total=0, connect=None, read=None, redirect=None, status=None)) after connection broken by 'NewConnectionError('<urllib3.connection.HTTPConnection object at 0x7f0b140d0970>: Failed to establish a new connection: [Errno 111] Connection refused')': /wd/hub/session
[2025-05-19T08:37:32.337+0000] {MathDag.py:50} ERROR - Lỗi crawl link https://loigiaihay.com/de-so-9-de-thi-vao-lop-10-mon-toan-c44a49471.html: HTTPConnectionPool(host='localhost', port=4444): Max retries exceeded with url: /wd/hub/session (Caused by NewConnectionError('<urllib3.connection.HTTPConnection object at 0x7f0b14086df0>: Failed to establish a new connection: [Errno 111] Connection refused'))
[2025-05-19T08:37:32.337+0000] {MathDag.py:45} INFO - Đang crawl link 31/64: https://loigiaihay.com/de-so-10-de-thi-vao-lop-10-mon-toan-c44a49472.html
[2025-05-19T08:37:32.338+0000] {connectionpool.py:812} WARNING - Retrying (Retry(total=2, connect=None, read=None, redirect=None, status=None)) after connection broken by 'NewConnectionError('<urllib3.connection.HTTPConnection object at 0x7f0b14086820>: Failed to establish a new connection: [Errno 111] Connection refused')': /wd/hub/session
[2025-05-19T08:37:32.338+0000] {connectionpool.py:812} WARNING - Retrying (Retry(total=1, connect=None, read=None, redirect=None, status=None)) after connection broken by 'NewConnectionError('<urllib3.connection.HTTPConnection object at 0x7f0b14086940>: Failed to establish a new connection: [Errno 111] Connection refused')': /wd/hub/session
[2025-05-19T08:37:32.339+0000] {connectionpool.py:812} WARNING - Retrying (Retry(total=0, connect=None, read=None, redirect=None, status=None)) after connection broken by 'NewConnectionError('<urllib3.connection.HTTPConnection object at 0x7f0b14086fa0>: Failed to establish a new connection: [Errno 111] Connection refused')': /wd/hub/session
[2025-05-19T08:37:32.340+0000] {MathDag.py:50} ERROR - Lỗi crawl link https://loigiaihay.com/de-so-10-de-thi-vao-lop-10-mon-toan-c44a49472.html: HTTPConnectionPool(host='localhost', port=4444): Max retries exceeded with url: /wd/hub/session (Caused by NewConnectionError('<urllib3.connection.HTTPConnection object at 0x7f0b14086d60>: Failed to establish a new connection: [Errno 111] Connection refused'))
[2025-05-19T08:37:32.340+0000] {MathDag.py:45} INFO - Đang crawl link 32/64: https://loigiaihay.com/de-so-11-de-thi-vao-lop-10-mon-toan-c44a49473.html
[2025-05-19T08:37:32.341+0000] {connectionpool.py:812} WARNING - Retrying (Retry(total=2, connect=None, read=None, redirect=None, status=None)) after connection broken by 'NewConnectionError('<urllib3.connection.HTTPConnection object at 0x7f0b140d0790>: Failed to establish a new connection: [Errno 111] Connection refused')': /wd/hub/session
[2025-05-19T08:37:32.341+0000] {connectionpool.py:812} WARNING - Retrying (Retry(total=1, connect=None, read=None, redirect=None, status=None)) after connection broken by 'NewConnectionError('<urllib3.connection.HTTPConnection object at 0x7f0b140d07c0>: Failed to establish a new connection: [Errno 111] Connection refused')': /wd/hub/session
[2025-05-19T08:37:32.342+0000] {connectionpool.py:812} WARNING - Retrying (Retry(total=0, connect=None, read=None, redirect=None, status=None)) after connection broken by 'NewConnectionError('<urllib3.connection.HTTPConnection object at 0x7f0b140d0a90>: Failed to establish a new connection: [Errno 111] Connection refused')': /wd/hub/session
[2025-05-19T08:37:32.342+0000] {MathDag.py:50} ERROR - Lỗi crawl link https://loigiaihay.com/de-so-11-de-thi-vao-lop-10-mon-toan-c44a49473.html: HTTPConnectionPool(host='localhost', port=4444): Max retries exceeded with url: /wd/hub/session (Caused by NewConnectionError('<urllib3.connection.HTTPConnection object at 0x7f0b140f6eb0>: Failed to establish a new connection: [Errno 111] Connection refused'))
[2025-05-19T08:37:32.342+0000] {MathDag.py:45} INFO - Đang crawl link 33/64: https://loigiaihay.com/de-so-12-de-thi-vao-lop-10-mon-toan-c44a49474.html
[2025-05-19T08:37:32.343+0000] {connectionpool.py:812} WARNING - Retrying (Retry(total=2, connect=None, read=None, redirect=None, status=None)) after connection broken by 'NewConnectionError('<urllib3.connection.HTTPConnection object at 0x7f0b140e5340>: Failed to establish a new connection: [Errno 111] Connection refused')': /wd/hub/session
[2025-05-19T08:37:32.343+0000] {connectionpool.py:812} WARNING - Retrying (Retry(total=1, connect=None, read=None, redirect=None, status=None)) after connection broken by 'NewConnectionError('<urllib3.connection.HTTPConnection object at 0x7f0b140e5460>: Failed to establish a new connection: [Errno 111] Connection refused')': /wd/hub/session
[2025-05-19T08:37:32.344+0000] {connectionpool.py:812} WARNING - Retrying (Retry(total=0, connect=None, read=None, redirect=None, status=None)) after connection broken by 'NewConnectionError('<urllib3.connection.HTTPConnection object at 0x7f0b140e5760>: Failed to establish a new connection: [Errno 111] Connection refused')': /wd/hub/session
[2025-05-19T08:37:32.344+0000] {MathDag.py:50} ERROR - Lỗi crawl link https://loigiaihay.com/de-so-12-de-thi-vao-lop-10-mon-toan-c44a49474.html: HTTPConnectionPool(host='localhost', port=4444): Max retries exceeded with url: /wd/hub/session (Caused by NewConnectionError('<urllib3.connection.HTTPConnection object at 0x7f0b140e5970>: Failed to establish a new connection: [Errno 111] Connection refused'))
[2025-05-19T08:37:32.344+0000] {MathDag.py:45} INFO - Đang crawl link 34/64: https://loigiaihay.com/de-so-13-de-thi-vao-lop-10-mon-toan-c44a49515.html
[2025-05-19T08:37:32.345+0000] {connectionpool.py:812} WARNING - Retrying (Retry(total=2, connect=None, read=None, redirect=None, status=None)) after connection broken by 'NewConnectionError('<urllib3.connection.HTTPConnection object at 0x7f0b140933a0>: Failed to establish a new connection: [Errno 111] Connection refused')': /wd/hub/session
[2025-05-19T08:37:32.346+0000] {connectionpool.py:812} WARNING - Retrying (Retry(total=1, connect=None, read=None, redirect=None, status=None)) after connection broken by 'NewConnectionError('<urllib3.connection.HTTPConnection object at 0x7f0b140934c0>: Failed to establish a new connection: [Errno 111] Connection refused')': /wd/hub/session
[2025-05-19T08:37:32.346+0000] {connectionpool.py:812} WARNING - Retrying (Retry(total=0, connect=None, read=None, redirect=None, status=None)) after connection broken by 'NewConnectionError('<urllib3.connection.HTTPConnection object at 0x7f0b14093670>: Failed to establish a new connection: [Errno 111] Connection refused')': /wd/hub/session
[2025-05-19T08:37:32.347+0000] {MathDag.py:50} ERROR - Lỗi crawl link https://loigiaihay.com/de-so-13-de-thi-vao-lop-10-mon-toan-c44a49515.html: HTTPConnectionPool(host='localhost', port=4444): Max retries exceeded with url: /wd/hub/session (Caused by NewConnectionError('<urllib3.connection.HTTPConnection object at 0x7f0b140937c0>: Failed to establish a new connection: [Errno 111] Connection refused'))
[2025-05-19T08:37:32.347+0000] {MathDag.py:45} INFO - Đang crawl link 35/64: https://loigiaihay.com/de-so-14-de-thi-vao-lop-10-mon-toan-c44a49529.html
[2025-05-19T08:37:32.348+0000] {connectionpool.py:812} WARNING - Retrying (Retry(total=2, connect=None, read=None, redirect=None, status=None)) after connection broken by 'NewConnectionError('<urllib3.connection.HTTPConnection object at 0x7f0b140e5520>: Failed to establish a new connection: [Errno 111] Connection refused')': /wd/hub/session
[2025-05-19T08:37:32.348+0000] {connectionpool.py:812} WARNING - Retrying (Retry(total=1, connect=None, read=None, redirect=None, status=None)) after connection broken by 'NewConnectionError('<urllib3.connection.HTTPConnection object at 0x7f0b140e5850>: Failed to establish a new connection: [Errno 111] Connection refused')': /wd/hub/session
[2025-05-19T08:37:32.349+0000] {connectionpool.py:812} WARNING - Retrying (Retry(total=0, connect=None, read=None, redirect=None, status=None)) after connection broken by 'NewConnectionError('<urllib3.connection.HTTPConnection object at 0x7f0b141072e0>: Failed to establish a new connection: [Errno 111] Connection refused')': /wd/hub/session
[2025-05-19T08:37:32.349+0000] {MathDag.py:50} ERROR - Lỗi crawl link https://loigiaihay.com/de-so-14-de-thi-vao-lop-10-mon-toan-c44a49529.html: HTTPConnectionPool(host='localhost', port=4444): Max retries exceeded with url: /wd/hub/session (Caused by NewConnectionError('<urllib3.connection.HTTPConnection object at 0x7f0b141075b0>: Failed to establish a new connection: [Errno 111] Connection refused'))
[2025-05-19T08:37:32.349+0000] {MathDag.py:45} INFO - Đang crawl link 36/64: https://loigiaihay.com/de-so-15-de-thi-vao-lop-10-mon-toan-c44a49531.html
[2025-05-19T08:37:32.350+0000] {connectionpool.py:812} WARNING - Retrying (Retry(total=2, connect=None, read=None, redirect=None, status=None)) after connection broken by 'NewConnectionError('<urllib3.connection.HTTPConnection object at 0x7f0b140d05b0>: Failed to establish a new connection: [Errno 111] Connection refused')': /wd/hub/session
[2025-05-19T08:37:32.350+0000] {connectionpool.py:812} WARNING - Retrying (Retry(total=1, connect=None, read=None, redirect=None, status=None)) after connection broken by 'NewConnectionError('<urllib3.connection.HTTPConnection object at 0x7f0b140d0910>: Failed to establish a new connection: [Errno 111] Connection refused')': /wd/hub/session
[2025-05-19T08:37:32.351+0000] {connectionpool.py:812} WARNING - Retrying (Retry(total=0, connect=None, read=None, redirect=None, status=None)) after connection broken by 'NewConnectionError('<urllib3.connection.HTTPConnection object at 0x7f0b140d0760>: Failed to establish a new connection: [Errno 111] Connection refused')': /wd/hub/session
[2025-05-19T08:37:32.351+0000] {MathDag.py:50} ERROR - Lỗi crawl link https://loigiaihay.com/de-so-15-de-thi-vao-lop-10-mon-toan-c44a49531.html: HTTPConnectionPool(host='localhost', port=4444): Max retries exceeded with url: /wd/hub/session (Caused by NewConnectionError('<urllib3.connection.HTTPConnection object at 0x7f0b14086e80>: Failed to establish a new connection: [Errno 111] Connection refused'))
[2025-05-19T08:37:32.351+0000] {MathDag.py:45} INFO - Đang crawl link 37/64: https://loigiaihay.com/de-so-16-de-thi-vao-lop-10-mon-toan-c44a49533.html
[2025-05-19T08:37:32.353+0000] {connectionpool.py:812} WARNING - Retrying (Retry(total=2, connect=None, read=None, redirect=None, status=None)) after connection broken by 'NewConnectionError('<urllib3.connection.HTTPConnection object at 0x7f0b14093cd0>: Failed to establish a new connection: [Errno 111] Connection refused')': /wd/hub/session
[2025-05-19T08:37:32.353+0000] {connectionpool.py:812} WARNING - Retrying (Retry(total=1, connect=None, read=None, redirect=None, status=None)) after connection broken by 'NewConnectionError('<urllib3.connection.HTTPConnection object at 0x7f0b14093df0>: Failed to establish a new connection: [Errno 111] Connection refused')': /wd/hub/session
[2025-05-19T08:37:32.354+0000] {connectionpool.py:812} WARNING - Retrying (Retry(total=0, connect=None, read=None, redirect=None, status=None)) after connection broken by 'NewConnectionError('<urllib3.connection.HTTPConnection object at 0x7f0b14093fa0>: Failed to establish a new connection: [Errno 111] Connection refused')': /wd/hub/session
[2025-05-19T08:37:32.354+0000] {MathDag.py:50} ERROR - Lỗi crawl link https://loigiaihay.com/de-so-16-de-thi-vao-lop-10-mon-toan-c44a49533.html: HTTPConnectionPool(host='localhost', port=4444): Max retries exceeded with url: /wd/hub/session (Caused by NewConnectionError('<urllib3.connection.HTTPConnection object at 0x7f0b140a5160>: Failed to establish a new connection: [Errno 111] Connection refused'))
[2025-05-19T08:37:32.355+0000] {MathDag.py:45} INFO - Đang crawl link 38/64: https://loigiaihay.com/de-so-17-de-thi-vao-lop-10-mon-toan-c44a49536.html
[2025-05-19T08:37:32.355+0000] {connectionpool.py:812} WARNING - Retrying (Retry(total=2, connect=None, read=None, redirect=None, status=None)) after connection broken by 'NewConnectionError('<urllib3.connection.HTTPConnection object at 0x7f0b140d0a00>: Failed to establish a new connection: [Errno 111] Connection refused')': /wd/hub/session
[2025-05-19T08:37:32.356+0000] {connectionpool.py:812} WARNING - Retrying (Retry(total=1, connect=None, read=None, redirect=None, status=None)) after connection broken by 'NewConnectionError('<urllib3.connection.HTTPConnection object at 0x7f0b140d0790>: Failed to establish a new connection: [Errno 111] Connection refused')': /wd/hub/session
[2025-05-19T08:37:32.356+0000] {connectionpool.py:812} WARNING - Retrying (Retry(total=0, connect=None, read=None, redirect=None, status=None)) after connection broken by 'NewConnectionError('<urllib3.connection.HTTPConnection object at 0x7f0b140d0f70>: Failed to establish a new connection: [Errno 111] Connection refused')': /wd/hub/session
[2025-05-19T08:37:32.357+0000] {MathDag.py:50} ERROR - Lỗi crawl link https://loigiaihay.com/de-so-17-de-thi-vao-lop-10-mon-toan-c44a49536.html: HTTPConnectionPool(host='localhost', port=4444): Max retries exceeded with url: /wd/hub/session (Caused by NewConnectionError('<urllib3.connection.HTTPConnection object at 0x7f0b140f6fa0>: Failed to establish a new connection: [Errno 111] Connection refused'))
[2025-05-19T08:37:32.357+0000] {MathDag.py:45} INFO - Đang crawl link 39/64: https://loigiaihay.com/de-so-18-de-thi-vao-lop-10-mon-toan-c44a49538.html
[2025-05-19T08:37:32.358+0000] {connectionpool.py:812} WARNING - Retrying (Retry(total=2, connect=None, read=None, redirect=None, status=None)) after connection broken by 'NewConnectionError('<urllib3.connection.HTTPConnection object at 0x7f0b140e5520>: Failed to establish a new connection: [Errno 111] Connection refused')': /wd/hub/session
[2025-05-19T08:37:32.358+0000] {connectionpool.py:812} WARNING - Retrying (Retry(total=1, connect=None, read=None, redirect=None, status=None)) after connection broken by 'NewConnectionError('<urllib3.connection.HTTPConnection object at 0x7f0b140e58b0>: Failed to establish a new connection: [Errno 111] Connection refused')': /wd/hub/session
[2025-05-19T08:37:32.359+0000] {connectionpool.py:812} WARNING - Retrying (Retry(total=0, connect=None, read=None, redirect=None, status=None)) after connection broken by 'NewConnectionError('<urllib3.connection.HTTPConnection object at 0x7f0b140e5790>: Failed to establish a new connection: [Errno 111] Connection refused')': /wd/hub/session
[2025-05-19T08:37:32.359+0000] {MathDag.py:50} ERROR - Lỗi crawl link https://loigiaihay.com/de-so-18-de-thi-vao-lop-10-mon-toan-c44a49538.html: HTTPConnectionPool(host='localhost', port=4444): Max retries exceeded with url: /wd/hub/session (Caused by NewConnectionError('<urllib3.connection.HTTPConnection object at 0x7f0b1417c910>: Failed to establish a new connection: [Errno 111] Connection refused'))
[2025-05-19T08:37:32.359+0000] {MathDag.py:45} INFO - Đang crawl link 40/64: https://loigiaihay.com/de-so-19-de-thi-vao-lop-10-mon-toan-c44a49540.html
[2025-05-19T08:37:32.360+0000] {connectionpool.py:812} WARNING - Retrying (Retry(total=2, connect=None, read=None, redirect=None, status=None)) after connection broken by 'NewConnectionError('<urllib3.connection.HTTPConnection object at 0x7f0b140a5760>: Failed to establish a new connection: [Errno 111] Connection refused')': /wd/hub/session
[2025-05-19T08:37:32.361+0000] {connectionpool.py:812} WARNING - Retrying (Retry(total=1, connect=None, read=None, redirect=None, status=None)) after connection broken by 'NewConnectionError('<urllib3.connection.HTTPConnection object at 0x7f0b140a5880>: Failed to establish a new connection: [Errno 111] Connection refused')': /wd/hub/session
[2025-05-19T08:37:32.361+0000] {connectionpool.py:812} WARNING - Retrying (Retry(total=0, connect=None, read=None, redirect=None, status=None)) after connection broken by 'NewConnectionError('<urllib3.connection.HTTPConnection object at 0x7f0b140a5a30>: Failed to establish a new connection: [Errno 111] Connection refused')': /wd/hub/session
[2025-05-19T08:37:32.362+0000] {MathDag.py:50} ERROR - Lỗi crawl link https://loigiaihay.com/de-so-19-de-thi-vao-lop-10-mon-toan-c44a49540.html: HTTPConnectionPool(host='localhost', port=4444): Max retries exceeded with url: /wd/hub/session (Caused by NewConnectionError('<urllib3.connection.HTTPConnection object at 0x7f0b140a5b80>: Failed to establish a new connection: [Errno 111] Connection refused'))
[2025-05-19T08:37:32.362+0000] {MathDag.py:45} INFO - Đang crawl link 41/64: https://loigiaihay.com/de-so-20-de-thi-vao-lop-10-mon-toan-c44a49541.html
[2025-05-19T08:37:32.363+0000] {connectionpool.py:812} WARNING - Retrying (Retry(total=2, connect=None, read=None, redirect=None, status=None)) after connection broken by 'NewConnectionError('<urllib3.connection.HTTPConnection object at 0x7f0b140e54f0>: Failed to establish a new connection: [Errno 111] Connection refused')': /wd/hub/session
[2025-05-19T08:37:32.363+0000] {connectionpool.py:812} WARNING - Retrying (Retry(total=1, connect=None, read=None, redirect=None, status=None)) after connection broken by 'NewConnectionError('<urllib3.connection.HTTPConnection object at 0x7f0b14107220>: Failed to establish a new connection: [Errno 111] Connection refused')': /wd/hub/session
[2025-05-19T08:37:32.363+0000] {connectionpool.py:812} WARNING - Retrying (Retry(total=0, connect=None, read=None, redirect=None, status=None)) after connection broken by 'NewConnectionError('<urllib3.connection.HTTPConnection object at 0x7f0b14107610>: Failed to establish a new connection: [Errno 111] Connection refused')': /wd/hub/session
[2025-05-19T08:37:32.364+0000] {MathDag.py:50} ERROR - Lỗi crawl link https://loigiaihay.com/de-so-20-de-thi-vao-lop-10-mon-toan-c44a49541.html: HTTPConnectionPool(host='localhost', port=4444): Max retries exceeded with url: /wd/hub/session (Caused by NewConnectionError('<urllib3.connection.HTTPConnection object at 0x7f0b1f9a3c10>: Failed to establish a new connection: [Errno 111] Connection refused'))
[2025-05-19T08:37:32.364+0000] {MathDag.py:45} INFO - Đang crawl link 42/64: https://loigiaihay.com/de-so-21-de-thi-vao-lop-10-mon-toan-c44a49573.html
[2025-05-19T08:37:32.365+0000] {connectionpool.py:812} WARNING - Retrying (Retry(total=2, connect=None, read=None, redirect=None, status=None)) after connection broken by 'NewConnectionError('<urllib3.connection.HTTPConnection object at 0x7f0b140d0910>: Failed to establish a new connection: [Errno 111] Connection refused')': /wd/hub/session
[2025-05-19T08:37:32.365+0000] {connectionpool.py:812} WARNING - Retrying (Retry(total=1, connect=None, read=None, redirect=None, status=None)) after connection broken by 'NewConnectionError('<urllib3.connection.HTTPConnection object at 0x7f0b140d0fa0>: Failed to establish a new connection: [Errno 111] Connection refused')': /wd/hub/session
[2025-05-19T08:37:32.366+0000] {connectionpool.py:812} WARNING - Retrying (Retry(total=0, connect=None, read=None, redirect=None, status=None)) after connection broken by 'NewConnectionError('<urllib3.connection.HTTPConnection object at 0x7f0b140860d0>: Failed to establish a new connection: [Errno 111] Connection refused')': /wd/hub/session
[2025-05-19T08:37:32.366+0000] {MathDag.py:50} ERROR - Lỗi crawl link https://loigiaihay.com/de-so-21-de-thi-vao-lop-10-mon-toan-c44a49573.html: HTTPConnectionPool(host='localhost', port=4444): Max retries exceeded with url: /wd/hub/session (Caused by NewConnectionError('<urllib3.connection.HTTPConnection object at 0x7f0b140a5c70>: Failed to establish a new connection: [Errno 111] Connection refused'))
[2025-05-19T08:37:32.367+0000] {MathDag.py:45} INFO - Đang crawl link 43/64: https://loigiaihay.com/de-so-22-de-thi-vao-lop-10-mon-toan-c44a49582.html
[2025-05-19T08:37:32.368+0000] {connectionpool.py:812} WARNING - Retrying (Retry(total=2, connect=None, read=None, redirect=None, status=None)) after connection broken by 'NewConnectionError('<urllib3.connection.HTTPConnection object at 0x7f0b140b71c0>: Failed to establish a new connection: [Errno 111] Connection refused')': /wd/hub/session
[2025-05-19T08:37:32.368+0000] {connectionpool.py:812} WARNING - Retrying (Retry(total=1, connect=None, read=None, redirect=None, status=None)) after connection broken by 'NewConnectionError('<urllib3.connection.HTTPConnection object at 0x7f0b140b72e0>: Failed to establish a new connection: [Errno 111] Connection refused')': /wd/hub/session
[2025-05-19T08:37:32.369+0000] {connectionpool.py:812} WARNING - Retrying (Retry(total=0, connect=None, read=None, redirect=None, status=None)) after connection broken by 'NewConnectionError('<urllib3.connection.HTTPConnection object at 0x7f0b140b7490>: Failed to establish a new connection: [Errno 111] Connection refused')': /wd/hub/session
[2025-05-19T08:37:32.369+0000] {MathDag.py:50} ERROR - Lỗi crawl link https://loigiaihay.com/de-so-22-de-thi-vao-lop-10-mon-toan-c44a49582.html: HTTPConnectionPool(host='localhost', port=4444): Max retries exceeded with url: /wd/hub/session (Caused by NewConnectionError('<urllib3.connection.HTTPConnection object at 0x7f0b140b75e0>: Failed to establish a new connection: [Errno 111] Connection refused'))
[2025-05-19T08:37:32.369+0000] {MathDag.py:45} INFO - Đang crawl link 44/64: https://loigiaihay.com/de-so-23-de-thi-vao-lop-10-mon-toan-c44a49583.html
[2025-05-19T08:37:32.370+0000] {connectionpool.py:812} WARNING - Retrying (Retry(total=2, connect=None, read=None, redirect=None, status=None)) after connection broken by 'NewConnectionError('<urllib3.connection.HTTPConnection object at 0x7f0b140d0a60>: Failed to establish a new connection: [Errno 111] Connection refused')': /wd/hub/session
[2025-05-19T08:37:32.370+0000] {connectionpool.py:812} WARNING - Retrying (Retry(total=1, connect=None, read=None, redirect=None, status=None)) after connection broken by 'NewConnectionError('<urllib3.connection.HTTPConnection object at 0x7f0b140d07c0>: Failed to establish a new connection: [Errno 111] Connection refused')': /wd/hub/session
[2025-05-19T08:37:32.371+0000] {connectionpool.py:812} WARNING - Retrying (Retry(total=0, connect=None, read=None, redirect=None, status=None)) after connection broken by 'NewConnectionError('<urllib3.connection.HTTPConnection object at 0x7f0b141a2e80>: Failed to establish a new connection: [Errno 111] Connection refused')': /wd/hub/session
[2025-05-19T08:37:32.371+0000] {MathDag.py:50} ERROR - Lỗi crawl link https://loigiaihay.com/de-so-23-de-thi-vao-lop-10-mon-toan-c44a49583.html: HTTPConnectionPool(host='localhost', port=4444): Max retries exceeded with url: /wd/hub/session (Caused by NewConnectionError('<urllib3.connection.HTTPConnection object at 0x7f0b140f6fa0>: Failed to establish a new connection: [Errno 111] Connection refused'))
[2025-05-19T08:37:32.371+0000] {MathDag.py:45} INFO - Đang crawl link 45/64: https://loigiaihay.com/de-so-24-de-thi-vao-lop-10-mon-toan-c44a49585.html
[2025-05-19T08:37:32.372+0000] {connectionpool.py:812} WARNING - Retrying (Retry(total=2, connect=None, read=None, redirect=None, status=None)) after connection broken by 'NewConnectionError('<urllib3.connection.HTTPConnection object at 0x7f0b140e50d0>: Failed to establish a new connection: [Errno 111] Connection refused')': /wd/hub/session
[2025-05-19T08:37:32.373+0000] {connectionpool.py:812} WARNING - Retrying (Retry(total=1, connect=None, read=None, redirect=None, status=None)) after connection broken by 'NewConnectionError('<urllib3.connection.HTTPConnection object at 0x7f0b140e52e0>: Failed to establish a new connection: [Errno 111] Connection refused')': /wd/hub/session
[2025-05-19T08:37:32.374+0000] {connectionpool.py:812} WARNING - Retrying (Retry(total=0, connect=None, read=None, redirect=None, status=None)) after connection broken by 'NewConnectionError('<urllib3.connection.HTTPConnection object at 0x7f0b1417c2b0>: Failed to establish a new connection: [Errno 111] Connection refused')': /wd/hub/session
[2025-05-19T08:37:32.374+0000] {MathDag.py:50} ERROR - Lỗi crawl link https://loigiaihay.com/de-so-24-de-thi-vao-lop-10-mon-toan-c44a49585.html: HTTPConnectionPool(host='localhost', port=4444): Max retries exceeded with url: /wd/hub/session (Caused by NewConnectionError('<urllib3.connection.HTTPConnection object at 0x7f0b140a5220>: Failed to establish a new connection: [Errno 111] Connection refused'))
[2025-05-19T08:37:32.374+0000] {MathDag.py:45} INFO - Đang crawl link 46/64: https://loigiaihay.com/de-so-25-de-thi-vao-lop-10-mon-toan-c44a49613.html
[2025-05-19T08:37:32.375+0000] {connectionpool.py:812} WARNING - Retrying (Retry(total=2, connect=None, read=None, redirect=None, status=None)) after connection broken by 'NewConnectionError('<urllib3.connection.HTTPConnection object at 0x7f0b140b7be0>: Failed to establish a new connection: [Errno 111] Connection refused')': /wd/hub/session
[2025-05-19T08:37:32.375+0000] {connectionpool.py:812} WARNING - Retrying (Retry(total=1, connect=None, read=None, redirect=None, status=None)) after connection broken by 'NewConnectionError('<urllib3.connection.HTTPConnection object at 0x7f0b140b7d00>: Failed to establish a new connection: [Errno 111] Connection refused')': /wd/hub/session
[2025-05-19T08:37:32.376+0000] {connectionpool.py:812} WARNING - Retrying (Retry(total=0, connect=None, read=None, redirect=None, status=None)) after connection broken by 'NewConnectionError('<urllib3.connection.HTTPConnection object at 0x7f0b140b7eb0>: Failed to establish a new connection: [Errno 111] Connection refused')': /wd/hub/session
[2025-05-19T08:37:32.377+0000] {MathDag.py:50} ERROR - Lỗi crawl link https://loigiaihay.com/de-so-25-de-thi-vao-lop-10-mon-toan-c44a49613.html: HTTPConnectionPool(host='localhost', port=4444): Max retries exceeded with url: /wd/hub/session (Caused by NewConnectionError('<urllib3.connection.HTTPConnection object at 0x7f0b1404f040>: Failed to establish a new connection: [Errno 111] Connection refused'))
[2025-05-19T08:37:32.377+0000] {MathDag.py:45} INFO - Đang crawl link 47/64: https://loigiaihay.com/de-so-26-de-thi-vao-lop-10-mon-toan-c44a49614.html
[2025-05-19T08:37:32.378+0000] {connectionpool.py:812} WARNING - Retrying (Retry(total=2, connect=None, read=None, redirect=None, status=None)) after connection broken by 'NewConnectionError('<urllib3.connection.HTTPConnection object at 0x7f0b140a5d30>: Failed to establish a new connection: [Errno 111] Connection refused')': /wd/hub/session
[2025-05-19T08:37:32.378+0000] {connectionpool.py:812} WARNING - Retrying (Retry(total=1, connect=None, read=None, redirect=None, status=None)) after connection broken by 'NewConnectionError('<urllib3.connection.HTTPConnection object at 0x7f0b140a5820>: Failed to establish a new connection: [Errno 111] Connection refused')': /wd/hub/session
[2025-05-19T08:37:32.379+0000] {connectionpool.py:812} WARNING - Retrying (Retry(total=0, connect=None, read=None, redirect=None, status=None)) after connection broken by 'NewConnectionError('<urllib3.connection.HTTPConnection object at 0x7f0b140a5a90>: Failed to establish a new connection: [Errno 111] Connection refused')': /wd/hub/session
[2025-05-19T08:37:32.379+0000] {MathDag.py:50} ERROR - Lỗi crawl link https://loigiaihay.com/de-so-26-de-thi-vao-lop-10-mon-toan-c44a49614.html: HTTPConnectionPool(host='localhost', port=4444): Max retries exceeded with url: /wd/hub/session (Caused by NewConnectionError('<urllib3.connection.HTTPConnection object at 0x7f0b140a57f0>: Failed to establish a new connection: [Errno 111] Connection refused'))
[2025-05-19T08:37:32.379+0000] {MathDag.py:45} INFO - Đang crawl link 48/64: https://loigiaihay.com/de-so-27-de-thi-vao-lop-10-mon-toan-c44a49615.html
[2025-05-19T08:37:32.380+0000] {connectionpool.py:812} WARNING - Retrying (Retry(total=2, connect=None, read=None, redirect=None, status=None)) after connection broken by 'NewConnectionError('<urllib3.connection.HTTPConnection object at 0x7f0b140a5040>: Failed to establish a new connection: [Errno 111] Connection refused')': /wd/hub/session
[2025-05-19T08:37:32.381+0000] {connectionpool.py:812} WARNING - Retrying (Retry(total=1, connect=None, read=None, redirect=None, status=None)) after connection broken by 'NewConnectionError('<urllib3.connection.HTTPConnection object at 0x7f0b1414a130>: Failed to establish a new connection: [Errno 111] Connection refused')': /wd/hub/session
[2025-05-19T08:37:32.381+0000] {connectionpool.py:812} WARNING - Retrying (Retry(total=0, connect=None, read=None, redirect=None, status=None)) after connection broken by 'NewConnectionError('<urllib3.connection.HTTPConnection object at 0x7f0b14107e80>: Failed to establish a new connection: [Errno 111] Connection refused')': /wd/hub/session
[2025-05-19T08:37:32.382+0000] {MathDag.py:50} ERROR - Lỗi crawl link https://loigiaihay.com/de-so-27-de-thi-vao-lop-10-mon-toan-c44a49615.html: HTTPConnectionPool(host='localhost', port=4444): Max retries exceeded with url: /wd/hub/session (Caused by NewConnectionError('<urllib3.connection.HTTPConnection object at 0x7f0b14093a60>: Failed to establish a new connection: [Errno 111] Connection refused'))
[2025-05-19T08:37:32.382+0000] {MathDag.py:45} INFO - Đang crawl link 49/64: https://loigiaihay.com/de-so-28-de-thi-vao-lop-10-mon-toan-c44a49616.html
[2025-05-19T08:37:32.383+0000] {connectionpool.py:812} WARNING - Retrying (Retry(total=2, connect=None, read=None, redirect=None, status=None)) after connection broken by 'NewConnectionError('<urllib3.connection.HTTPConnection object at 0x7f0b14093fd0>: Failed to establish a new connection: [Errno 111] Connection refused')': /wd/hub/session
[2025-05-19T08:37:32.383+0000] {connectionpool.py:812} WARNING - Retrying (Retry(total=1, connect=None, read=None, redirect=None, status=None)) after connection broken by 'NewConnectionError('<urllib3.connection.HTTPConnection object at 0x7f0b14093c70>: Failed to establish a new connection: [Errno 111] Connection refused')': /wd/hub/session
[2025-05-19T08:37:32.384+0000] {connectionpool.py:812} WARNING - Retrying (Retry(total=0, connect=None, read=None, redirect=None, status=None)) after connection broken by 'NewConnectionError('<urllib3.connection.HTTPConnection object at 0x7f0b14093160>: Failed to establish a new connection: [Errno 111] Connection refused')': /wd/hub/session
[2025-05-19T08:37:32.384+0000] {MathDag.py:50} ERROR - Lỗi crawl link https://loigiaihay.com/de-so-28-de-thi-vao-lop-10-mon-toan-c44a49616.html: HTTPConnectionPool(host='localhost', port=4444): Max retries exceeded with url: /wd/hub/session (Caused by NewConnectionError('<urllib3.connection.HTTPConnection object at 0x7f0b14093520>: Failed to establish a new connection: [Errno 111] Connection refused'))
[2025-05-19T08:37:32.384+0000] {MathDag.py:45} INFO - Đang crawl link 50/64: https://loigiaihay.com/de-so-29-de-thi-vao-lop-10-mon-toan-c44a49621.html
[2025-05-19T08:37:32.385+0000] {connectionpool.py:812} WARNING - Retrying (Retry(total=2, connect=None, read=None, redirect=None, status=None)) after connection broken by 'NewConnectionError('<urllib3.connection.HTTPConnection object at 0x7f0b14086dc0>: Failed to establish a new connection: [Errno 111] Connection refused')': /wd/hub/session
[2025-05-19T08:37:32.385+0000] {connectionpool.py:812} WARNING - Retrying (Retry(total=1, connect=None, read=None, redirect=None, status=None)) after connection broken by 'NewConnectionError('<urllib3.connection.HTTPConnection object at 0x7f0b14093df0>: Failed to establish a new connection: [Errno 111] Connection refused')': /wd/hub/session
[2025-05-19T08:37:32.386+0000] {connectionpool.py:812} WARNING - Retrying (Retry(total=0, connect=None, read=None, redirect=None, status=None)) after connection broken by 'NewConnectionError('<urllib3.connection.HTTPConnection object at 0x7f0b14093580>: Failed to establish a new connection: [Errno 111] Connection refused')': /wd/hub/session
[2025-05-19T08:37:32.387+0000] {MathDag.py:50} ERROR - Lỗi crawl link https://loigiaihay.com/de-so-29-de-thi-vao-lop-10-mon-toan-c44a49621.html: HTTPConnectionPool(host='localhost', port=4444): Max retries exceeded with url: /wd/hub/session (Caused by NewConnectionError('<urllib3.connection.HTTPConnection object at 0x7f0b14093550>: Failed to establish a new connection: [Errno 111] Connection refused'))
[2025-05-19T08:37:32.387+0000] {MathDag.py:45} INFO - Đang crawl link 51/64: https://loigiaihay.com/de-so-30-de-thi-vao-lop-10-mon-toan-c44a49629.html
[2025-05-19T08:37:32.388+0000] {connectionpool.py:812} WARNING - Retrying (Retry(total=2, connect=None, read=None, redirect=None, status=None)) after connection broken by 'NewConnectionError('<urllib3.connection.HTTPConnection object at 0x7f0b14093d00>: Failed to establish a new connection: [Errno 111] Connection refused')': /wd/hub/session
[2025-05-19T08:37:32.388+0000] {connectionpool.py:812} WARNING - Retrying (Retry(total=1, connect=None, read=None, redirect=None, status=None)) after connection broken by 'NewConnectionError('<urllib3.connection.HTTPConnection object at 0x7f0b14107160>: Failed to establish a new connection: [Errno 111] Connection refused')': /wd/hub/session
[2025-05-19T08:37:32.389+0000] {connectionpool.py:812} WARNING - Retrying (Retry(total=0, connect=None, read=None, redirect=None, status=None)) after connection broken by 'NewConnectionError('<urllib3.connection.HTTPConnection object at 0x7f0b141072b0>: Failed to establish a new connection: [Errno 111] Connection refused')': /wd/hub/session
[2025-05-19T08:37:32.389+0000] {MathDag.py:50} ERROR - Lỗi crawl link https://loigiaihay.com/de-so-30-de-thi-vao-lop-10-mon-toan-c44a49629.html: HTTPConnectionPool(host='localhost', port=4444): Max retries exceeded with url: /wd/hub/session (Caused by NewConnectionError('<urllib3.connection.HTTPConnection object at 0x7f0b140a5670>: Failed to establish a new connection: [Errno 111] Connection refused'))
[2025-05-19T08:37:32.389+0000] {MathDag.py:45} INFO - Đang crawl link 52/64: https://loigiaihay.com/de-so-31-de-thi-vao-lop-10-mon-toan-c44a49640.html
[2025-05-19T08:37:32.390+0000] {connectionpool.py:812} WARNING - Retrying (Retry(total=2, connect=None, read=None, redirect=None, status=None)) after connection broken by 'NewConnectionError('<urllib3.connection.HTTPConnection object at 0x7f0b140a5b20>: Failed to establish a new connection: [Errno 111] Connection refused')': /wd/hub/session
[2025-05-19T08:37:32.391+0000] {connectionpool.py:812} WARNING - Retrying (Retry(total=1, connect=None, read=None, redirect=None, status=None)) after connection broken by 'NewConnectionError('<urllib3.connection.HTTPConnection object at 0x7f0b140a5f10>: Failed to establish a new connection: [Errno 111] Connection refused')': /wd/hub/session
[2025-05-19T08:37:32.391+0000] {connectionpool.py:812} WARNING - Retrying (Retry(total=0, connect=None, read=None, redirect=None, status=None)) after connection broken by 'NewConnectionError('<urllib3.connection.HTTPConnection object at 0x7f0b140a5970>: Failed to establish a new connection: [Errno 111] Connection refused')': /wd/hub/session
[2025-05-19T08:37:32.392+0000] {MathDag.py:50} ERROR - Lỗi crawl link https://loigiaihay.com/de-so-31-de-thi-vao-lop-10-mon-toan-c44a49640.html: HTTPConnectionPool(host='localhost', port=4444): Max retries exceeded with url: /wd/hub/session (Caused by NewConnectionError('<urllib3.connection.HTTPConnection object at 0x7f0b140a5a30>: Failed to establish a new connection: [Errno 111] Connection refused'))
[2025-05-19T08:37:32.392+0000] {MathDag.py:45} INFO - Đang crawl link 53/64: https://loigiaihay.com/de-so-32-de-thi-vao-lop-10-mon-toan-c44a49639.html
[2025-05-19T08:37:32.392+0000] {connectionpool.py:812} WARNING - Retrying (Retry(total=2, connect=None, read=None, redirect=None, status=None)) after connection broken by 'NewConnectionError('<urllib3.connection.HTTPConnection object at 0x7f0b14086520>: Failed to establish a new connection: [Errno 111] Connection refused')': /wd/hub/session
[2025-05-19T08:37:32.393+0000] {connectionpool.py:812} WARNING - Retrying (Retry(total=1, connect=None, read=None, redirect=None, status=None)) after connection broken by 'NewConnectionError('<urllib3.connection.HTTPConnection object at 0x7f0b14086610>: Failed to establish a new connection: [Errno 111] Connection refused')': /wd/hub/session
[2025-05-19T08:37:32.393+0000] {connectionpool.py:812} WARNING - Retrying (Retry(total=0, connect=None, read=None, redirect=None, status=None)) after connection broken by 'NewConnectionError('<urllib3.connection.HTTPConnection object at 0x7f0b14086fa0>: Failed to establish a new connection: [Errno 111] Connection refused')': /wd/hub/session
[2025-05-19T08:37:32.395+0000] {MathDag.py:50} ERROR - Lỗi crawl link https://loigiaihay.com/de-so-32-de-thi-vao-lop-10-mon-toan-c44a49639.html: HTTPConnectionPool(host='localhost', port=4444): Max retries exceeded with url: /wd/hub/session (Caused by NewConnectionError('<urllib3.connection.HTTPConnection object at 0x7f0b1417c910>: Failed to establish a new connection: [Errno 111] Connection refused'))
[2025-05-19T08:37:32.395+0000] {MathDag.py:45} INFO - Đang crawl link 54/64: https://loigiaihay.com/de-so-33-de-thi-vao-lop-10-mon-toan-c44a49641.html
[2025-05-19T08:37:32.396+0000] {connectionpool.py:812} WARNING - Retrying (Retry(total=2, connect=None, read=None, redirect=None, status=None)) after connection broken by 'NewConnectionError('<urllib3.connection.HTTPConnection object at 0x7f0b140a5c70>: Failed to establish a new connection: [Errno 111] Connection refused')': /wd/hub/session
[2025-05-19T08:37:32.396+0000] {connectionpool.py:812} WARNING - Retrying (Retry(total=1, connect=None, read=None, redirect=None, status=None)) after connection broken by 'NewConnectionError('<urllib3.connection.HTTPConnection object at 0x7f0b140a56a0>: Failed to establish a new connection: [Errno 111] Connection refused')': /wd/hub/session
[2025-05-19T08:37:32.397+0000] {connectionpool.py:812} WARNING - Retrying (Retry(total=0, connect=None, read=None, redirect=None, status=None)) after connection broken by 'NewConnectionError('<urllib3.connection.HTTPConnection object at 0x7f0b140a5700>: Failed to establish a new connection: [Errno 111] Connection refused')': /wd/hub/session
[2025-05-19T08:37:32.397+0000] {MathDag.py:50} ERROR - Lỗi crawl link https://loigiaihay.com/de-so-33-de-thi-vao-lop-10-mon-toan-c44a49641.html: HTTPConnectionPool(host='localhost', port=4444): Max retries exceeded with url: /wd/hub/session (Caused by NewConnectionError('<urllib3.connection.HTTPConnection object at 0x7f0b140a5520>: Failed to establish a new connection: [Errno 111] Connection refused'))
[2025-05-19T08:37:32.397+0000] {MathDag.py:45} INFO - Đang crawl link 55/64: https://loigiaihay.com/de-so-34-de-thi-vao-lop-10-mon-toan-c44a49643.html
[2025-05-19T08:37:32.398+0000] {connectionpool.py:812} WARNING - Retrying (Retry(total=2, connect=None, read=None, redirect=None, status=None)) after connection broken by 'NewConnectionError('<urllib3.connection.HTTPConnection object at 0x7f0b14093af0>: Failed to establish a new connection: [Errno 111] Connection refused')': /wd/hub/session
[2025-05-19T08:37:32.398+0000] {connectionpool.py:812} WARNING - Retrying (Retry(total=1, connect=None, read=None, redirect=None, status=None)) after connection broken by 'NewConnectionError('<urllib3.connection.HTTPConnection object at 0x7f0b14093910>: Failed to establish a new connection: [Errno 111] Connection refused')': /wd/hub/session
[2025-05-19T08:37:32.399+0000] {connectionpool.py:812} WARNING - Retrying (Retry(total=0, connect=None, read=None, redirect=None, status=None)) after connection broken by 'NewConnectionError('<urllib3.connection.HTTPConnection object at 0x7f0b14093ca0>: Failed to establish a new connection: [Errno 111] Connection refused')': /wd/hub/session
[2025-05-19T08:37:32.399+0000] {MathDag.py:50} ERROR - Lỗi crawl link https://loigiaihay.com/de-so-34-de-thi-vao-lop-10-mon-toan-c44a49643.html: HTTPConnectionPool(host='localhost', port=4444): Max retries exceeded with url: /wd/hub/session (Caused by NewConnectionError('<urllib3.connection.HTTPConnection object at 0x7f0b140936a0>: Failed to establish a new connection: [Errno 111] Connection refused'))
[2025-05-19T08:37:32.399+0000] {MathDag.py:45} INFO - Đang crawl link 56/64: https://loigiaihay.com/de-so-35-de-thi-vao-lop-10-mon-toan-c44a49644.html
[2025-05-19T08:37:32.400+0000] {connectionpool.py:812} WARNING - Retrying (Retry(total=2, connect=None, read=None, redirect=None, status=None)) after connection broken by 'NewConnectionError('<urllib3.connection.HTTPConnection object at 0x7f0b140865e0>: Failed to establish a new connection: [Errno 111] Connection refused')': /wd/hub/session
[2025-05-19T08:37:32.401+0000] {connectionpool.py:812} WARNING - Retrying (Retry(total=1, connect=None, read=None, redirect=None, status=None)) after connection broken by 'NewConnectionError('<urllib3.connection.HTTPConnection object at 0x7f0b14086430>: Failed to establish a new connection: [Errno 111] Connection refused')': /wd/hub/session
[2025-05-19T08:37:32.401+0000] {connectionpool.py:812} WARNING - Retrying (Retry(total=0, connect=None, read=None, redirect=None, status=None)) after connection broken by 'NewConnectionError('<urllib3.connection.HTTPConnection object at 0x7f0b140862b0>: Failed to establish a new connection: [Errno 111] Connection refused')': /wd/hub/session
[2025-05-19T08:37:32.402+0000] {MathDag.py:50} ERROR - Lỗi crawl link https://loigiaihay.com/de-so-35-de-thi-vao-lop-10-mon-toan-c44a49644.html: HTTPConnectionPool(host='localhost', port=4444): Max retries exceeded with url: /wd/hub/session (Caused by NewConnectionError('<urllib3.connection.HTTPConnection object at 0x7f0b14086cd0>: Failed to establish a new connection: [Errno 111] Connection refused'))
[2025-05-19T08:37:32.402+0000] {MathDag.py:45} INFO - Đang crawl link 57/64: https://loigiaihay.com/de-so-36-de-thi-vao-lop-10-mon-toan-c44a49645.html
[2025-05-19T08:37:32.403+0000] {connectionpool.py:812} WARNING - Retrying (Retry(total=2, connect=None, read=None, redirect=None, status=None)) after connection broken by 'NewConnectionError('<urllib3.connection.HTTPConnection object at 0x7f0b140934c0>: Failed to establish a new connection: [Errno 111] Connection refused')': /wd/hub/session
[2025-05-19T08:37:32.404+0000] {connectionpool.py:812} WARNING - Retrying (Retry(total=1, connect=None, read=None, redirect=None, status=None)) after connection broken by 'NewConnectionError('<urllib3.connection.HTTPConnection object at 0x7f0b14093d60>: Failed to establish a new connection: [Errno 111] Connection refused')': /wd/hub/session
[2025-05-19T08:37:32.404+0000] {connectionpool.py:812} WARNING - Retrying (Retry(total=0, connect=None, read=None, redirect=None, status=None)) after connection broken by 'NewConnectionError('<urllib3.connection.HTTPConnection object at 0x7f0b14093130>: Failed to establish a new connection: [Errno 111] Connection refused')': /wd/hub/session
[2025-05-19T08:37:32.404+0000] {MathDag.py:50} ERROR - Lỗi crawl link https://loigiaihay.com/de-so-36-de-thi-vao-lop-10-mon-toan-c44a49645.html: HTTPConnectionPool(host='localhost', port=4444): Max retries exceeded with url: /wd/hub/session (Caused by NewConnectionError('<urllib3.connection.HTTPConnection object at 0x7f0b14093fd0>: Failed to establish a new connection: [Errno 111] Connection refused'))
[2025-05-19T08:37:32.405+0000] {MathDag.py:45} INFO - Đang crawl link 58/64: https://loigiaihay.com/de-so-37-de-thi-vao-lop-10-mon-toan-c44a49646.html
[2025-05-19T08:37:32.405+0000] {connectionpool.py:812} WARNING - Retrying (Retry(total=2, connect=None, read=None, redirect=None, status=None)) after connection broken by 'NewConnectionError('<urllib3.connection.HTTPConnection object at 0x7f0b140a5a30>: Failed to establish a new connection: [Errno 111] Connection refused')': /wd/hub/session
[2025-05-19T08:37:32.406+0000] {connectionpool.py:812} WARNING - Retrying (Retry(total=1, connect=None, read=None, redirect=None, status=None)) after connection broken by 'NewConnectionError('<urllib3.connection.HTTPConnection object at 0x7f0b140a5bb0>: Failed to establish a new connection: [Errno 111] Connection refused')': /wd/hub/session
[2025-05-19T08:37:32.406+0000] {connectionpool.py:812} WARNING - Retrying (Retry(total=0, connect=None, read=None, redirect=None, status=None)) after connection broken by 'NewConnectionError('<urllib3.connection.HTTPConnection object at 0x7f0b140a51f0>: Failed to establish a new connection: [Errno 111] Connection refused')': /wd/hub/session
[2025-05-19T08:37:32.407+0000] {MathDag.py:50} ERROR - Lỗi crawl link https://loigiaihay.com/de-so-37-de-thi-vao-lop-10-mon-toan-c44a49646.html: HTTPConnectionPool(host='localhost', port=4444): Max retries exceeded with url: /wd/hub/session (Caused by NewConnectionError('<urllib3.connection.HTTPConnection object at 0x7f0b140a5070>: Failed to establish a new connection: [Errno 111] Connection refused'))
[2025-05-19T08:37:32.407+0000] {MathDag.py:45} INFO - Đang crawl link 59/64: https://loigiaihay.com/de-so-38-de-thi-vao-lop-10-mon-toan-c44a49647.html
[2025-05-19T08:37:32.408+0000] {connectionpool.py:812} WARNING - Retrying (Retry(total=2, connect=None, read=None, redirect=None, status=None)) after connection broken by 'NewConnectionError('<urllib3.connection.HTTPConnection object at 0x7f0b140a53d0>: Failed to establish a new connection: [Errno 111] Connection refused')': /wd/hub/session
[2025-05-19T08:37:32.408+0000] {connectionpool.py:812} WARNING - Retrying (Retry(total=1, connect=None, read=None, redirect=None, status=None)) after connection broken by 'NewConnectionError('<urllib3.connection.HTTPConnection object at 0x7f0b14086fd0>: Failed to establish a new connection: [Errno 111] Connection refused')': /wd/hub/session
[2025-05-19T08:37:32.409+0000] {connectionpool.py:812} WARNING - Retrying (Retry(total=0, connect=None, read=None, redirect=None, status=None)) after connection broken by 'NewConnectionError('<urllib3.connection.HTTPConnection object at 0x7f0b14086b20>: Failed to establish a new connection: [Errno 111] Connection refused')': /wd/hub/session
[2025-05-19T08:37:32.409+0000] {MathDag.py:50} ERROR - Lỗi crawl link https://loigiaihay.com/de-so-38-de-thi-vao-lop-10-mon-toan-c44a49647.html: HTTPConnectionPool(host='localhost', port=4444): Max retries exceeded with url: /wd/hub/session (Caused by NewConnectionError('<urllib3.connection.HTTPConnection object at 0x7f0b14086d30>: Failed to establish a new connection: [Errno 111] Connection refused'))
[2025-05-19T08:37:32.409+0000] {MathDag.py:45} INFO - Đang crawl link 60/64: https://loigiaihay.com/de-so-39-de-thi-vao-lop-10-mon-toan-c44a49648.html
[2025-05-19T08:37:32.410+0000] {connectionpool.py:812} WARNING - Retrying (Retry(total=2, connect=None, read=None, redirect=None, status=None)) after connection broken by 'NewConnectionError('<urllib3.connection.HTTPConnection object at 0x7f0b140e5340>: Failed to establish a new connection: [Errno 111] Connection refused')': /wd/hub/session
[2025-05-19T08:37:32.411+0000] {connectionpool.py:812} WARNING - Retrying (Retry(total=1, connect=None, read=None, redirect=None, status=None)) after connection broken by 'NewConnectionError('<urllib3.connection.HTTPConnection object at 0x7f0b140e5880>: Failed to establish a new connection: [Errno 111] Connection refused')': /wd/hub/session
[2025-05-19T08:37:32.411+0000] {connectionpool.py:812} WARNING - Retrying (Retry(total=0, connect=None, read=None, redirect=None, status=None)) after connection broken by 'NewConnectionError('<urllib3.connection.HTTPConnection object at 0x7f0b140a58e0>: Failed to establish a new connection: [Errno 111] Connection refused')': /wd/hub/session
[2025-05-19T08:37:32.411+0000] {MathDag.py:50} ERROR - Lỗi crawl link https://loigiaihay.com/de-so-39-de-thi-vao-lop-10-mon-toan-c44a49648.html: HTTPConnectionPool(host='localhost', port=4444): Max retries exceeded with url: /wd/hub/session (Caused by NewConnectionError('<urllib3.connection.HTTPConnection object at 0x7f0b140a53d0>: Failed to establish a new connection: [Errno 111] Connection refused'))
[2025-05-19T08:37:32.412+0000] {MathDag.py:45} INFO - Đang crawl link 61/64: https://loigiaihay.com/de-so-40-de-thi-vao-lop-10-mon-toan-c44a49649.html
[2025-05-19T08:37:32.413+0000] {connectionpool.py:812} WARNING - Retrying (Retry(total=2, connect=None, read=None, redirect=None, status=None)) after connection broken by 'NewConnectionError('<urllib3.connection.HTTPConnection object at 0x7f0b140a5580>: Failed to establish a new connection: [Errno 111] Connection refused')': /wd/hub/session
[2025-05-19T08:37:32.413+0000] {connectionpool.py:812} WARNING - Retrying (Retry(total=1, connect=None, read=None, redirect=None, status=None)) after connection broken by 'NewConnectionError('<urllib3.connection.HTTPConnection object at 0x7f0b140a5850>: Failed to establish a new connection: [Errno 111] Connection refused')': /wd/hub/session
[2025-05-19T08:37:32.413+0000] {connectionpool.py:812} WARNING - Retrying (Retry(total=0, connect=None, read=None, redirect=None, status=None)) after connection broken by 'NewConnectionError('<urllib3.connection.HTTPConnection object at 0x7f0b1417c910>: Failed to establish a new connection: [Errno 111] Connection refused')': /wd/hub/session
[2025-05-19T08:37:32.414+0000] {MathDag.py:50} ERROR - Lỗi crawl link https://loigiaihay.com/de-so-40-de-thi-vao-lop-10-mon-toan-c44a49649.html: HTTPConnectionPool(host='localhost', port=4444): Max retries exceeded with url: /wd/hub/session (Caused by NewConnectionError('<urllib3.connection.HTTPConnection object at 0x7f0b141072b0>: Failed to establish a new connection: [Errno 111] Connection refused'))
[2025-05-19T08:37:32.414+0000] {MathDag.py:45} INFO - Đang crawl link 62/64: https://loigiaihay.com/de-so-41-de-thi-vao-lop-10-mon-toan-c44a49650.html
[2025-05-19T08:37:32.415+0000] {connectionpool.py:812} WARNING - Retrying (Retry(total=2, connect=None, read=None, redirect=None, status=None)) after connection broken by 'NewConnectionError('<urllib3.connection.HTTPConnection object at 0x7f0b14086190>: Failed to establish a new connection: [Errno 111] Connection refused')': /wd/hub/session
[2025-05-19T08:37:32.416+0000] {connectionpool.py:812} WARNING - Retrying (Retry(total=1, connect=None, read=None, redirect=None, status=None)) after connection broken by 'NewConnectionError('<urllib3.connection.HTTPConnection object at 0x7f0b140863d0>: Failed to establish a new connection: [Errno 111] Connection refused')': /wd/hub/session
[2025-05-19T08:37:32.416+0000] {connectionpool.py:812} WARNING - Retrying (Retry(total=0, connect=None, read=None, redirect=None, status=None)) after connection broken by 'NewConnectionError('<urllib3.connection.HTTPConnection object at 0x7f0b14093c70>: Failed to establish a new connection: [Errno 111] Connection refused')': /wd/hub/session
[2025-05-19T08:37:32.417+0000] {MathDag.py:50} ERROR - Lỗi crawl link https://loigiaihay.com/de-so-41-de-thi-vao-lop-10-mon-toan-c44a49650.html: HTTPConnectionPool(host='localhost', port=4444): Max retries exceeded with url: /wd/hub/session (Caused by NewConnectionError('<urllib3.connection.HTTPConnection object at 0x7f0b14093e50>: Failed to establish a new connection: [Errno 111] Connection refused'))
[2025-05-19T08:37:32.417+0000] {MathDag.py:45} INFO - Đang crawl link 63/64: https://loigiaihay.com/de-so-42-de-thi-vao-lop-10-mon-toan-c44a49651.html
[2025-05-19T08:37:32.418+0000] {connectionpool.py:812} WARNING - Retrying (Retry(total=2, connect=None, read=None, redirect=None, status=None)) after connection broken by 'NewConnectionError('<urllib3.connection.HTTPConnection object at 0x7f0b14093a30>: Failed to establish a new connection: [Errno 111] Connection refused')': /wd/hub/session
[2025-05-19T08:37:32.418+0000] {connectionpool.py:812} WARNING - Retrying (Retry(total=1, connect=None, read=None, redirect=None, status=None)) after connection broken by 'NewConnectionError('<urllib3.connection.HTTPConnection object at 0x7f0b140934c0>: Failed to establish a new connection: [Errno 111] Connection refused')': /wd/hub/session
[2025-05-19T08:37:32.419+0000] {connectionpool.py:812} WARNING - Retrying (Retry(total=0, connect=None, read=None, redirect=None, status=None)) after connection broken by 'NewConnectionError('<urllib3.connection.HTTPConnection object at 0x7f0b140e5250>: Failed to establish a new connection: [Errno 111] Connection refused')': /wd/hub/session
[2025-05-19T08:37:32.419+0000] {MathDag.py:50} ERROR - Lỗi crawl link https://loigiaihay.com/de-so-42-de-thi-vao-lop-10-mon-toan-c44a49651.html: HTTPConnectionPool(host='localhost', port=4444): Max retries exceeded with url: /wd/hub/session (Caused by NewConnectionError('<urllib3.connection.HTTPConnection object at 0x7f0b140e50a0>: Failed to establish a new connection: [Errno 111] Connection refused'))
[2025-05-19T08:37:32.419+0000] {MathDag.py:45} INFO - Đang crawl link 64/64: https://loigiaihay.com/de-so-43-de-thi-vao-lop-10-mon-toan-c44a49652.html
[2025-05-19T08:37:32.420+0000] {connectionpool.py:812} WARNING - Retrying (Retry(total=2, connect=None, read=None, redirect=None, status=None)) after connection broken by 'NewConnectionError('<urllib3.connection.HTTPConnection object at 0x7f0b14086bb0>: Failed to establish a new connection: [Errno 111] Connection refused')': /wd/hub/session
[2025-05-19T08:37:32.421+0000] {connectionpool.py:812} WARNING - Retrying (Retry(total=1, connect=None, read=None, redirect=None, status=None)) after connection broken by 'NewConnectionError('<urllib3.connection.HTTPConnection object at 0x7f0b14086d00>: Failed to establish a new connection: [Errno 111] Connection refused')': /wd/hub/session
[2025-05-19T08:37:32.421+0000] {connectionpool.py:812} WARNING - Retrying (Retry(total=0, connect=None, read=None, redirect=None, status=None)) after connection broken by 'NewConnectionError('<urllib3.connection.HTTPConnection object at 0x7f0b14086c10>: Failed to establish a new connection: [Errno 111] Connection refused')': /wd/hub/session
[2025-05-19T08:37:32.422+0000] {MathDag.py:50} ERROR - Lỗi crawl link https://loigiaihay.com/de-so-43-de-thi-vao-lop-10-mon-toan-c44a49652.html: HTTPConnectionPool(host='localhost', port=4444): Max retries exceeded with url: /wd/hub/session (Caused by NewConnectionError('<urllib3.connection.HTTPConnection object at 0x7f0b14086c70>: Failed to establish a new connection: [Errno 111] Connection refused'))
[2025-05-19T08:37:32.439+0000] {python.py:177} INFO - Done. Returned value was: None
[2025-05-19T08:37:32.446+0000] {taskinstance.py:1322} INFO - Marking task as SUCCESS. dag_id=math_crawler_pipeline, task_id=extract_problem_and_solution, execution_date=20250519T083728, start_date=20250519T083732, end_date=20250519T083732
[2025-05-19T08:37:32.469+0000] {local_task_job.py:159} INFO - Task exited with return code 0
[2025-05-19T08:37:32.487+0000] {taskinstance.py:2582} INFO - 2 downstream tasks scheduled from follow-on schedule check
